Workbook

Sheet Datos
B2: Simulación Monte Carlo - TIR del proyecto (Compañía X)
B3: Datos base y distribuciones triangulares (a=mínimo, b=moda, c=máximo)
B5: Parámetros generales
B6: Tasa de impuestos (T) | D6: 0.5
B7: TREMA | D7: 0.15
B8: Vida fiscal del activo (años) | D8: 5
B9: Umbral de aceptación Prob(TIR>TREMA) | D9: 0.9
B10: Número de simulaciones | D10: 1000
B12: Activo fijo y activo circulante inicial (distribución triangular)
B13: Variable | C13: a (mínimo / optimista) | D13: b (moda / más probable) | E13: c (máximo / pesimista)
B14: Activo fijo inicial (AF) | C14: 60000 | D14: 70000 | E14: 100000
B15: Activo circulante inicial (AC) | C15: 25000 | D15: 30000 | E15: 40000
B17: Flujo de efectivo antes de impuestos, por año (triangular, igual los 5 años)
B18: Variable | C18: a (mínimo / optimista) | D18: b (moda / más probable) | E18: c (máximo / pesimista)
B19: Flujo antes de impuestos (x) | C19: 30000 | D19: 40000 | E19: 45000
B21: Tasas de inflación, por año (triangular)
B22: Año | C22: a (mínimo / optimista) | D22: b (moda / más probable) | E22: c (máximo / pesimista)
B23: 1 | C23: 0.12 | D23: 0.15 | E23: 0.18
B24: 2 | C24: 0.12 | D24: 0.15 | E24: 0.18
B25: 3 | C25: 0.15 | D25: 0.18 | E25: 0.22
B26: 4 | C26: 0.18 | D26: 0.2 | E26: 0.25
B27: 5 | C27: 0.19 | D27: 0.22 | E27: 0.28
B30: Extremos teóricos (Paso 1 y Paso 2, calculados a mano)
B31: TIR mínima (todo pesimista) | D31: -0.031
B32: TIR máxima (todo optimista) | D32: 0.1991

Sheet Resultados
B2: Resultados de la simulación (Excel)
B3: Basado en 1000 simulaciones de la TIR (Pasos 4 a 9 del método de Coss Bu)
B5: Tabla de frecuencia acumulada de la TIR simulada (Pasos 3, 8 y 9)
B6: Intervalo # | C6: Límite inferior (%) | D6: Límite superior (%) | E6: Frecuencia | F6: Fracción | G6: Fracción acumulada
B7: 1 | C7: =Datos!$D$31*100 -> -3.1 | D7: =Datos!$D$31*100+(Datos!$D$32*100-Datos!$D$31*100)/20*1 -> -1.9495 | E7: =COUNTIFS(Simulacion!$BV$2:$BV$1001,">="&C7,Simulacion!$BV$2:$BV$1001,"<="&D7) -> 0 | F7: =E7/Datos!$D$10 -> 0 | G7: =F7 -> 0
B8: 2 | C8: =D7 -> -1.9495 | D8: =Datos!$D$31*100+(Datos!$D$32*100-Datos!$D$31*100)/20*2 -> -0.799 | E8: =COUNTIFS(Simulacion!$BV$2:$BV$1001,">"&C8,Simulacion!$BV$2:$BV$1001,"<="&D8) -> 0 | F8: =E8/Datos!$D$10 -> 0 | G8: =G7+F8 -> 0
B9: 3 | C9: =D8 -> -0.799 | D9: =Datos!$D$31*100+(Datos!$D$32*100-Datos!$D$31*100)/20*3 -> 0.3515 | E9: =COUNTIFS(Simulacion!$BV$2:$BV$1001,">"&C9,Simulacion!$BV$2:$BV$1001,"<="&D9) -> 0 | F9: =E9/Datos!$D$10 -> 0 | G9: =G8+F9 -> 0
B10: 4 | C10: =D9 -> 0.3515 | D10: =Datos!$D$31*100+(Datos!$D$32*100-Datos!$D$31*100)/20*4 -> 1.502 | E10: =COUNTIFS(Simulacion!$BV$2:$BV$1001,">"&C10,Simulacion!$BV$2:$BV$1001,"<="&D10) -> 0 | F10: =E10/Datos!$D$10 -> 0 | G10: =G9+F10 -> 0
B11: 5 | C11: =D10 -> 1.502 | D11: =Datos!$D$31*100+(Datos!$D$32*100-Datos!$D$31*100)/20*5 -> 2.6525 | E11: =COUNTIFS(Simulacion!$BV$2:$BV$1001,">"&C11,Simulacion!$BV$2:$BV$1001,"<="&D11) -> 2 | F11: =E11/Datos!$D$10 -> 0.002 | G11: =G10+F11 -> 0.002
B12: 6 | C12: =D11 -> 2.6525 | D12: =Datos!$D$31*100+(Datos!$D$32*100-Datos!$D$31*100)/20*6 -> 3.803 | E12: =COUNTIFS(Simulacion!$BV$2:$BV$1001,">"&C12,Simulacion!$BV$2:$BV$1001,"<="&D12) -> 17 | F12: =E12/Datos!$D$10 -> 0.017 | G12: =G11+F12 -> 0.019
B13: 7 | C13: =D12 -> 3.803 | D13: =Datos!$D$31*100+(Datos!$D$32*100-Datos!$D$31*100)/20*7 -> 4.9535 | E13: =COUNTIFS(Simulacion!$BV$2:$BV$1001,">"&C13,Simulacion!$BV$2:$BV$1001,"<="&D13) -> 86 | F13: =E13/Datos!$D$10 -> 0.086 | G13: =G12+F13 -> 0.105
B14: 8 | C14: =D13 -> 4.9535 | D14: =Datos!$D$31*100+(Datos!$D$32*100-Datos!$D$31*100)/20*8 -> 6.104 | E14: =COUNTIFS(Simulacion!$BV$2:$BV$1001,">"&C14,Simulacion!$BV$2:$BV$1001,"<="&D14) -> 123 | F14: =E14/Datos!$D$10 -> 0.123 | G14: =G13+F14 -> 0.228
B15: 9 | C15: =D14 -> 6.104 | D15: =Datos!$D$31*100+(Datos!$D$32*100-Datos!$D$31*100)/20*9 -> 7.2545 | E15: =COUNTIFS(Simulacion!$BV$2:$BV$1001,">"&C15,Simulacion!$BV$2:$BV$1001,"<="&D15) -> 187 | F15: =E15/Datos!$D$10 -> 0.187 | G15: =G14+F15 -> 0.415
B16: 10 | C16: =D15 -> 7.2545 | D16: =Datos!$D$31*100+(Datos!$D$32*100-Datos!$D$31*100)/20*10 -> 8.405 | E16: =COUNTIFS(Simulacion!$BV$2:$BV$1001,">"&C16,Simulacion!$BV$2:$BV$1001,"<="&D16) -> 196 | F16: =E16/Datos!$D$10 -> 0.196 | G16: =G15+F16 -> 0.611
B17: 11 | C17: =D16 -> 8.405 | D17: =Datos!$D$31*100+(Datos!$D$32*100-Datos!$D$31*100)/20*11 -> 9.5555 | E17: =COUNTIFS(Simulacion!$BV$2:$BV$1001,">"&C17,Simulacion!$BV$2:$BV$1001,"<="&D17) -> 194 | F17: =E17/Datos!$D$10 -> 0.194 | G17: =G16+F17 -> 0.805
B18: 12 | C18: =D17 -> 9.5555 | D18: =Datos!$D$31*100+(Datos!$D$32*100-Datos!$D$31*100)/20*12 -> 10.706 | E18: =COUNTIFS(Simulacion!$BV$2:$BV$1001,">"&C18,Simulacion!$BV$2:$BV$1001,"<="&D18) -> 110 | F18: =E18/Datos!$D$10 -> 0.11 | G18: =G17+F18 -> 0.915
B19: 13 | C19: =D18 -> 10.706 | D19: =Datos!$D$31*100+(Datos!$D$32*100-Datos!$D$31*100)/20*13 -> 11.8565 | E19: =COUNTIFS(Simulacion!$BV$2:$BV$1001,">"&C19,Simulacion!$BV$2:$BV$1001,"<="&D19) -> 69 | F19: =E19/Datos!$D$10 -> 0.069 | G19: =G18+F19 -> 0.984
B20: 14 | C20: =D19 -> 11.8565 | D20: =Datos!$D$31*100+(Datos!$D$32*100-Datos!$D$31*100)/20*14 -> 13.007 | E20: =COUNTIFS(Simulacion!$BV$2:$BV$1001,">"&C20,Simulacion!$BV$2:$BV$1001,"<="&D20) -> 10 | F20: =E20/Datos!$D$10 -> 0.01 | G20: =G19+F20 -> 0.994
B21: 15 | C21: =D20 -> 13.007 | D21: =Datos!$D$31*100+(Datos!$D$32*100-Datos!$D$31*100)/20*15 -> 14.1575 | E21: =COUNTIFS(Simulacion!$BV$2:$BV$1001,">"&C21,Simulacion!$BV$2:$BV$1001,"<="&D21) -> 5 | F21: =E21/Datos!$D$10 -> 0.005 | G21: =G20+F21 -> 0.999
B22: 16 | C22: =D21 -> 14.1575 | D22: =Datos!$D$31*100+(Datos!$D$32*100-Datos!$D$31*100)/20*16 -> 15.308 | E22: =COUNTIFS(Simulacion!$BV$2:$BV$1001,">"&C22,Simulacion!$BV$2:$BV$1001,"<="&D22) -> 1 | F22: =E22/Datos!$D$10 -> 0.001 | G22: =G21+F22 -> 1
B23: 17 | C23: =D22 -> 15.308 | D23: =Datos!$D$31*100+(Datos!$D$32*100-Datos!$D$31*100)/20*17 -> 16.4585 | E23: =COUNTIFS(Simulacion!$BV$2:$BV$1001,">"&C23,Simulacion!$BV$2:$BV$1001,"<="&D23) -> 0 | F23: =E23/Datos!$D$10 -> 0 | G23: =G22+F23 -> 1
B24: 18 | C24: =D23 -> 16.4585 | D24: =Datos!$D$31*100+(Datos!$D$32*100-Datos!$D$31*100)/20*18 -> 17.609 | E24: =COUNTIFS(Simulacion!$BV$2:$BV$1001,">"&C24,Simulacion!$BV$2:$BV$1001,"<="&D24) -> 0 | F24: =E24/Datos!$D$10 -> 0 | G24: =G23+F24 -> 1
B25: 19 | C25: =D24 -> 17.609 | D25: =Datos!$D$31*100+(Datos!$D$32*100-Datos!$D$31*100)/20*19 -> 18.7595 | E25: =COUNTIFS(Simulacion!$BV$2:$BV$1001,">"&C25,Simulacion!$BV$2:$BV$1001,"<="&D25) -> 0 | F25: =E25/Datos!$D$10 -> 0 | G25: =G24+F25 -> 1
B26: 20 | C26: =D25 -> 18.7595 | D26: =Datos!$D$31*100+(Datos!$D$32*100-Datos!$D$31*100)/20*20 -> 19.91 | E26: =COUNTIFS(Simulacion!$BV$2:$BV$1001,">"&C26,Simulacion!$BV$2:$BV$1001,"<="&D26) -> 0 | F26: =E26/Datos!$D$10 -> 0 | G26: =G25+F26 -> 1
B29: Resultado principal
B30: Prob(TIR > TREMA) | D30: =COUNTIF(Simulacion!$BV$2:$BV$1001,">"&(Datos!$D$7*100))/Datos!$D$10 -> 0
B31: Umbral requerido por la administración | D31: =Datos!$D$9 -> 0.9
B32: Decisión | D32: =IF(D30>=D31,"ACEPTAR el proyecto","RECHAZAR el proyecto") -> RECHAZAR el proyecto
B35: Comparación y validación de resultados (Teórico / Excel / Java)
B36: Método | C36: Prob(TIR > TREMA) | D36: Decisión
B37: Teórico (libro, Tabla 5.6) | C37: 0 | D37: Rechazar
B38: Excel (esta simulación) | C38: =D30 -> 0 | D38: =D32 -> RECHAZAR el proyecto
B39: Java (completar con tu programa)

Sheet Simulacion
A1: N° sim | B1: R (AF) | C1: AF simulado | D1: R (AC) | E1: AC simulado | F1: R (x año 1) | G1: x año 1 | H1: R (x año 2) | I1: x año 2 | J1: R (x año 3) | K1: x año 3 | L1: R (x año 4) | M1: x año 4 | N1: R (x año 5) | O1: x año 5 | P1: R (i año 1) | Q1: i año 1 | R1: R (i año 2) | S1: i año 2 | T1: R (i año 3) | U1: i año 3 | V1: R (i año 4) | W1: i año 4 | X1: R (i año 5) | Y1: i año 5 | Z1: Inflación acum. año 1 | AA1: Inflación acum. año 2 | AB1: Inflación acum. año 3 | AC1: Inflación acum. año 4 | AD1: Inflación acum. año 5 | AE1: Inv. adicional AC año 1 | AF1: Inv. adicional AC año 2 | AG1: Inv. adicional AC año 3 | AH1: Inv. adicional AC año 4 | AI1: Inv. adicional AC año 5 | AJ1: Flujo antes imp. año 1 (corriente) | AK1: Flujo antes imp. año 2 (corriente) | AL1: Flujo antes imp. año 3 (corriente) | AM1: Flujo antes imp. año 4 (corriente) | AN1: Flujo antes imp. año 5 (corriente) | AO1: Depreciación (fija) | AP1: Ingreso gravable año 1 | AQ1: Ingreso gravable año 2 | AR1: Ingreso gravable año 3 | AS1: Ingreso gravable año 4 | AT1: Ingreso gravable año 5 | AU1: Impuestos año 1 | AV1: Impuestos año 2 | AW1: Impuestos año 3 | AX1: Impuestos año 4 | AY1: Impuestos año 5 | AZ1: Flujo desp. imp. año 1 (corriente) | BA1: Flujo desp. imp. año 2 (corriente) | BB1: Flujo desp. imp. año 3 (corriente) | BC1: Flujo desp. imp. año 4 (corriente) | BD1: Flujo desp. imp. año 5 (corriente) | BE1: Flujo desp. imp. año 1 (constante) | BF1: Flujo desp. imp. año 2 (constante) | BG1: Flujo desp. imp. año 3 (constante) | BH1: Flujo desp. imp. año 4 (constante) | BI1: Flujo desp. imp. año 5 (constante) | BJ1: VR: AC recuperado (nominal) | BK1: VR: 20% AF recuperado (nominal) | BL1: VR antes de impuestos | BM1: VR impuestos | BN1: VR pesos corrientes | BO1: VR pesos constantes | BP1: Flujo año 0 | BQ1: Flujo año 1 | BR1: Flujo año 2 | BS1: Flujo año 3 | BT1: Flujo año 4 | BU1: Flujo año 5 | BV1: TIR simulada
A2: 1 | B2: =RAND() -> 0.60193344 | C2: =IF(B2<=(Datos!$D$14-Datos!$C$14)/(Datos!$E$14-Datos!$C$14),Datos!$C$14+SQRT((Datos!$E$14-Datos!$C$14)*(Datos!$D$14-Datos!$C$14)*B2),Datos!$E$14-SQRT((Datos!$E$14-Datos!$C$14)*(Datos!$E$14-Datos!$D$14)*(1-B2))) -> 78144.111 | D2: =RAND() -> 0.05707694 | E2: =IF(D2<=(Datos!$D$15-Datos!$C$15)/(Datos!$E$15-Datos!$C$15),Datos!$C$15+SQRT((Datos!$E$15-Datos!$C$15)*(Datos!$D$15-Datos!$C$15)*D2),Datos!$E$15-SQRT((Datos!$E$15-Datos!$C$15)*(Datos!$E$15-Datos!$D$15)*(1-D2))) -> 27069.002 | F2: =RAND() -> 0.52198623 | G2: =IF(F2<=(Datos!$D$19-Datos!$C$19)/(Datos!$E$19-Datos!$C$19),Datos!$C$19+SQRT((Datos!$E$19-Datos!$C$19)*(Datos!$D$19-Datos!$C$19)*F2),Datos!$E$19-SQRT((Datos!$E$19-Datos!$C$19)*(Datos!$E$19-Datos!$D$19)*(1-F2))) -> 38848.612 | H2: =RAND() -> 0.77434318 | I2: =IF(H2<=(Datos!$D$19-Datos!$C$19)/(Datos!$E$19-Datos!$C$19),Datos!$C$19+SQRT((Datos!$E$19-Datos!$C$19)*(Datos!$D$19-Datos!$C$19)*H2),Datos!$E$19-SQRT((Datos!$E$19-Datos!$C$19)*(Datos!$E$19-Datos!$D$19)*(1-H2))) -> 40886.089 | J2: =RAND() -> 0.60339473 | K2: =IF(J2<=(Datos!$D$19-Datos!$C$19)/(Datos!$E$19-Datos!$C$19),Datos!$C$19+SQRT((Datos!$E$19-Datos!$C$19)*(Datos!$D$19-Datos!$C$19)*J2),Datos!$E$19-SQRT((Datos!$E$19-Datos!$C$19)*(Datos!$E$19-Datos!$D$19)*(1-J2))) -> 39513.633 | L2: =RAND() -> 0.91110671 | M2: =IF(L2<=(Datos!$D$19-Datos!$C$19)/(Datos!$E$19-Datos!$C$19),Datos!$C$19+SQRT((Datos!$E$19-Datos!$C$19)*(Datos!$D$19-Datos!$C$19)*L2),Datos!$E$19-SQRT((Datos!$E$19-Datos!$C$19)*(Datos!$E$19-Datos!$D$19)*(1-L2))) -> 42417.947 | N2: =RAND() -> 0.53130355 | O2: =IF(N2<=(Datos!$D$19-Datos!$C$19)/(Datos!$E$19-Datos!$C$19),Datos!$C$19+SQRT((Datos!$E$19-Datos!$C$19)*(Datos!$D$19-Datos!$C$19)*N2),Datos!$E$19-SQRT((Datos!$E$19-Datos!$C$19)*(Datos!$E$19-Datos!$D$19)*(1-N2))) -> 38927.235 | P2: =RAND() -> 0.61723302 | Q2: =IF(P2<=(Datos!$D$23-Datos!$C$23)/(Datos!$E$23-Datos!$C$23),Datos!$C$23+SQRT((Datos!$E$23-Datos!$C$23)*(Datos!$D$23-Datos!$C$23)*P2),Datos!$E$23-SQRT((Datos!$E$23-Datos!$C$23)*(Datos!$E$23-Datos!$D$23)*(1-P2))) -> 0.15375156 | R2: =RAND() -> 0.53378512 | S2: =IF(R2<=(Datos!$D$24-Datos!$C$24)/(Datos!$E$24-Datos!$C$24),Datos!$C$24+SQRT((Datos!$E$24-Datos!$C$24)*(Datos!$D$24-Datos!$C$24)*R2),Datos!$E$24-SQRT((Datos!$E$24-Datos!$C$24)*(Datos!$E$24-Datos!$D$24)*(1-R2))) -> 0.15103128 | T2: =RAND() -> 0.98959544 | U2: =IF(T2<=(Datos!$D$25-Datos!$C$25)/(Datos!$E$25-Datos!$C$25),Datos!$C$25+SQRT((Datos!$E$25-Datos!$C$25)*(Datos!$D$25-Datos!$C$25)*T2),Datos!$E$25-SQRT((Datos!$E$25-Datos!$C$25)*(Datos!$E$25-Datos!$D$25)*(1-T2))) -> 0.21460252 | V2: =RAND() -> 0.41782046 | W2: =IF(V2<=(Datos!$D$26-Datos!$C$26)/(Datos!$E$26-Datos!$C$26),Datos!$C$26+SQRT((Datos!$E$26-Datos!$C$26)*(Datos!$D$26-Datos!$C$26)*V2),Datos!$E$26-SQRT((Datos!$E$26-Datos!$C$26)*(Datos!$E$26-Datos!$D$26)*(1-V2))) -> 0.2048599 | X2: =RAND() -> 0.36322658 | Y2: =IF(X2<=(Datos!$D$27-Datos!$C$27)/(Datos!$E$27-Datos!$C$27),Datos!$C$27+SQRT((Datos!$E$27-Datos!$C$27)*(Datos!$D$27-Datos!$C$27)*X2),Datos!$E$27-SQRT((Datos!$E$27-Datos!$C$27)*(Datos!$E$27-Datos!$D$27)*(1-X2))) -> 0.22136062 | Z2: =(1+Q2) -> 1.1537516 | AA2: =Z2*(1+S2) -> 1.3280041 | AB2: =AA2*(1+U2) -> 1.6129972 | AC2: =AB2*(1+W2) -> 1.9434356 | AD2: =AC2*(1+Y2) -> 2.3736357 | AE2: =E2*Q2 -> 4161.9014 | AF2: =AE2*(1+S2) -> 4790.4786 | AG2: =AF2*(1+U2) -> 5818.5274 | AH2: =AG2*(1+W2) -> 7010.5104 | AI2: =AH2*(1+Y2) -> 8562.3614 | AJ2: =G2*Z2 -> 44821.647 | AK2: =I2*AA2 -> 54296.896 | AL2: =K2*AB2 -> 63735.378 | AM2: =M2*AC2 -> 82436.549 | AN2: =O2*AD2 -> 92399.077 | AO2: =C2/Datos!$D$8 -> 15628.822 | AP2: =AJ2-AO2 -> 29192.824 | AQ2: =AK2-AO2 -> 38668.073 | AR2: =AL2-AO2 -> 48106.556 | AS2: =AM2-AO2 -> 66807.727 | AT2: =AN2-AO2 -> 76770.255 | AU2: =AP2*Datos!$D$6 -> 14596.412 | AV2: =AQ2*Datos!$D$6 -> 19334.037 | AW2: =AR2*Datos!$D$6 -> 24053.278 | AX2: =AS2*Datos!$D$6 -> 33403.863 | AY2: =AT2*Datos!$D$6 -> 38385.127 | AZ2: =AJ2-AU2-AE2 -> 26063.333 | BA2: =AK2-AV2-AF2 -> 30172.38 | BB2: =AL2-AW2-AG2 -> 33863.573 | BC2: =AM2-AX2-AH2 -> 42022.175 | BD2: =AN2-AY2-AI2 -> 45451.588 | BE2: =AZ2/Z2 -> 22590.074 | BF2: =BA2/AA2 -> 22720.095 | BG2: =BB2/AB2 -> 20994.192 | BH2: =BC2/AC2 -> 21622.623 | BI2: =BD2/AD2 -> 19148.51 | BJ2: =E2*AD2 -> 64251.951 | BK2: =0.2*C2*AD2 -> 37097.131 | BL2: =BJ2+BK2 -> 101349.08 | BM2: =BK2*Datos!$D$6 -> 18548.565 | BN2: =BL2-BM2 -> 82800.517 | BO2: =BN2/AD2 -> 34883.413 | BP2: =-(C2+E2) -> -105213.11 | BQ2: =BE2 -> 22590.074 | BR2: =BF2 -> 22720.095 | BS2: =BG2 -> 20994.192 | BT2: =BH2 -> 21622.623 | BU2: =BI2+BO2 -> 54031.924 | BV2: =IFERROR(IRR(BP2:BU2,0.1),NA())*100 -> 9.4092004
A3: 2 | B3: =RAND() -> 0.54540251 | C3: =IF(B3<=(Datos!$D$14-Datos!$C$14)/(Datos!$E$14-Datos!$C$14),Datos!$C$14+SQRT((Datos!$E$14-Datos!$C$14)*(Datos!$D$14-Datos!$C$14)*B3),Datos!$E$14-SQRT((Datos!$E$14-Datos!$C$14)*(Datos!$E$14-Datos!$D$14)*(1-B3))) -> 76643.695 | D3: =RAND() -> 0.79426882 | E3: =IF(D3<=(Datos!$D$15-Datos!$C$15)/(Datos!$E$15-Datos!$C$15),Datos!$C$15+SQRT((Datos!$E$15-Datos!$C$15)*(Datos!$D$15-Datos!$C$15)*D3),Datos!$E$15-SQRT((Datos!$E$15-Datos!$C$15)*(Datos!$E$15-Datos!$D$15)*(1-D3))) -> 34444.851 | F3: =RAND() -> 0.098297147 | G3: =IF(F3<=(Datos!$D$19-Datos!$C$19)/(Datos!$E$19-Datos!$C$19),Datos!$C$19+SQRT((Datos!$E$19-Datos!$C$19)*(Datos!$D$19-Datos!$C$19)*F3),Datos!$E$19-SQRT((Datos!$E$19-Datos!$C$19)*(Datos!$E$19-Datos!$D$19)*(1-F3))) -> 33839.866 | H3: =RAND() -> 0.25659634 | I3: =IF(H3<=(Datos!$D$19-Datos!$C$19)/(Datos!$E$19-Datos!$C$19),Datos!$C$19+SQRT((Datos!$E$19-Datos!$C$19)*(Datos!$D$19-Datos!$C$19)*H3),Datos!$E$19-SQRT((Datos!$E$19-Datos!$C$19)*(Datos!$E$19-Datos!$D$19)*(1-H3))) -> 36203.987 | J3: =RAND() -> 0.7077358 | K3: =IF(J3<=(Datos!$D$19-Datos!$C$19)/(Datos!$E$19-Datos!$C$19),Datos!$C$19+SQRT((Datos!$E$19-Datos!$C$19)*(Datos!$D$19-Datos!$C$19)*J3),Datos!$E$19-SQRT((Datos!$E$19-Datos!$C$19)*(Datos!$E$19-Datos!$D$19)*(1-J3))) -> 40318.14 | L3: =RAND() -> 0.61438333 | M3: =IF(L3<=(Datos!$D$19-Datos!$C$19)/(Datos!$E$19-Datos!$C$19),Datos!$C$19+SQRT((Datos!$E$19-Datos!$C$19)*(Datos!$D$19-Datos!$C$19)*L3),Datos!$E$19-SQRT((Datos!$E$19-Datos!$C$19)*(Datos!$E$19-Datos!$D$19)*(1-L3))) -> 39599.87 | N3: =RAND() -> 0.27941134 | O3: =IF(N3<=(Datos!$D$19-Datos!$C$19)/(Datos!$E$19-Datos!$C$19),Datos!$C$19+SQRT((Datos!$E$19-Datos!$C$19)*(Datos!$D$19-Datos!$C$19)*N3),Datos!$E$19-SQRT((Datos!$E$19-Datos!$C$19)*(Datos!$E$19-Datos!$D$19)*(1-N3))) -> 36473.925 | P3: =RAND() -> 0.99325523 | Q3: =IF(P3<=(Datos!$D$23-Datos!$C$23)/(Datos!$E$23-Datos!$C$23),Datos!$C$23+SQRT((Datos!$E$23-Datos!$C$23)*(Datos!$D$23-Datos!$C$23)*P3),Datos!$E$23-SQRT((Datos!$E$23-Datos!$C$23)*(Datos!$E$23-Datos!$D$23)*(1-P3))) -> 0.17651567 | R3: =RAND() -> 0.17401586 | S3: =IF(R3<=(Datos!$D$24-Datos!$C$24)/(Datos!$E$24-Datos!$C$24),Datos!$C$24+SQRT((Datos!$E$24-Datos!$C$24)*(Datos!$D$24-Datos!$C$24)*R3),Datos!$E$24-SQRT((Datos!$E$24-Datos!$C$24)*(Datos!$E$24-Datos!$D$24)*(1-R3))) -> 0.13769826 | T3: =RAND() -> 0.32388892 | U3: =IF(T3<=(Datos!$D$25-Datos!$C$25)/(Datos!$E$25-Datos!$C$25),Datos!$C$25+SQRT((Datos!$E$25-Datos!$C$25)*(Datos!$D$25-Datos!$C$25)*T3),Datos!$E$25-SQRT((Datos!$E$25-Datos!$C$25)*(Datos!$E$25-Datos!$D$25)*(1-T3))) -> 0.17608001 | V3: =RAND() -> 0.29917027 | W3: =IF(V3<=(Datos!$D$26-Datos!$C$26)/(Datos!$E$26-Datos!$C$26),Datos!$C$26+SQRT((Datos!$E$26-Datos!$C$26)*(Datos!$D$26-Datos!$C$26)*V3),Datos!$E$26-SQRT((Datos!$E$26-Datos!$C$26)*(Datos!$E$26-Datos!$D$26)*(1-V3))) -> 0.2004732 | X3: =RAND() -> 0.56727219 | Y3: =IF(X3<=(Datos!$D$27-Datos!$C$27)/(Datos!$E$27-Datos!$C$27),Datos!$C$27+SQRT((Datos!$E$27-Datos!$C$27)*(Datos!$D$27-Datos!$C$27)*X3),Datos!$E$27-SQRT((Datos!$E$27-Datos!$C$27)*(Datos!$E$27-Datos!$D$27)*(1-X3))) -> 0.23166026 | Z3: =(1+Q3) -> 1.1765157 | AA3: =Z3*(1+S3) -> 1.3385198 | AB3: =AA3*(1+U3) -> 1.5742064 | AC3: =AB3*(1+W3) -> 1.8897926 | AD3: =AC3*(1+Y3) -> 2.3275825 | AE3: =E3*Q3 -> 6080.0559 | AF3: =AE3*(1+S3) -> 6917.269 | AG3: =AF3*(1+U3) -> 8135.2618 | AH3: =AG3*(1+W3) -> 9766.1638 | AI3: =AH3*(1+Y3) -> 12028.596 | AJ3: =G3*Z3 -> 39813.133 | AK3: =I3*AA3 -> 48459.754 | AL3: =K3*AB3 -> 63469.074 | AM3: =M3*AC3 -> 74835.541 | AN3: =O3*AD3 -> 84896.067 | AO3: =C3/Datos!$D$8 -> 15328.739 | AP3: =AJ3-AO3 -> 24484.394 | AQ3: =AK3-AO3 -> 33131.015 | AR3: =AL3-AO3 -> 48140.335 | AS3: =AM3-AO3 -> 59506.802 | AT3: =AN3-AO3 -> 69567.328 | AU3: =AP3*Datos!$D$6 -> 12242.197 | AV3: =AQ3*Datos!$D$6 -> 16565.508 | AW3: =AR3*Datos!$D$6 -> 24070.168 | AX3: =AS3*Datos!$D$6 -> 29753.401 | AY3: =AT3*Datos!$D$6 -> 34783.664 | AZ3: =AJ3-AU3-AE3 -> 21490.88 | BA3: =AK3-AV3-AF3 -> 24976.978 | BB3: =AL3-AW3-AG3 -> 31263.645 | BC3: =AM3-AX3-AH3 -> 35315.976 | BD3: =AN3-AY3-AI3 -> 38083.807 | BE3: =AZ3/Z3 -> 18266.548 | BF3: =BA3/AA3 -> 18660.148 | BG3: =BB3/AB3 -> 19859.94 | BH3: =BC3/AC3 -> 18687.752 | BI3: =BD3/AD3 -> 16361.958 | BJ3: =E3*AD3 -> 80173.232 | BK3: =0.2*C3*AD3 -> 35678.904 | BL3: =BJ3+BK3 -> 115852.14 | BM3: =BK3*Datos!$D$6 -> 17839.452 | BN3: =BL3-BM3 -> 98012.684 | BO3: =BN3/AD3 -> 42109.221 | BP3: =-(C3+E3) -> -111088.55 | BQ3: =BE3 -> 18266.548 | BR3: =BF3 -> 18660.148 | BS3: =BG3 -> 19859.94 | BT3: =BH3 -> 18687.752 | BU3: =BI3+BO3 -> 58471.179 | BV3: =IFERROR(IRR(BP3:BU3,0.1),NA())*100 -> 5.4255393
A4: 3 | B4: =RAND() -> 0.78093121 | C4: =IF(B4<=(Datos!$D$14-Datos!$C$14)/(Datos!$E$14-Datos!$C$14),Datos!$C$14+SQRT((Datos!$E$14-Datos!$C$14)*(Datos!$D$14-Datos!$C$14)*B4),Datos!$E$14-SQRT((Datos!$E$14-Datos!$C$14)*(Datos!$E$14-Datos!$D$14)*(1-B4))) -> 83786.347 | D4: =RAND() -> 0.89340253 | E4: =IF(D4<=(Datos!$D$15-Datos!$C$15)/(Datos!$E$15-Datos!$C$15),Datos!$C$15+SQRT((Datos!$E$15-Datos!$C$15)*(Datos!$D$15-Datos!$C$15)*D4),Datos!$E$15-SQRT((Datos!$E$15-Datos!$C$15)*(Datos!$E$15-Datos!$D$15)*(1-D4))) -> 36001.298 | F4: =RAND() -> 0.54697048 | G4: =IF(F4<=(Datos!$D$19-Datos!$C$19)/(Datos!$E$19-Datos!$C$19),Datos!$C$19+SQRT((Datos!$E$19-Datos!$C$19)*(Datos!$D$19-Datos!$C$19)*F4),Datos!$E$19-SQRT((Datos!$E$19-Datos!$C$19)*(Datos!$E$19-Datos!$D$19)*(1-F4))) -> 39057.901 | H4: =RAND() -> 0.70106003 | I4: =IF(H4<=(Datos!$D$19-Datos!$C$19)/(Datos!$E$19-Datos!$C$19),Datos!$C$19+SQRT((Datos!$E$19-Datos!$C$19)*(Datos!$D$19-Datos!$C$19)*H4),Datos!$E$19-SQRT((Datos!$E$19-Datos!$C$19)*(Datos!$E$19-Datos!$D$19)*(1-H4))) -> 40264.971 | J4: =RAND() -> 0.10560835 | K4: =IF(J4<=(Datos!$D$19-Datos!$C$19)/(Datos!$E$19-Datos!$C$19),Datos!$C$19+SQRT((Datos!$E$19-Datos!$C$19)*(Datos!$D$19-Datos!$C$19)*J4),Datos!$E$19-SQRT((Datos!$E$19-Datos!$C$19)*(Datos!$E$19-Datos!$D$19)*(1-J4))) -> 33980.107 | L4: =RAND() -> 0.63486598 | M4: =IF(L4<=(Datos!$D$19-Datos!$C$19)/(Datos!$E$19-Datos!$C$19),Datos!$C$19+SQRT((Datos!$E$19-Datos!$C$19)*(Datos!$D$19-Datos!$C$19)*L4),Datos!$E$19-SQRT((Datos!$E$19-Datos!$C$19)*(Datos!$E$19-Datos!$D$19)*(1-L4))) -> 39758.581 | N4: =RAND() -> 0.48838328 | O4: =IF(N4<=(Datos!$D$19-Datos!$C$19)/(Datos!$E$19-Datos!$C$19),Datos!$C$19+SQRT((Datos!$E$19-Datos!$C$19)*(Datos!$D$19-Datos!$C$19)*N4),Datos!$E$19-SQRT((Datos!$E$19-Datos!$C$19)*(Datos!$E$19-Datos!$D$19)*(1-N4))) -> 38559.059 | P4: =RAND() -> 0.87431428 | Q4: =IF(P4<=(Datos!$D$23-Datos!$C$23)/(Datos!$E$23-Datos!$C$23),Datos!$C$23+SQRT((Datos!$E$23-Datos!$C$23)*(Datos!$D$23-Datos!$C$23)*P4),Datos!$E$23-SQRT((Datos!$E$23-Datos!$C$23)*(Datos!$E$23-Datos!$D$23)*(1-P4))) -> 0.16495891 | R4: =RAND() -> 0.7666802 | S4: =IF(R4<=(Datos!$D$24-Datos!$C$24)/(Datos!$E$24-Datos!$C$24),Datos!$C$24+SQRT((Datos!$E$24-Datos!$C$24)*(Datos!$D$24-Datos!$C$24)*R4),Datos!$E$24-SQRT((Datos!$E$24-Datos!$C$24)*(Datos!$E$24-Datos!$D$24)*(1-R4))) -> 0.15950669 | T4: =RAND() -> 0.85571163 | U4: =IF(T4<=(Datos!$D$25-Datos!$C$25)/(Datos!$E$25-Datos!$C$25),Datos!$C$25+SQRT((Datos!$E$25-Datos!$C$25)*(Datos!$D$25-Datos!$C$25)*T4),Datos!$E$25-SQRT((Datos!$E$25-Datos!$C$25)*(Datos!$E$25-Datos!$D$25)*(1-T4))) -> 0.19990006 | V4: =RAND() -> 0.66965756 | W4: =IF(V4<=(Datos!$D$26-Datos!$C$26)/(Datos!$E$26-Datos!$C$26),Datos!$C$26+SQRT((Datos!$E$26-Datos!$C$26)*(Datos!$D$26-Datos!$C$26)*V4),Datos!$E$26-SQRT((Datos!$E$26-Datos!$C$26)*(Datos!$E$26-Datos!$D$26)*(1-V4))) -> 0.21599708 | X4: =RAND() -> 0.47660747 | Y4: =IF(X4<=(Datos!$D$27-Datos!$C$27)/(Datos!$E$27-Datos!$C$27),Datos!$C$27+SQRT((Datos!$E$27-Datos!$C$27)*(Datos!$D$27-Datos!$C$27)*X4),Datos!$E$27-SQRT((Datos!$E$27-Datos!$C$27)*(Datos!$E$27-Datos!$D$27)*(1-X4))) -> 0.22683686 | Z4: =(1+Q4) -> 1.1649589 | AA4: =Z4*(1+S4) -> 1.3507777 | AB4: =AA4*(1+U4) -> 1.6207982 | AC4: =AB4*(1+W4) -> 1.9708859 | AD4: =AC4*(1+Y4) -> 2.4179554 | AE4: =E4*Q4 -> 5938.7349 | AF4: =AE4*(1+S4) -> 6886.0029 | AG4: =AF4*(1+U4) -> 8262.5153 | AH4: =AG4*(1+W4) -> 10047.195 | AI4: =AH4*(1+Y4) -> 12326.269 | AJ4: =G4*Z4 -> 45500.85 | AK4: =I4*AA4 -> 54389.023 | AL4: =K4*AB4 -> 55074.896 | AM4: =M4*AC4 -> 78359.625 | AN4: =O4*AD4 -> 93234.086 | AO4: =C4/Datos!$D$8 -> 16757.269 | AP4: =AJ4-AO4 -> 28743.581 | AQ4: =AK4-AO4 -> 37631.754 | AR4: =AL4-AO4 -> 38317.627 | AS4: =AM4-AO4 -> 61602.356 | AT4: =AN4-AO4 -> 76476.817 | AU4: =AP4*Datos!$D$6 -> 14371.79 | AV4: =AQ4*Datos!$D$6 -> 18815.877 | AW4: =AR4*Datos!$D$6 -> 19158.813 | AX4: =AS4*Datos!$D$6 -> 30801.178 | AY4: =AT4*Datos!$D$6 -> 38238.409 | AZ4: =AJ4-AU4-AE4 -> 25190.325 | BA4: =AK4-AV4-AF4 -> 28687.144 | BB4: =AL4-AW4-AG4 -> 27653.568 | BC4: =AM4-AX4-AH4 -> 37511.253 | BD4: =AN4-AY4-AI4 -> 42669.409 | BE4: =AZ4/Z4 -> 21623.359 | BF4: =BA4/AA4 -> 21237.502 | BG4: =BB4/AB4 -> 17061.697 | BH4: =BC4/AC4 -> 19032.686 | BI4: =BD4/AD4 -> 17646.897 | BJ4: =E4*AD4 -> 87049.534 | BK4: =0.2*C4*AD4 -> 40518.331 | BL4: =BJ4+BK4 -> 127567.86 | BM4: =BK4*Datos!$D$6 -> 20259.165 | BN4: =BL4-BM4 -> 107308.7 | BO4: =BN4/AD4 -> 44379.932 | BP4: =-(C4+E4) -> -119787.64 | BQ4: =BE4 -> 21623.359 | BR4: =BF4 -> 21237.502 | BS4: =BG4 -> 17061.697 | BT4: =BH4 -> 19032.686 | BU4: =BI4+BO4 -> 62026.829 | BV4: =IFERROR(IRR(BP4:BU4,0.1),NA())*100 -> 4.7614702
A5: 4 | B5: =RAND() -> 0.59750883 | C5: =IF(B5<=(Datos!$D$14-Datos!$C$14)/(Datos!$E$14-Datos!$C$14),Datos!$C$14+SQRT((Datos!$E$14-Datos!$C$14)*(Datos!$D$14-Datos!$C$14)*B5),Datos!$E$14-SQRT((Datos!$E$14-Datos!$C$14)*(Datos!$E$14-Datos!$D$14)*(1-B5))) -> 78022.98 | D5: =RAND() -> 0.6005698 | E5: =IF(D5<=(Datos!$D$15-Datos!$C$15)/(Datos!$E$15-Datos!$C$15),Datos!$C$15+SQRT((Datos!$E$15-Datos!$C$15)*(Datos!$D$15-Datos!$C$15)*D5),Datos!$E$15-SQRT((Datos!$E$15-Datos!$C$15)*(Datos!$E$15-Datos!$D$15)*(1-D5))) -> 32259.552 | F5: =RAND() -> 0.89976565 | G5: =IF(F5<=(Datos!$D$19-Datos!$C$19)/(Datos!$E$19-Datos!$C$19),Datos!$C$19+SQRT((Datos!$E$19-Datos!$C$19)*(Datos!$D$19-Datos!$C$19)*F5),Datos!$E$19-SQRT((Datos!$E$19-Datos!$C$19)*(Datos!$E$19-Datos!$D$19)*(1-F5))) -> 42258.18 | H5: =RAND() -> 0.10542773 | I5: =IF(H5<=(Datos!$D$19-Datos!$C$19)/(Datos!$E$19-Datos!$C$19),Datos!$C$19+SQRT((Datos!$E$19-Datos!$C$19)*(Datos!$D$19-Datos!$C$19)*H5),Datos!$E$19-SQRT((Datos!$E$19-Datos!$C$19)*(Datos!$E$19-Datos!$D$19)*(1-H5))) -> 33976.702 | J5: =RAND() -> 0.48115536 | K5: =IF(J5<=(Datos!$D$19-Datos!$C$19)/(Datos!$E$19-Datos!$C$19),Datos!$C$19+SQRT((Datos!$E$19-Datos!$C$19)*(Datos!$D$19-Datos!$C$19)*J5),Datos!$E$19-SQRT((Datos!$E$19-Datos!$C$19)*(Datos!$E$19-Datos!$D$19)*(1-J5))) -> 38495.487 | L5: =RAND() -> 0.99234987 | M5: =IF(L5<=(Datos!$D$19-Datos!$C$19)/(Datos!$E$19-Datos!$C$19),Datos!$C$19+SQRT((Datos!$E$19-Datos!$C$19)*(Datos!$D$19-Datos!$C$19)*L5),Datos!$E$19-SQRT((Datos!$E$19-Datos!$C$19)*(Datos!$E$19-Datos!$D$19)*(1-L5))) -> 44242.531 | N5: =RAND() -> 0.988754 | O5: =IF(N5<=(Datos!$D$19-Datos!$C$19)/(Datos!$E$19-Datos!$C$19),Datos!$C$19+SQRT((Datos!$E$19-Datos!$C$19)*(Datos!$D$19-Datos!$C$19)*N5),Datos!$E$19-SQRT((Datos!$E$19-Datos!$C$19)*(Datos!$E$19-Datos!$D$19)*(1-N5))) -> 44081.605 | P5: =RAND() -> 0.41088454 | Q5: =IF(P5<=(Datos!$D$23-Datos!$C$23)/(Datos!$E$23-Datos!$C$23),Datos!$C$23+SQRT((Datos!$E$23-Datos!$C$23)*(Datos!$D$23-Datos!$C$23)*P5),Datos!$E$23-SQRT((Datos!$E$23-Datos!$C$23)*(Datos!$E$23-Datos!$D$23)*(1-P5))) -> 0.14719544 | R5: =RAND() -> 0.73348475 | S5: =IF(R5<=(Datos!$D$24-Datos!$C$24)/(Datos!$E$24-Datos!$C$24),Datos!$C$24+SQRT((Datos!$E$24-Datos!$C$24)*(Datos!$D$24-Datos!$C$24)*R5),Datos!$E$24-SQRT((Datos!$E$24-Datos!$C$24)*(Datos!$E$24-Datos!$D$24)*(1-R5))) -> 0.15809732 | T5: =RAND() -> 0.80167401 | U5: =IF(T5<=(Datos!$D$25-Datos!$C$25)/(Datos!$E$25-Datos!$C$25),Datos!$C$25+SQRT((Datos!$E$25-Datos!$C$25)*(Datos!$D$25-Datos!$C$25)*T5),Datos!$E$25-SQRT((Datos!$E$25-Datos!$C$25)*(Datos!$E$25-Datos!$D$25)*(1-T5))) -> 0.19643493 | V5: =RAND() -> 0.27321466 | W5: =IF(V5<=(Datos!$D$26-Datos!$C$26)/(Datos!$E$26-Datos!$C$26),Datos!$C$26+SQRT((Datos!$E$26-Datos!$C$26)*(Datos!$D$26-Datos!$C$26)*V5),Datos!$E$26-SQRT((Datos!$E$26-Datos!$C$26)*(Datos!$E$26-Datos!$D$26)*(1-V5))) -> 0.19955762 | X5: =RAND() -> 0.0048136516 | Y5: =IF(X5<=(Datos!$D$27-Datos!$C$27)/(Datos!$E$27-Datos!$C$27),Datos!$C$27+SQRT((Datos!$E$27-Datos!$C$27)*(Datos!$D$27-Datos!$C$27)*X5),Datos!$E$27-SQRT((Datos!$E$27-Datos!$C$27)*(Datos!$E$27-Datos!$D$27)*(1-X5))) -> 0.19360512 | Z5: =(1+Q5) -> 1.1471954 | AA5: =Z5*(1+S5) -> 1.328564 | AB5: =AA5*(1+U5) -> 1.5895403 | AC5: =AB5*(1+W5) -> 1.9067452 | AD5: =AC5*(1+Y5) -> 2.2759008 | AE5: =E5*Q5 -> 4748.4591 | AF5: =AE5*(1+S5) -> 5499.1778 | AG5: =AF5*(1+U5) -> 6579.4084 | AH5: =AG5*(1+W5) -> 7892.3794 | AI5: =AH5*(1+Y5) -> 9420.3845 | AJ5: =G5*Z5 -> 48478.392 | AK5: =I5*AA5 -> 45140.222 | AL5: =K5*AB5 -> 61190.13 | AM5: =M5*AC5 -> 84359.234 | AN5: =O5*AD5 -> 100325.36 | AO5: =C5/Datos!$D$8 -> 15604.596 | AP5: =AJ5-AO5 -> 32873.796 | AQ5: =AK5-AO5 -> 29535.626 | AR5: =AL5-AO5 -> 45585.534 | AS5: =AM5-AO5 -> 68754.638 | AT5: =AN5-AO5 -> 84720.766 | AU5: =AP5*Datos!$D$6 -> 16436.898 | AV5: =AQ5*Datos!$D$6 -> 14767.813 | AW5: =AR5*Datos!$D$6 -> 22792.767 | AX5: =AS5*Datos!$D$6 -> 34377.319 | AY5: =AT5*Datos!$D$6 -> 42360.383 | AZ5: =AJ5-AU5-AE5 -> 27293.035 | BA5: =AK5-AV5-AF5 -> 24873.231 | BB5: =AL5-AW5-AG5 -> 31817.954 | BC5: =AM5-AX5-AH5 -> 42089.536 | BD5: =AN5-AY5-AI5 -> 48544.594 | BE5: =AZ5/Z5 -> 23791.094 | BF5: =BA5/AA5 -> 18721.892 | BG5: =BB5/AB5 -> 20017.079 | BH5: =BC5/AC5 -> 22074.022 | BI5: =BD5/AD5 -> 21329.837 | BJ5: =E5*AD5 -> 73419.542 | BK5: =0.2*C5*AD5 -> 35514.513 | BL5: =BJ5+BK5 -> 108934.06 | BM5: =BK5*Datos!$D$6 -> 17757.257 | BN5: =BL5-BM5 -> 91176.799 | BO5: =BN5/AD5 -> 40061.85 | BP5: =-(C5+E5) -> -110282.53 | BQ5: =BE5 -> 23791.094 | BR5: =BF5 -> 18721.892 | BS5: =BG5 -> 20017.079 | BT5: =BH5 -> 22074.022 | BU5: =BI5+BO5 -> 61391.687 | BV5: =IFERROR(IRR(BP5:BU5,0.1),NA())*100 -> 8.4929349
A6: 5 | B6: =RAND() -> 0.41353586 | C6: =IF(B6<=(Datos!$D$14-Datos!$C$14)/(Datos!$E$14-Datos!$C$14),Datos!$C$14+SQRT((Datos!$E$14-Datos!$C$14)*(Datos!$D$14-Datos!$C$14)*B6),Datos!$E$14-SQRT((Datos!$E$14-Datos!$C$14)*(Datos!$E$14-Datos!$D$14)*(1-B6))) -> 73471.582 | D6: =RAND() -> 0.22364934 | E6: =IF(D6<=(Datos!$D$15-Datos!$C$15)/(Datos!$E$15-Datos!$C$15),Datos!$C$15+SQRT((Datos!$E$15-Datos!$C$15)*(Datos!$D$15-Datos!$C$15)*D6),Datos!$E$15-SQRT((Datos!$E$15-Datos!$C$15)*(Datos!$E$15-Datos!$D$15)*(1-D6))) -> 29095.571 | F6: =RAND() -> 0.8449858 | G6: =IF(F6<=(Datos!$D$19-Datos!$C$19)/(Datos!$E$19-Datos!$C$19),Datos!$C$19+SQRT((Datos!$E$19-Datos!$C$19)*(Datos!$D$19-Datos!$C$19)*F6),Datos!$E$19-SQRT((Datos!$E$19-Datos!$C$19)*(Datos!$E$19-Datos!$D$19)*(1-F6))) -> 41590.298 | H6: =RAND() -> 0.88374339 | I6: =IF(H6<=(Datos!$D$19-Datos!$C$19)/(Datos!$E$19-Datos!$C$19),Datos!$C$19+SQRT((Datos!$E$19-Datos!$C$19)*(Datos!$D$19-Datos!$C$19)*H6),Datos!$E$19-SQRT((Datos!$E$19-Datos!$C$19)*(Datos!$E$19-Datos!$D$19)*(1-H6))) -> 42047.163 | J6: =RAND() -> 0.42471568 | K6: =IF(J6<=(Datos!$D$19-Datos!$C$19)/(Datos!$E$19-Datos!$C$19),Datos!$C$19+SQRT((Datos!$E$19-Datos!$C$19)*(Datos!$D$19-Datos!$C$19)*J6),Datos!$E$19-SQRT((Datos!$E$19-Datos!$C$19)*(Datos!$E$19-Datos!$D$19)*(1-J6))) -> 37981.689 | L6: =RAND() -> 0.33946289 | M6: =IF(L6<=(Datos!$D$19-Datos!$C$19)/(Datos!$E$19-Datos!$C$19),Datos!$C$19+SQRT((Datos!$E$19-Datos!$C$19)*(Datos!$D$19-Datos!$C$19)*L6),Datos!$E$19-SQRT((Datos!$E$19-Datos!$C$19)*(Datos!$E$19-Datos!$D$19)*(1-L6))) -> 37135.785 | N6: =RAND() -> 0.26847768 | O6: =IF(N6<=(Datos!$D$19-Datos!$C$19)/(Datos!$E$19-Datos!$C$19),Datos!$C$19+SQRT((Datos!$E$19-Datos!$C$19)*(Datos!$D$19-Datos!$C$19)*N6),Datos!$E$19-SQRT((Datos!$E$19-Datos!$C$19)*(Datos!$E$19-Datos!$D$19)*(1-N6))) -> 36345.995 | P6: =RAND() -> 0.011247525 | Q6: =IF(P6<=(Datos!$D$23-Datos!$C$23)/(Datos!$E$23-Datos!$C$23),Datos!$C$23+SQRT((Datos!$E$23-Datos!$C$23)*(Datos!$D$23-Datos!$C$23)*P6),Datos!$E$23-SQRT((Datos!$E$23-Datos!$C$23)*(Datos!$E$23-Datos!$D$23)*(1-P6))) -> 0.12449951 | R6: =RAND() -> 0.5312172 | S6: =IF(R6<=(Datos!$D$24-Datos!$C$24)/(Datos!$E$24-Datos!$C$24),Datos!$C$24+SQRT((Datos!$E$24-Datos!$C$24)*(Datos!$D$24-Datos!$C$24)*R6),Datos!$E$24-SQRT((Datos!$E$24-Datos!$C$24)*(Datos!$E$24-Datos!$D$24)*(1-R6))) -> 0.15095161 | T6: =RAND() -> 0.54117485 | U6: =IF(T6<=(Datos!$D$25-Datos!$C$25)/(Datos!$E$25-Datos!$C$25),Datos!$C$25+SQRT((Datos!$E$25-Datos!$C$25)*(Datos!$D$25-Datos!$C$25)*T6),Datos!$E$25-SQRT((Datos!$E$25-Datos!$C$25)*(Datos!$E$25-Datos!$D$25)*(1-T6))) -> 0.18415714 | V6: =RAND() -> 0.97819957 | W6: =IF(V6<=(Datos!$D$26-Datos!$C$26)/(Datos!$E$26-Datos!$C$26),Datos!$C$26+SQRT((Datos!$E$26-Datos!$C$26)*(Datos!$D$26-Datos!$C$26)*V6),Datos!$E$26-SQRT((Datos!$E$26-Datos!$C$26)*(Datos!$E$26-Datos!$D$26)*(1-V6))) -> 0.24126493 | X6: =RAND() -> 0.93034039 | Y6: =IF(X6<=(Datos!$D$27-Datos!$C$27)/(Datos!$E$27-Datos!$C$27),Datos!$C$27+SQRT((Datos!$E$27-Datos!$C$27)*(Datos!$D$27-Datos!$C$27)*X6),Datos!$E$27-SQRT((Datos!$E$27-Datos!$C$27)*(Datos!$E$27-Datos!$D$27)*(1-X6))) -> 0.26060511 | Z6: =(1+Q6) -> 1.1244995 | AA6: =Z6*(1+S6) -> 1.2942445 | AB6: =AA6*(1+U6) -> 1.5325889 | AC6: =AB6*(1+W6) -> 1.9023488 | AD6: =AC6*(1+Y6) -> 2.3981107 | AE6: =E6*Q6 -> 3622.3842 | AF6: =AE6*(1+S6) -> 4169.1889 | AG6: =AF6*(1+U6) -> 4936.9748 | AH6: =AG6*(1+W6) -> 6128.0937 | AI6: =AH6*(1+Y6) -> 7725.1062 | AJ6: =G6*Z6 -> 46768.27 | AK6: =I6*AA6 -> 54419.31 | AL6: =K6*AB6 -> 58210.314 | AM6: =M6*AC6 -> 70645.218 | AN6: =O6*AD6 -> 87161.718 | AO6: =C6/Datos!$D$8 -> 14694.316 | AP6: =AJ6-AO6 -> 32073.954 | AQ6: =AK6-AO6 -> 39724.994 | AR6: =AL6-AO6 -> 43515.997 | AS6: =AM6-AO6 -> 55950.902 | AT6: =AN6-AO6 -> 72467.401 | AU6: =AP6*Datos!$D$6 -> 16036.977 | AV6: =AQ6*Datos!$D$6 -> 19862.497 | AW6: =AR6*Datos!$D$6 -> 21757.999 | AX6: =AS6*Datos!$D$6 -> 27975.451 | AY6: =AT6*Datos!$D$6 -> 36233.701 | AZ6: =AJ6-AU6-AE6 -> 27108.909 | BA6: =AK6-AV6-AF6 -> 30387.624 | BB6: =AL6-AW6-AG6 -> 31515.34 | BC6: =AM6-AX6-AH6 -> 36541.674 | BD6: =AN6-AY6-AI6 -> 43202.911 | BE6: =AZ6/Z6 -> 24107.533 | BF6: =BA6/AA6 -> 23479.044 | BG6: =BB6/AB6 -> 20563.467 | BH6: =BC6/AC6 -> 19208.713 | BI6: =BD6/AD6 -> 18015.395 | BJ6: =E6*AD6 -> 69774.398 | BK6: =0.2*C6*AD6 -> 35238.597 | BL6: =BJ6+BK6 -> 105012.99 | BM6: =BK6*Datos!$D$6 -> 17619.298 | BN6: =BL6-BM6 -> 87393.697 | BO6: =BN6/AD6 -> 36442.729 | BP6: =-(C6+E6) -> -102567.15 | BQ6: =BE6 -> 24107.533 | BR6: =BF6 -> 23479.044 | BS6: =BG6 -> 20563.467 | BT6: =BH6 -> 19208.713 | BU6: =BI6+BO6 -> 54458.124 | BV6: =IFERROR(IRR(BP6:BU6,0.1),NA())*100 -> 10.383738
A7: 6 | B7: =RAND() -> 0.92092783 | C7: =IF(B7<=(Datos!$D$14-Datos!$C$14)/(Datos!$E$14-Datos!$C$14),Datos!$C$14+SQRT((Datos!$E$14-Datos!$C$14)*(Datos!$D$14-Datos!$C$14)*B7),Datos!$E$14-SQRT((Datos!$E$14-Datos!$C$14)*(Datos!$E$14-Datos!$D$14)*(1-B7))) -> 90259.024 | D7: =RAND() -> 0.50229674 | E7: =IF(D7<=(Datos!$D$15-Datos!$C$15)/(Datos!$E$15-Datos!$C$15),Datos!$C$15+SQRT((Datos!$E$15-Datos!$C$15)*(Datos!$D$15-Datos!$C$15)*D7),Datos!$E$15-SQRT((Datos!$E$15-Datos!$C$15)*(Datos!$E$15-Datos!$D$15)*(1-D7))) -> 31359.659 | F7: =RAND() -> 0.14240447 | G7: =IF(F7<=(Datos!$D$19-Datos!$C$19)/(Datos!$E$19-Datos!$C$19),Datos!$C$19+SQRT((Datos!$E$19-Datos!$C$19)*(Datos!$D$19-Datos!$C$19)*F7),Datos!$E$19-SQRT((Datos!$E$19-Datos!$C$19)*(Datos!$E$19-Datos!$D$19)*(1-F7))) -> 34621.761 | H7: =RAND() -> 0.18405172 | I7: =IF(H7<=(Datos!$D$19-Datos!$C$19)/(Datos!$E$19-Datos!$C$19),Datos!$C$19+SQRT((Datos!$E$19-Datos!$C$19)*(Datos!$D$19-Datos!$C$19)*H7),Datos!$E$19-SQRT((Datos!$E$19-Datos!$C$19)*(Datos!$E$19-Datos!$D$19)*(1-H7))) -> 35254.308 | J7: =RAND() -> 0.65232207 | K7: =IF(J7<=(Datos!$D$19-Datos!$C$19)/(Datos!$E$19-Datos!$C$19),Datos!$C$19+SQRT((Datos!$E$19-Datos!$C$19)*(Datos!$D$19-Datos!$C$19)*J7),Datos!$E$19-SQRT((Datos!$E$19-Datos!$C$19)*(Datos!$E$19-Datos!$D$19)*(1-J7))) -> 39891.831 | L7: =RAND() -> 0.22938443 | M7: =IF(L7<=(Datos!$D$19-Datos!$C$19)/(Datos!$E$19-Datos!$C$19),Datos!$C$19+SQRT((Datos!$E$19-Datos!$C$19)*(Datos!$D$19-Datos!$C$19)*L7),Datos!$E$19-SQRT((Datos!$E$19-Datos!$C$19)*(Datos!$E$19-Datos!$D$19)*(1-L7))) -> 35865.805 | N7: =RAND() -> 0.15062585 | O7: =IF(N7<=(Datos!$D$19-Datos!$C$19)/(Datos!$E$19-Datos!$C$19),Datos!$C$19+SQRT((Datos!$E$19-Datos!$C$19)*(Datos!$D$19-Datos!$C$19)*N7),Datos!$E$19-SQRT((Datos!$E$19-Datos!$C$19)*(Datos!$E$19-Datos!$D$19)*(1-N7))) -> 34753.302 | P7: =RAND() -> 0.62902849 | Q7: =IF(P7<=(Datos!$D$23-Datos!$C$23)/(Datos!$E$23-Datos!$C$23),Datos!$C$23+SQRT((Datos!$E$23-Datos!$C$23)*(Datos!$D$23-Datos!$C$23)*P7),Datos!$E$23-SQRT((Datos!$E$23-Datos!$C$23)*(Datos!$E$23-Datos!$D$23)*(1-P7))) -> 0.15415917 | R7: =RAND() -> 0.37947219 | S7: =IF(R7<=(Datos!$D$24-Datos!$C$24)/(Datos!$E$24-Datos!$C$24),Datos!$C$24+SQRT((Datos!$E$24-Datos!$C$24)*(Datos!$D$24-Datos!$C$24)*R7),Datos!$E$24-SQRT((Datos!$E$24-Datos!$C$24)*(Datos!$E$24-Datos!$D$24)*(1-R7))) -> 0.14613522 | T7: =RAND() -> 0.50065838 | U7: =IF(T7<=(Datos!$D$25-Datos!$C$25)/(Datos!$E$25-Datos!$C$25),Datos!$C$25+SQRT((Datos!$E$25-Datos!$C$25)*(Datos!$D$25-Datos!$C$25)*T7),Datos!$E$25-SQRT((Datos!$E$25-Datos!$C$25)*(Datos!$E$25-Datos!$D$25)*(1-T7))) -> 0.18260807 | V7: =RAND() -> 0.15361898 | W7: =IF(V7<=(Datos!$D$26-Datos!$C$26)/(Datos!$E$26-Datos!$C$26),Datos!$C$26+SQRT((Datos!$E$26-Datos!$C$26)*(Datos!$D$26-Datos!$C$26)*V7),Datos!$E$26-SQRT((Datos!$E$26-Datos!$C$26)*(Datos!$E$26-Datos!$D$26)*(1-V7))) -> 0.19466515 | X7: =RAND() -> 0.74449748 | Y7: =IF(X7<=(Datos!$D$27-Datos!$C$27)/(Datos!$E$27-Datos!$C$27),Datos!$C$27+SQRT((Datos!$E$27-Datos!$C$27)*(Datos!$D$27-Datos!$C$27)*X7),Datos!$E$27-SQRT((Datos!$E$27-Datos!$C$27)*(Datos!$E$27-Datos!$D$27)*(1-X7))) -> 0.2428555 | Z7: =(1+Q7) -> 1.1541592 | AA7: =Z7*(1+S7) -> 1.3228225 | AB7: =AA7*(1+U7) -> 1.5643805 | AC7: =AB7*(1+W7) -> 1.8689109 | AD7: =AC7*(1+Y7) -> 2.3227862 | AE7: =E7*Q7 -> 4834.3789 | AF7: =AE7*(1+S7) -> 5540.852 | AG7: =AF7*(1+U7) -> 6552.6562 | AH7: =AG7*(1+W7) -> 7828.23 | AI7: =AH7*(1+Y7) -> 9729.3588 | AJ7: =G7*Z7 -> 39959.022 | AK7: =I7*AA7 -> 46635.192 | AL7: =K7*AB7 -> 62406.003 | AM7: =M7*AC7 -> 67029.993 | AN7: =O7*AD7 -> 80724.49 | AO7: =C7/Datos!$D$8 -> 18051.805 | AP7: =AJ7-AO7 -> 21907.217 | AQ7: =AK7-AO7 -> 28583.387 | AR7: =AL7-AO7 -> 44354.198 | AS7: =AM7-AO7 -> 48978.188 | AT7: =AN7-AO7 -> 62672.685 | AU7: =AP7*Datos!$D$6 -> 10953.609 | AV7: =AQ7*Datos!$D$6 -> 14291.693 | AW7: =AR7*Datos!$D$6 -> 22177.099 | AX7: =AS7*Datos!$D$6 -> 24489.094 | AY7: =AT7*Datos!$D$6 -> 31336.342 | AZ7: =AJ7-AU7-AE7 -> 24171.035 | BA7: =AK7-AV7-AF7 -> 26802.646 | BB7: =AL7-AW7-AG7 -> 33676.248 | BC7: =AM7-AX7-AH7 -> 34712.669 | BD7: =AN7-AY7-AI7 -> 39658.788 | BE7: =AZ7/Z7 -> 20942.549 | BF7: =BA7/AA7 -> 20261.711 | BG7: =BB7/AB7 -> 21526.89 | BH7: =BC7/AC7 -> 18573.742 | BI7: =BD7/AD7 -> 17073.801 | BJ7: =E7*AD7 -> 72841.784 | BK7: =0.2*C7*AD7 -> 41930.483 | BL7: =BJ7+BK7 -> 114772.27 | BM7: =BK7*Datos!$D$6 -> 20965.242 | BN7: =BL7-BM7 -> 93807.025 | BO7: =BN7/AD7 -> 40385.562 | BP7: =-(C7+E7) -> -121618.68 | BQ7: =BE7 -> 20942.549 | BR7: =BF7 -> 20261.711 | BS7: =BG7 -> 21526.89 | BT7: =BH7 -> 18573.742 | BU7: =BI7+BO7 -> 57459.362 | BV7: =IFERROR(IRR(BP7:BU7,0.1),NA())*100 -> 3.8732657
A8: 7 | B8: =RAND() -> 0.74815288 | C8: =IF(B8<=(Datos!$D$14-Datos!$C$14)/(Datos!$E$14-Datos!$C$14),Datos!$C$14+SQRT((Datos!$E$14-Datos!$C$14)*(Datos!$D$14-Datos!$C$14)*B8),Datos!$E$14-SQRT((Datos!$E$14-Datos!$C$14)*(Datos!$E$14-Datos!$D$14)*(1-B8))) -> 82615.624 | D8: =RAND() -> 0.19310795 | E8: =IF(D8<=(Datos!$D$15-Datos!$C$15)/(Datos!$E$15-Datos!$C$15),Datos!$C$15+SQRT((Datos!$E$15-Datos!$C$15)*(Datos!$D$15-Datos!$C$15)*D8),Datos!$E$15-SQRT((Datos!$E$15-Datos!$C$15)*(Datos!$E$15-Datos!$D$15)*(1-D8))) -> 28805.666 | F8: =RAND() -> 0.97670881 | G8: =IF(F8<=(Datos!$D$19-Datos!$C$19)/(Datos!$E$19-Datos!$C$19),Datos!$C$19+SQRT((Datos!$E$19-Datos!$C$19)*(Datos!$D$19-Datos!$C$19)*F8),Datos!$E$19-SQRT((Datos!$E$19-Datos!$C$19)*(Datos!$E$19-Datos!$D$19)*(1-F8))) -> 43678.319 | H8: =RAND() -> 0.88353807 | I8: =IF(H8<=(Datos!$D$19-Datos!$C$19)/(Datos!$E$19-Datos!$C$19),Datos!$C$19+SQRT((Datos!$E$19-Datos!$C$19)*(Datos!$D$19-Datos!$C$19)*H8),Datos!$E$19-SQRT((Datos!$E$19-Datos!$C$19)*(Datos!$E$19-Datos!$D$19)*(1-H8))) -> 42044.557 | J8: =RAND() -> 0.90909293 | K8: =IF(J8<=(Datos!$D$19-Datos!$C$19)/(Datos!$E$19-Datos!$C$19),Datos!$C$19+SQRT((Datos!$E$19-Datos!$C$19)*(Datos!$D$19-Datos!$C$19)*J8),Datos!$E$19-SQRT((Datos!$E$19-Datos!$C$19)*(Datos!$E$19-Datos!$D$19)*(1-J8))) -> 42388.864 | L8: =RAND() -> 0.35940327 | M8: =IF(L8<=(Datos!$D$19-Datos!$C$19)/(Datos!$E$19-Datos!$C$19),Datos!$C$19+SQRT((Datos!$E$19-Datos!$C$19)*(Datos!$D$19-Datos!$C$19)*L8),Datos!$E$19-SQRT((Datos!$E$19-Datos!$C$19)*(Datos!$E$19-Datos!$D$19)*(1-L8))) -> 37342.376 | N8: =RAND() -> 0.56020953 | O8: =IF(N8<=(Datos!$D$19-Datos!$C$19)/(Datos!$E$19-Datos!$C$19),Datos!$C$19+SQRT((Datos!$E$19-Datos!$C$19)*(Datos!$D$19-Datos!$C$19)*N8),Datos!$E$19-SQRT((Datos!$E$19-Datos!$C$19)*(Datos!$E$19-Datos!$D$19)*(1-N8))) -> 39166.866 | P8: =RAND() -> 0.083774523 | Q8: =IF(P8<=(Datos!$D$23-Datos!$C$23)/(Datos!$E$23-Datos!$C$23),Datos!$C$23+SQRT((Datos!$E$23-Datos!$C$23)*(Datos!$D$23-Datos!$C$23)*P8),Datos!$E$23-SQRT((Datos!$E$23-Datos!$C$23)*(Datos!$E$23-Datos!$D$23)*(1-P8))) -> 0.13227983 | R8: =RAND() -> 0.4336553 | S8: =IF(R8<=(Datos!$D$24-Datos!$C$24)/(Datos!$E$24-Datos!$C$24),Datos!$C$24+SQRT((Datos!$E$24-Datos!$C$24)*(Datos!$D$24-Datos!$C$24)*R8),Datos!$E$24-SQRT((Datos!$E$24-Datos!$C$24)*(Datos!$E$24-Datos!$D$24)*(1-R8))) -> 0.14793885 | T8: =RAND() -> 0.83322011 | U8: =IF(T8<=(Datos!$D$25-Datos!$C$25)/(Datos!$E$25-Datos!$C$25),Datos!$C$25+SQRT((Datos!$E$25-Datos!$C$25)*(Datos!$D$25-Datos!$C$25)*T8),Datos!$E$25-SQRT((Datos!$E$25-Datos!$C$25)*(Datos!$E$25-Datos!$D$25)*(1-T8))) -> 0.19839019 | V8: =RAND() -> 0.44451667 | W8: =IF(V8<=(Datos!$D$26-Datos!$C$26)/(Datos!$E$26-Datos!$C$26),Datos!$C$26+SQRT((Datos!$E$26-Datos!$C$26)*(Datos!$D$26-Datos!$C$26)*V8),Datos!$E$26-SQRT((Datos!$E$26-Datos!$C$26)*(Datos!$E$26-Datos!$D$26)*(1-V8))) -> 0.20590701 | X8: =RAND() -> 0.63729597 | Y8: =IF(X8<=(Datos!$D$27-Datos!$C$27)/(Datos!$E$27-Datos!$C$27),Datos!$C$27+SQRT((Datos!$E$27-Datos!$C$27)*(Datos!$D$27-Datos!$C$27)*X8),Datos!$E$27-SQRT((Datos!$E$27-Datos!$C$27)*(Datos!$E$27-Datos!$D$27)*(1-X8))) -> 0.23574391 | Z8: =(1+Q8) -> 1.1322798 | AA8: =Z8*(1+S8) -> 1.299788 | AB8: =AA8*(1+U8) -> 1.5576532 | AC8: =AB8*(1+W8) -> 1.8783849 | AD8: =AC8*(1+Y8) -> 2.3212027 | AE8: =E8*Q8 -> 3810.4085 | AF8: =AE8*(1+S8) -> 4374.116 | AG8: =AF8*(1+U8) -> 5241.8977 | AH8: =AG8*(1+W8) -> 6321.2412 | AI8: =AH8*(1+Y8) -> 7811.4353 | AJ8: =G8*Z8 -> 49456.08 | AK8: =I8*AA8 -> 54649.011 | AL8: =K8*AB8 -> 66027.15 | AM8: =M8*AC8 -> 70143.356 | AN8: =O8*AD8 -> 90914.235 | AO8: =C8/Datos!$D$8 -> 16523.125 | AP8: =AJ8-AO8 -> 32932.955 | AQ8: =AK8-AO8 -> 38125.886 | AR8: =AL8-AO8 -> 49504.025 | AS8: =AM8-AO8 -> 53620.232 | AT8: =AN8-AO8 -> 74391.111 | AU8: =AP8*Datos!$D$6 -> 16466.478 | AV8: =AQ8*Datos!$D$6 -> 19062.943 | AW8: =AR8*Datos!$D$6 -> 24752.013 | AX8: =AS8*Datos!$D$6 -> 26810.116 | AY8: =AT8*Datos!$D$6 -> 37195.555 | AZ8: =AJ8-AU8-AE8 -> 29179.194 | BA8: =AK8-AV8-AF8 -> 31211.952 | BB8: =AL8-AW8-AG8 -> 36033.24 | BC8: =AM8-AX8-AH8 -> 37011.999 | BD8: =AN8-AY8-AI8 -> 45907.245 | BE8: =AZ8/Z8 -> 25770.303 | BF8: =BA8/AA8 -> 24013.109 | BG8: =BB8/AB8 -> 23133.031 | BH8: =BC8/AC8 -> 19704.161 | BI8: =BD8/AD8 -> 19777.353 | BJ8: =E8*AD8 -> 66863.791 | BK8: =0.2*C8*AD8 -> 38353.522 | BL8: =BJ8+BK8 -> 105217.31 | BM8: =BK8*Datos!$D$6 -> 19176.761 | BN8: =BL8-BM8 -> 86040.552 | BO8: =BN8/AD8 -> 37067.229 | BP8: =-(C8+E8) -> -111421.29 | BQ8: =BE8 -> 25770.303 | BR8: =BF8 -> 24013.109 | BS8: =BG8 -> 23133.031 | BT8: =BH8 -> 19704.161 | BU8: =BI8+BO8 -> 56844.581 | BV8: =IFERROR(IRR(BP8:BU8,0.1),NA())*100 -> 9.3680378
A9: 8 | B9: =RAND() -> 0.89741723 | C9: =IF(B9<=(Datos!$D$14-Datos!$C$14)/(Datos!$E$14-Datos!$C$14),Datos!$C$14+SQRT((Datos!$E$14-Datos!$C$14)*(Datos!$D$14-Datos!$C$14)*B9),Datos!$E$14-SQRT((Datos!$E$14-Datos!$C$14)*(Datos!$E$14-Datos!$D$14)*(1-B9))) -> 88904.987 | D9: =RAND() -> 0.94466136 | E9: =IF(D9<=(Datos!$D$15-Datos!$C$15)/(Datos!$E$15-Datos!$C$15),Datos!$C$15+SQRT((Datos!$E$15-Datos!$C$15)*(Datos!$D$15-Datos!$C$15)*D9),Datos!$E$15-SQRT((Datos!$E$15-Datos!$C$15)*(Datos!$E$15-Datos!$D$15)*(1-D9))) -> 37118.89 | F9: =RAND() -> 0.49834222 | G9: =IF(F9<=(Datos!$D$19-Datos!$C$19)/(Datos!$E$19-Datos!$C$19),Datos!$C$19+SQRT((Datos!$E$19-Datos!$C$19)*(Datos!$D$19-Datos!$C$19)*F9),Datos!$E$19-SQRT((Datos!$E$19-Datos!$C$19)*(Datos!$E$19-Datos!$D$19)*(1-F9))) -> 38645.885 | H9: =RAND() -> 0.80304642 | I9: =IF(H9<=(Datos!$D$19-Datos!$C$19)/(Datos!$E$19-Datos!$C$19),Datos!$C$19+SQRT((Datos!$E$19-Datos!$C$19)*(Datos!$D$19-Datos!$C$19)*H9),Datos!$E$19-SQRT((Datos!$E$19-Datos!$C$19)*(Datos!$E$19-Datos!$D$19)*(1-H9))) -> 41156.627 | J9: =RAND() -> 0.37583472 | K9: =IF(J9<=(Datos!$D$19-Datos!$C$19)/(Datos!$E$19-Datos!$C$19),Datos!$C$19+SQRT((Datos!$E$19-Datos!$C$19)*(Datos!$D$19-Datos!$C$19)*J9),Datos!$E$19-SQRT((Datos!$E$19-Datos!$C$19)*(Datos!$E$19-Datos!$D$19)*(1-J9))) -> 37508.343 | L9: =RAND() -> 0.92912046 | M9: =IF(L9<=(Datos!$D$19-Datos!$C$19)/(Datos!$E$19-Datos!$C$19),Datos!$C$19+SQRT((Datos!$E$19-Datos!$C$19)*(Datos!$D$19-Datos!$C$19)*L9),Datos!$E$19-SQRT((Datos!$E$19-Datos!$C$19)*(Datos!$E$19-Datos!$D$19)*(1-L9))) -> 42694.362 | N9: =RAND() -> 0.0761392 | O9: =IF(N9<=(Datos!$D$19-Datos!$C$19)/(Datos!$E$19-Datos!$C$19),Datos!$C$19+SQRT((Datos!$E$19-Datos!$C$19)*(Datos!$D$19-Datos!$C$19)*N9),Datos!$E$19-SQRT((Datos!$E$19-Datos!$C$19)*(Datos!$E$19-Datos!$D$19)*(1-N9))) -> 33379.479 | P9: =RAND() -> 0.082793499 | Q9: =IF(P9<=(Datos!$D$23-Datos!$C$23)/(Datos!$E$23-Datos!$C$23),Datos!$C$23+SQRT((Datos!$E$23-Datos!$C$23)*(Datos!$D$23-Datos!$C$23)*P9),Datos!$E$23-SQRT((Datos!$E$23-Datos!$C$23)*(Datos!$E$23-Datos!$D$23)*(1-P9))) -> 0.13220771 | R9: =RAND() -> 0.37178426 | S9: =IF(R9<=(Datos!$D$24-Datos!$C$24)/(Datos!$E$24-Datos!$C$24),Datos!$C$24+SQRT((Datos!$E$24-Datos!$C$24)*(Datos!$D$24-Datos!$C$24)*R9),Datos!$E$24-SQRT((Datos!$E$24-Datos!$C$24)*(Datos!$E$24-Datos!$D$24)*(1-R9))) -> 0.14586913 | T9: =RAND() -> 0.53151722 | U9: =IF(T9<=(Datos!$D$25-Datos!$C$25)/(Datos!$E$25-Datos!$C$25),Datos!$C$25+SQRT((Datos!$E$25-Datos!$C$25)*(Datos!$D$25-Datos!$C$25)*T9),Datos!$E$25-SQRT((Datos!$E$25-Datos!$C$25)*(Datos!$E$25-Datos!$D$25)*(1-T9))) -> 0.18378189 | V9: =RAND() -> 0.77236377 | W9: =IF(V9<=(Datos!$D$26-Datos!$C$26)/(Datos!$E$26-Datos!$C$26),Datos!$C$26+SQRT((Datos!$E$26-Datos!$C$26)*(Datos!$D$26-Datos!$C$26)*V9),Datos!$E$26-SQRT((Datos!$E$26-Datos!$C$26)*(Datos!$E$26-Datos!$D$26)*(1-V9))) -> 0.22177365 | X9: =RAND() -> 0.93316111 | Y9: =IF(X9<=(Datos!$D$27-Datos!$C$27)/(Datos!$E$27-Datos!$C$27),Datos!$C$27+SQRT((Datos!$E$27-Datos!$C$27)*(Datos!$D$27-Datos!$C$27)*X9),Datos!$E$27-SQRT((Datos!$E$27-Datos!$C$27)*(Datos!$E$27-Datos!$D$27)*(1-X9))) -> 0.26100184 | Z9: =(1+Q9) -> 1.1322077 | AA9: =Z9*(1+S9) -> 1.2973619 | AB9: =AA9*(1+U9) -> 1.5357935 | AC9: =AB9*(1+W9) -> 1.876392 | AD9: =AC9*(1+Y9) -> 2.3661338 | AE9: =E9*Q9 -> 4907.4036 | AF9: =AE9*(1+S9) -> 5623.2422 | AG9: =AF9*(1+U9) -> 6656.6923 | AH9: =AG9*(1+W9) -> 8132.9713 | AI9: =AH9*(1+Y9) -> 10255.692 | AJ9: =G9*Z9 -> 43755.17 | AK9: =I9*AA9 -> 53395.038 | AL9: =K9*AB9 -> 57605.068 | AM9: =M9*AC9 -> 80111.36 | AN9: =O9*AD9 -> 78980.313 | AO9: =C9/Datos!$D$8 -> 17780.997 | AP9: =AJ9-AO9 -> 25974.172 | AQ9: =AK9-AO9 -> 35614.041 | AR9: =AL9-AO9 -> 39824.071 | AS9: =AM9-AO9 -> 62330.363 | AT9: =AN9-AO9 -> 61199.316 | AU9: =AP9*Datos!$D$6 -> 12987.086 | AV9: =AQ9*Datos!$D$6 -> 17807.02 | AW9: =AR9*Datos!$D$6 -> 19912.035 | AX9: =AS9*Datos!$D$6 -> 31165.181 | AY9: =AT9*Datos!$D$6 -> 30599.658 | AZ9: =AJ9-AU9-AE9 -> 25860.68 | BA9: =AK9-AV9-AF9 -> 29964.775 | BB9: =AL9-AW9-AG9 -> 31036.34 | BC9: =AM9-AX9-AH9 -> 40813.207 | BD9: =AN9-AY9-AI9 -> 38124.963 | BE9: =AZ9/Z9 -> 22840.932 | BF9: =BA9/AA9 -> 23096.698 | BG9: =BB9/AB9 -> 20208.668 | BH9: =BC9/AC9 -> 21750.896 | BI9: =BD9/AD9 -> 16112.768 | BJ9: =E9*AD9 -> 87828.258 | BK9: =0.2*C9*AD9 -> 42072.218 | BL9: =BJ9+BK9 -> 129900.48 | BM9: =BK9*Datos!$D$6 -> 21036.109 | BN9: =BL9-BM9 -> 108864.37 | BO9: =BN9/AD9 -> 46009.388 | BP9: =-(C9+E9) -> -126023.88 | BQ9: =BE9 -> 22840.932 | BR9: =BF9 -> 23096.698 | BS9: =BG9 -> 20208.668 | BT9: =BH9 -> 21750.896 | BU9: =BI9+BO9 -> 62122.156 | BV9: =IFERROR(IRR(BP9:BU9,0.1),NA())*100 -> 5.1723929
A10: 9 | B10: =RAND() -> 0.71989567 | C10: =IF(B10<=(Datos!$D$14-Datos!$C$14)/(Datos!$E$14-Datos!$C$14),Datos!$C$14+SQRT((Datos!$E$14-Datos!$C$14)*(Datos!$D$14-Datos!$C$14)*B10),Datos!$E$14-SQRT((Datos!$E$14-Datos!$C$14)*(Datos!$E$14-Datos!$D$14)*(1-B10))) -> 81666.283 | D10: =RAND() -> 0.38217975 | E10: =IF(D10<=(Datos!$D$15-Datos!$C$15)/(Datos!$E$15-Datos!$C$15),Datos!$C$15+SQRT((Datos!$E$15-Datos!$C$15)*(Datos!$D$15-Datos!$C$15)*D10),Datos!$E$15-SQRT((Datos!$E$15-Datos!$C$15)*(Datos!$E$15-Datos!$D$15)*(1-D10))) -> 30373.316 | F10: =RAND() -> 0.45893382 | G10: =IF(F10<=(Datos!$D$19-Datos!$C$19)/(Datos!$E$19-Datos!$C$19),Datos!$C$19+SQRT((Datos!$E$19-Datos!$C$19)*(Datos!$D$19-Datos!$C$19)*F10),Datos!$E$19-SQRT((Datos!$E$19-Datos!$C$19)*(Datos!$E$19-Datos!$D$19)*(1-F10))) -> 38296.992 | H10: =RAND() -> 0.52936211 | I10: =IF(H10<=(Datos!$D$19-Datos!$C$19)/(Datos!$E$19-Datos!$C$19),Datos!$C$19+SQRT((Datos!$E$19-Datos!$C$19)*(Datos!$D$19-Datos!$C$19)*H10),Datos!$E$19-SQRT((Datos!$E$19-Datos!$C$19)*(Datos!$E$19-Datos!$D$19)*(1-H10))) -> 38910.91 | J10: =RAND() -> 0.90344423 | K10: =IF(J10<=(Datos!$D$19-Datos!$C$19)/(Datos!$E$19-Datos!$C$19),Datos!$C$19+SQRT((Datos!$E$19-Datos!$C$19)*(Datos!$D$19-Datos!$C$19)*J10),Datos!$E$19-SQRT((Datos!$E$19-Datos!$C$19)*(Datos!$E$19-Datos!$D$19)*(1-J10))) -> 42308.963 | L10: =RAND() -> 0.57598606 | M10: =IF(L10<=(Datos!$D$19-Datos!$C$19)/(Datos!$E$19-Datos!$C$19),Datos!$C$19+SQRT((Datos!$E$19-Datos!$C$19)*(Datos!$D$19-Datos!$C$19)*L10),Datos!$E$19-SQRT((Datos!$E$19-Datos!$C$19)*(Datos!$E$19-Datos!$D$19)*(1-L10))) -> 39295.048 | N10: =RAND() -> 0.68972868 | O10: =IF(N10<=(Datos!$D$19-Datos!$C$19)/(Datos!$E$19-Datos!$C$19),Datos!$C$19+SQRT((Datos!$E$19-Datos!$C$19)*(Datos!$D$19-Datos!$C$19)*N10),Datos!$E$19-SQRT((Datos!$E$19-Datos!$C$19)*(Datos!$E$19-Datos!$D$19)*(1-N10))) -> 40176.065 | P10: =RAND() -> 0.48949228 | Q10: =IF(P10<=(Datos!$D$23-Datos!$C$23)/(Datos!$E$23-Datos!$C$23),Datos!$C$23+SQRT((Datos!$E$23-Datos!$C$23)*(Datos!$D$23-Datos!$C$23)*P10),Datos!$E$23-SQRT((Datos!$E$23-Datos!$C$23)*(Datos!$E$23-Datos!$D$23)*(1-P10))) -> 0.14968309 | R10: =RAND() -> 0.79938947 | S10: =IF(R10<=(Datos!$D$24-Datos!$C$24)/(Datos!$E$24-Datos!$C$24),Datos!$C$24+SQRT((Datos!$E$24-Datos!$C$24)*(Datos!$D$24-Datos!$C$24)*R10),Datos!$E$24-SQRT((Datos!$E$24-Datos!$C$24)*(Datos!$E$24-Datos!$D$24)*(1-R10))) -> 0.1609974 | T10: =RAND() -> 0.18042149 | U10: =IF(T10<=(Datos!$D$25-Datos!$C$25)/(Datos!$E$25-Datos!$C$25),Datos!$C$25+SQRT((Datos!$E$25-Datos!$C$25)*(Datos!$D$25-Datos!$C$25)*T10),Datos!$E$25-SQRT((Datos!$E$25-Datos!$C$25)*(Datos!$E$25-Datos!$D$25)*(1-T10))) -> 0.16946497 | V10: =RAND() -> 0.55541556 | W10: =IF(V10<=(Datos!$D$26-Datos!$C$26)/(Datos!$E$26-Datos!$C$26),Datos!$C$26+SQRT((Datos!$E$26-Datos!$C$26)*(Datos!$D$26-Datos!$C$26)*V10),Datos!$E$26-SQRT((Datos!$E$26-Datos!$C$26)*(Datos!$E$26-Datos!$D$26)*(1-V10))) -> 0.21055326 | X10: =RAND() -> 0.0034560945 | Y10: =IF(X10<=(Datos!$D$27-Datos!$C$27)/(Datos!$E$27-Datos!$C$27),Datos!$C$27+SQRT((Datos!$E$27-Datos!$C$27)*(Datos!$D$27-Datos!$C$27)*X10),Datos!$E$27-SQRT((Datos!$E$27-Datos!$C$27)*(Datos!$E$27-Datos!$D$27)*(1-X10))) -> 0.19305474 | Z10: =(1+Q10) -> 1.1496831 | AA10: =Z10*(1+S10) -> 1.3347791 | AB10: =AA10*(1+U10) -> 1.5609774 | AC10: =AB10*(1+W10) -> 1.8896462 | AD10: =AC10*(1+Y10) -> 2.2544514 | AE10: =E10*Q10 -> 4546.372 | AF10: =AE10*(1+S10) -> 5278.326 | AG10: =AF10*(1+U10) -> 6172.8174 | AH10: =AG10*(1+W10) -> 7472.5242 | AI10: =AH10*(1+Y10) -> 8915.1305 | AJ10: =G10*Z10 -> 44029.404 | AK10: =I10*AA10 -> 51937.469 | AL10: =K10*AB10 -> 66043.333 | AM10: =M10*AC10 -> 74253.739 | AN10: =O10*AD10 -> 90574.987 | AO10: =C10/Datos!$D$8 -> 16333.257 | AP10: =AJ10-AO10 -> 27696.148 | AQ10: =AK10-AO10 -> 35604.212 | AR10: =AL10-AO10 -> 49710.077 | AS10: =AM10-AO10 -> 57920.483 | AT10: =AN10-AO10 -> 74241.73 | AU10: =AP10*Datos!$D$6 -> 13848.074 | AV10: =AQ10*Datos!$D$6 -> 17802.106 | AW10: =AR10*Datos!$D$6 -> 24855.038 | AX10: =AS10*Datos!$D$6 -> 28960.241 | AY10: =AT10*Datos!$D$6 -> 37120.865 | AZ10: =AJ10-AU10-AE10 -> 25634.958 | BA10: =AK10-AV10-AF10 -> 28857.037 | BB10: =AL10-AW10-AG10 -> 35015.478 | BC10: =AM10-AX10-AH10 -> 37820.974 | BD10: =AN10-AY10-AI10 -> 44538.991 | BE10: =AZ10/Z10 -> 22297.413 | BF10: =BA10/AA10 -> 21619.335 | BG10: =BB10/AB10 -> 22431.765 | BH10: =BC10/AC10 -> 20014.843 | BI10: =BD10/AD10 -> 19756.022 | BJ10: =E10*AD10 -> 68475.166 | BK10: =0.2*C10*AD10 -> 36822.533 | BL10: =BJ10+BK10 -> 105297.7 | BM10: =BK10*Datos!$D$6 -> 18411.267 | BN10: =BL10-BM10 -> 86886.433 | BO10: =BN10/AD10 -> 38539.945 | BP10: =-(C10+E10) -> -112039.6 | BQ10: =BE10 -> 22297.413 | BR10: =BF10 -> 21619.335 | BS10: =BG10 -> 22431.765 | BT10: =BH10 -> 20014.843 | BU10: =BI10+BO10 -> 58295.966 | BV10: =IFERROR(IRR(BP10:BU10,0.1),NA())*100 -> 7.8059272
A11: 10 | B11: =RAND() -> 0.36041999 | C11: =IF(B11<=(Datos!$D$14-Datos!$C$14)/(Datos!$E$14-Datos!$C$14),Datos!$C$14+SQRT((Datos!$E$14-Datos!$C$14)*(Datos!$D$14-Datos!$C$14)*B11),Datos!$E$14-SQRT((Datos!$E$14-Datos!$C$14)*(Datos!$E$14-Datos!$D$14)*(1-B11))) -> 72296.282 | D11: =RAND() -> 0.46714586 | E11: =IF(D11<=(Datos!$D$15-Datos!$C$15)/(Datos!$E$15-Datos!$C$15),Datos!$C$15+SQRT((Datos!$E$15-Datos!$C$15)*(Datos!$D$15-Datos!$C$15)*D11),Datos!$E$15-SQRT((Datos!$E$15-Datos!$C$15)*(Datos!$E$15-Datos!$D$15)*(1-D11))) -> 31059.747 | F11: =RAND() -> 0.80818021 | G11: =IF(F11<=(Datos!$D$19-Datos!$C$19)/(Datos!$E$19-Datos!$C$19),Datos!$C$19+SQRT((Datos!$E$19-Datos!$C$19)*(Datos!$D$19-Datos!$C$19)*F11),Datos!$E$19-SQRT((Datos!$E$19-Datos!$C$19)*(Datos!$E$19-Datos!$D$19)*(1-F11))) -> 41207.048 | H11: =RAND() -> 0.92515075 | I11: =IF(H11<=(Datos!$D$19-Datos!$C$19)/(Datos!$E$19-Datos!$C$19),Datos!$C$19+SQRT((Datos!$E$19-Datos!$C$19)*(Datos!$D$19-Datos!$C$19)*H11),Datos!$E$19-SQRT((Datos!$E$19-Datos!$C$19)*(Datos!$E$19-Datos!$D$19)*(1-H11))) -> 42630.677 | J11: =RAND() -> 0.01631589 | K11: =IF(J11<=(Datos!$D$19-Datos!$C$19)/(Datos!$E$19-Datos!$C$19),Datos!$C$19+SQRT((Datos!$E$19-Datos!$C$19)*(Datos!$D$19-Datos!$C$19)*J11),Datos!$E$19-SQRT((Datos!$E$19-Datos!$C$19)*(Datos!$E$19-Datos!$D$19)*(1-J11))) -> 31564.412 | L11: =RAND() -> 0.077167628 | M11: =IF(L11<=(Datos!$D$19-Datos!$C$19)/(Datos!$E$19-Datos!$C$19),Datos!$C$19+SQRT((Datos!$E$19-Datos!$C$19)*(Datos!$D$19-Datos!$C$19)*L11),Datos!$E$19-SQRT((Datos!$E$19-Datos!$C$19)*(Datos!$E$19-Datos!$D$19)*(1-L11))) -> 33402.226 | N11: =RAND() -> 0.34007442 | O11: =IF(N11<=(Datos!$D$19-Datos!$C$19)/(Datos!$E$19-Datos!$C$19),Datos!$C$19+SQRT((Datos!$E$19-Datos!$C$19)*(Datos!$D$19-Datos!$C$19)*N11),Datos!$E$19-SQRT((Datos!$E$19-Datos!$C$19)*(Datos!$E$19-Datos!$D$19)*(1-N11))) -> 37142.21 | P11: =RAND() -> 0.49754587 | Q11: =IF(P11<=(Datos!$D$23-Datos!$C$23)/(Datos!$E$23-Datos!$C$23),Datos!$C$23+SQRT((Datos!$E$23-Datos!$C$23)*(Datos!$D$23-Datos!$C$23)*P11),Datos!$E$23-SQRT((Datos!$E$23-Datos!$C$23)*(Datos!$E$23-Datos!$D$23)*(1-P11))) -> 0.14992629 | R11: =RAND() -> 0.27048622 | S11: =IF(R11<=(Datos!$D$24-Datos!$C$24)/(Datos!$E$24-Datos!$C$24),Datos!$C$24+SQRT((Datos!$E$24-Datos!$C$24)*(Datos!$D$24-Datos!$C$24)*R11),Datos!$E$24-SQRT((Datos!$E$24-Datos!$C$24)*(Datos!$E$24-Datos!$D$24)*(1-R11))) -> 0.14206525 | T11: =RAND() -> 0.86678125 | U11: =IF(T11<=(Datos!$D$25-Datos!$C$25)/(Datos!$E$25-Datos!$C$25),Datos!$C$25+SQRT((Datos!$E$25-Datos!$C$25)*(Datos!$D$25-Datos!$C$25)*T11),Datos!$E$25-SQRT((Datos!$E$25-Datos!$C$25)*(Datos!$E$25-Datos!$D$25)*(1-T11))) -> 0.20068647 | V11: =RAND() -> 0.63324856 | W11: =IF(V11<=(Datos!$D$26-Datos!$C$26)/(Datos!$E$26-Datos!$C$26),Datos!$C$26+SQRT((Datos!$E$26-Datos!$C$26)*(Datos!$D$26-Datos!$C$26)*V11),Datos!$E$26-SQRT((Datos!$E$26-Datos!$C$26)*(Datos!$E$26-Datos!$D$26)*(1-V11))) -> 0.21417222 | X11: =RAND() -> 0.016566715 | Y11: =IF(X11<=(Datos!$D$27-Datos!$C$27)/(Datos!$E$27-Datos!$C$27),Datos!$C$27+SQRT((Datos!$E$27-Datos!$C$27)*(Datos!$D$27-Datos!$C$27)*X11),Datos!$E$27-SQRT((Datos!$E$27-Datos!$C$27)*(Datos!$E$27-Datos!$D$27)*(1-X11))) -> 0.19668806 | Z11: =(1+Q11) -> 1.1499263 | AA11: =Z11*(1+S11) -> 1.3132908 | AB11: =AA11*(1+U11) -> 1.5768506 | AC11: =AB11*(1+W11) -> 1.9145681 | AD11: =AC11*(1+Y11) -> 2.2911408 | AE11: =E11*Q11 -> 4656.6725 | AF11: =AE11*(1+S11) -> 5318.2239 | AG11: =AF11*(1+U11) -> 6385.5194 | AH11: =AG11*(1+W11) -> 7753.1203 | AI11: =AH11*(1+Y11) -> 9278.0664 | AJ11: =G11*Z11 -> 47385.068 | AK11: =I11*AA11 -> 55986.477 | AL11: =K11*AB11 -> 49772.36 | AM11: =M11*AC11 -> 63950.838 | AN11: =O11*AD11 -> 85098.033 | AO11: =C11/Datos!$D$8 -> 14459.256 | AP11: =AJ11-AO11 -> 32925.811 | AQ11: =AK11-AO11 -> 41527.221 | AR11: =AL11-AO11 -> 35313.103 | AS11: =AM11-AO11 -> 49491.582 | AT11: =AN11-AO11 -> 70638.777 | AU11: =AP11*Datos!$D$6 -> 16462.906 | AV11: =AQ11*Datos!$D$6 -> 20763.611 | AW11: =AR11*Datos!$D$6 -> 17656.552 | AX11: =AS11*Datos!$D$6 -> 24745.791 | AY11: =AT11*Datos!$D$6 -> 35319.389 | AZ11: =AJ11-AU11-AE11 -> 26265.49 | BA11: =AK11-AV11-AF11 -> 29904.643 | BB11: =AL11-AW11-AG11 -> 25730.289 | BC11: =AM11-AX11-AH11 -> 31451.927 | BD11: =AN11-AY11-AI11 -> 40500.578 | BE11: =AZ11/Z11 -> 22841.02 | BF11: =BA11/AA11 -> 22770.769 | BG11: =BB11/AB11 -> 16317.519 | BH11: =BC11/AC11 -> 16427.687 | BI11: =BD11/AD11 -> 17677.036 | BJ11: =E11*AD11 -> 71162.255 | BK11: =0.2*C11*AD11 -> 33128.192 | BL11: =BJ11+BK11 -> 104290.45 | BM11: =BK11*Datos!$D$6 -> 16564.096 | BN11: =BL11-BM11 -> 87726.351 | BO11: =BN11/AD11 -> 38289.375 | BP11: =-(C11+E11) -> -103356.03 | BQ11: =BE11 -> 22841.02 | BR11: =BF11 -> 22770.769 | BS11: =BG11 -> 16317.519 | BT11: =BH11 -> 16427.687 | BU11: =BI11+BO11 -> 55966.411 | BV11: =IFERROR(IRR(BP11:BU11,0.1),NA())*100 -> 8.1389937
