Workbook

Sheet Ejercicio 1 - Trapezoidal V
B1: Ejercicio 1 — Distribución Trapezoidal Método de Composición
B3: Parámetros
B4: a = | C4: 3 | G4: Debe cumplirse: 0 < a < b < c
B5: b = | C5: 7
B6: c = | C6: 10
B7: N° simulaciones = | C7: 1000
B9: Áreas (deducidas en la teoría, Paso 1)
B10: A1 = | C10: =C4/(-C4+C5+C6) -> 0.21428571
B11: A2 = | C11: =(2*C5-2*C4)/(-C4+C5+C6) -> 0.57142857
B12: A3 = | C12: =(C6-C5)/(-C4+C5+C6) -> 0.21428571
B13: Suma = | C13: =C10+C11+C12 -> 1 | F13: Región 1: X = a*√R Región 2: X = a + (b−a)*R Región 3: X = c − (c−b)*√(1−R)
B16: i | C16: R_region | D16: R_valor | E16: Región | F16: X | G16: Fórmula de X según región (Paso 5 de la teoría): Región 1 -> a*SQRT(R_valor) | Región 2 -> a+(b-a)*R_valor | Región 3 -> c-(c-b)*SQRT(1-R_valor)
B17: 1 | C17: =RAND() -> 0.50985324 | D17: =RAND() -> 0.5998261 | E17: =IF(C17<=$C$10,1,IF(C17<=$C$10+$C$11,2,3)) -> 2 | F17: =IF(E17=1,$C$4*SQRT(D17),IF(E17=2,$C$4+($C$5-$C$4)*D17,$C$6-($C$6-$C$5)*SQRT(1-D17))) -> 5.3993044
B18: 2 | C18: =RAND() -> 0.87091636 | D18: =RAND() -> 0.25724521 | E18: =IF(C18<=$C$10,1,IF(C18<=$C$10+$C$11,2,3)) -> 3 | F18: =IF(E18=1,$C$4*SQRT(D18),IF(E18=2,$C$4+($C$5-$C$4)*D18,$C$6-($C$6-$C$5)*SQRT(1-D18))) -> 7.4145033
B19: 3 | C19: =RAND() -> 0.53353241 | D19: =RAND() -> 0.12718183 | E19: =IF(C19<=$C$10,1,IF(C19<=$C$10+$C$11,2,3)) -> 2 | F19: =IF(E19=1,$C$4*SQRT(D19),IF(E19=2,$C$4+($C$5-$C$4)*D19,$C$6-($C$6-$C$5)*SQRT(1-D19))) -> 3.5087273
B20: 4 | C20: =RAND() -> 0.039578797 | D20: =RAND() -> 0.96776714 | E20: =IF(C20<=$C$10,1,IF(C20<=$C$10+$C$11,2,3)) -> 1 | F20: =IF(E20=1,$C$4*SQRT(D20),IF(E20=2,$C$4+($C$5-$C$4)*D20,$C$6-($C$6-$C$5)*SQRT(1-D20))) -> 2.9512547
B21: 5 | C21: =RAND() -> 0.56743481 | D21: =RAND() -> 0.095470759 | E21: =IF(C21<=$C$10,1,IF(C21<=$C$10+$C$11,2,3)) -> 2 | F21: =IF(E21=1,$C$4*SQRT(D21),IF(E21=2,$C$4+($C$5-$C$4)*D21,$C$6-($C$6-$C$5)*SQRT(1-D21))) -> 3.381883
B22: 6 | C22: =RAND() -> 0.45703949 | D22: =RAND() -> 0.41729593 | E22: =IF(C22<=$C$10,1,IF(C22<=$C$10+$C$11,2,3)) -> 2 | F22: =IF(E22=1,$C$4*SQRT(D22),IF(E22=2,$C$4+($C$5-$C$4)*D22,$C$6-($C$6-$C$5)*SQRT(1-D22))) -> 4.6691837
B23: 7 | C23: =RAND() -> 0.59957542 | D23: =RAND() -> 0.68451148 | E23: =IF(C23<=$C$10,1,IF(C23<=$C$10+$C$11,2,3)) -> 2 | F23: =IF(E23=1,$C$4*SQRT(D23),IF(E23=2,$C$4+($C$5-$C$4)*D23,$C$6-($C$6-$C$5)*SQRT(1-D23))) -> 5.7380459
B24: 8 | C24: =RAND() -> 0.12505711 | D24: =RAND() -> 0.82649769 | E24: =IF(C24<=$C$10,1,IF(C24<=$C$10+$C$11,2,3)) -> 1 | F24: =IF(E24=1,$C$4*SQRT(D24),IF(E24=2,$C$4+($C$5-$C$4)*D24,$C$6-($C$6-$C$5)*SQRT(1-D24))) -> 2.7273575
B25: 9 | C25: =RAND() -> 0.7449589 | D25: =RAND() -> 0.77617766 | E25: =IF(C25<=$C$10,1,IF(C25<=$C$10+$C$11,2,3)) -> 2 | F25: =IF(E25=1,$C$4*SQRT(D25),IF(E25=2,$C$4+($C$5-$C$4)*D25,$C$6-($C$6-$C$5)*SQRT(1-D25))) -> 6.1047106
B26: 10 | C26: =RAND() -> 0.29217048 | D26: =RAND() -> 0.31280412 | E26: =IF(C26<=$C$10,1,IF(C26<=$C$10+$C$11,2,3)) -> 2 | F26: =IF(E26=1,$C$4*SQRT(D26),IF(E26=2,$C$4+($C$5-$C$4)*D26,$C$6-($C$6-$C$5)*SQRT(1-D26))) -> 4.2512165
B27: 11 | C27: =RAND() -> 0.03712624 | D27: =RAND() -> 0.21177364 | E27: =IF(C27<=$C$10,1,IF(C27<=$C$10+$C$11,2,3)) -> 1 | F27: =IF(E27=1,$C$4*SQRT(D27),IF(E27=2,$C$4+($C$5-$C$4)*D27,$C$6-($C$6-$C$5)*SQRT(1-D27))) -> 1.3805661
B28: 12 | C28: =RAND() -> 0.94116552 | D28: =RAND() -> 0.86884693 | E28: =IF(C28<=$C$10,1,IF(C28<=$C$10+$C$11,2,3)) -> 3 | F28: =IF(E28=1,$C$4*SQRT(D28),IF(E28=2,$C$4+($C$5-$C$4)*D28,$C$6-($C$6-$C$5)*SQRT(1-D28))) -> 8.9135481
... B1016: 1000 | C1016: =RAND() -> 0.086363534 | D1016: =RAND() -> 0.12037865 | E1016: =IF(C1016<=$C$10,1,IF(C1016<=$C$10+$C$11,2,3)) -> 1 | F1016: =IF(E1016=1,$C$4*SQRT(D1016),IF(E1016=2,$C$4+($C$5-$C$4)*D1016,$C$6-($C$6-$C$5)*SQRT(1-D1016))) -> 1.0408688
B1018: Promedio X = | C1018: =AVERAGE(F17:F1016) -> 4.9110382
B1019: Mínimo X = | C1019: =MIN(F17:F1016) -> 0.052209938
B1020: Máximo X = | C1020: =MAX(F17:F1016) -> 9.7179121
B1023: Histograma vs. densidad teórica (dominio [0, c])
H1024: h (altura meseta) = | I1024: =2/(-C4+C5+C6) -> 0.14285714
B1025: Bin | C1025: Lím. inf. | D1025: Lím. sup. | E1025: Punto medio | F1025: Frecuencia | G1025: Densidad emp. | H1025: Densidad teór.
B1026: 1 | C1026: =($C$6/20)*0 -> 0 | D1026: =($C$6/20)*1 -> 0.5 | E1026: =(C1026+D1026)/2 -> 0.25 | F1026: =COUNTIFS($F$17:$F$1016,">="&C1026,$F$17:$F$1016,"<"&D1026) -> 12 | G1026: =F1026/($C$7*(D1026-C1026)) -> 0.024 | H1026: =IF(E1026<=$C$4,$I$1024*E1026/$C$4,IF(E1026<=$C$5,$I$1024,$I$1024*($C$6-E1026)/($C$6-$C$5))) -> 0.011904762
B1027: 2 | C1027: =($C$6/20)*1 -> 0.5 | D1027: =($C$6/20)*2 -> 1 | E1027: =(C1027+D1027)/2 -> 0.75 | F1027: =COUNTIFS($F$17:$F$1016,">="&C1027,$F$17:$F$1016,"<"&D1027) -> 13 | G1027: =F1027/($C$7*(D1027-C1027)) -> 0.026 | H1027: =IF(E1027<=$C$4,$I$1024*E1027/$C$4,IF(E1027<=$C$5,$I$1024,$I$1024*($C$6-E1027)/($C$6-$C$5))) -> 0.035714286
B1028: 3 | C1028: =($C$6/20)*2 -> 1 | D1028: =($C$6/20)*3 -> 1.5 | E1028: =(C1028+D1028)/2 -> 1.25 | F1028: =COUNTIFS($F$17:$F$1016,">="&C1028,$F$17:$F$1016,"<"&D1028) -> 33 | G1028: =F1028/($C$7*(D1028-C1028)) -> 0.066 | H1028: =IF(E1028<=$C$4,$I$1024*E1028/$C$4,IF(E1028<=$C$5,$I$1024,$I$1024*($C$6-E1028)/($C$6-$C$5))) -> 0.05952381
B1029: 4 | C1029: =($C$6/20)*3 -> 1.5 | D1029: =($C$6/20)*4 -> 2 | E1029: =(C1029+D1029)/2 -> 1.75 | F1029: =COUNTIFS($F$17:$F$1016,">="&C1029,$F$17:$F$1016,"<"&D1029) -> 43 | G1029: =F1029/($C$7*(D1029-C1029)) -> 0.086 | H1029: =IF(E1029<=$C$4,$I$1024*E1029/$C$4,IF(E1029<=$C$5,$I$1024,$I$1024*($C$6-E1029)/($C$6-$C$5))) -> 0.083333333
B1030: 5 | C1030: =($C$6/20)*4 -> 2 | D1030: =($C$6/20)*5 -> 2.5 | E1030: =(C1030+D1030)/2 -> 2.25 | F1030: =COUNTIFS($F$17:$F$1016,">="&C1030,$F$17:$F$1016,"<"&D1030) -> 49 | G1030: =F1030/($C$7*(D1030-C1030)) -> 0.098 | H1030: =IF(E1030<=$C$4,$I$1024*E1030/$C$4,IF(E1030<=$C$5,$I$1024,$I$1024*($C$6-E1030)/($C$6-$C$5))) -> 0.10714286
B1031: 6 | C1031: =($C$6/20)*5 -> 2.5 | D1031: =($C$6/20)*6 -> 3 | E1031: =(C1031+D1031)/2 -> 2.75 | F1031: =COUNTIFS($F$17:$F$1016,">="&C1031,$F$17:$F$1016,"<"&D1031) -> 68 | G1031: =F1031/($C$7*(D1031-C1031)) -> 0.136 | H1031: =IF(E1031<=$C$4,$I$1024*E1031/$C$4,IF(E1031<=$C$5,$I$1024,$I$1024*($C$6-E1031)/($C$6-$C$5))) -> 0.13095238
B1032: 7 | C1032: =($C$6/20)*6 -> 3 | D1032: =($C$6/20)*7 -> 3.5 | E1032: =(C1032+D1032)/2 -> 3.25 | F1032: =COUNTIFS($F$17:$F$1016,">="&C1032,$F$17:$F$1016,"<"&D1032) -> 69 | G1032: =F1032/($C$7*(D1032-C1032)) -> 0.138 | H1032: =IF(E1032<=$C$4,$I$1024*E1032/$C$4,IF(E1032<=$C$5,$I$1024,$I$1024*($C$6-E1032)/($C$6-$C$5))) -> 0.14285714
B1033: 8 | C1033: =($C$6/20)*7 -> 3.5 | D1033: =($C$6/20)*8 -> 4 | E1033: =(C1033+D1033)/2 -> 3.75 | F1033: =COUNTIFS($F$17:$F$1016,">="&C1033,$F$17:$F$1016,"<"&D1033) -> 81 | G1033: =F1033/($C$7*(D1033-C1033)) -> 0.162 | H1033: =IF(E1033<=$C$4,$I$1024*E1033/$C$4,IF(E1033<=$C$5,$I$1024,$I$1024*($C$6-E1033)/($C$6-$C$5))) -> 0.14285714
B1034: 9 | C1034: =($C$6/20)*8 -> 4 | D1034: =($C$6/20)*9 -> 4.5 | E1034: =(C1034+D1034)/2 -> 4.25 | F1034: =COUNTIFS($F$17:$F$1016,">="&C1034,$F$17:$F$1016,"<"&D1034) -> 95 | G1034: =F1034/($C$7*(D1034-C1034)) -> 0.19 | H1034: =IF(E1034<=$C$4,$I$1024*E1034/$C$4,IF(E1034<=$C$5,$I$1024,$I$1024*($C$6-E1034)/($C$6-$C$5))) -> 0.14285714
...

Sheet Ejercicio 2 - Triangular V
B1: Ejercicio 2 — Distribución Triangular Método de Composición
B3: Parámetros
B4: a (punto 1) = | C4: 8 | G4: Debe cumplirse: a < c < b
B5: c (vértice) = | C5: 9
B6: b (punto 3) = | C6: 10
B7: N° simulaciones = | C7: 1000
B9: Áreas (Paso 1 de la teoría)
B10: A1 = | C10: =(C5-C4)/(C6-C4) -> 0.5
B11: A2 = | C11: =(C6-C5)/(C6-C4) -> 0.5
B12: Suma = | C12: =C10+C11 -> 1
B16: iteracion | C16: R_region | D16: R_valor | E16: Region | F16: X
B17: 1 | C17: =RAND() -> 0.51193726 | D17: =RAND() -> 0.68239737 | E17: =IF(C17<=$C$10,1,2) -> 2 | F17: =IF(E17=1,$C$4+SQRT(D17*($C$6-$C$4)*($C$5-$C$4)),$C$6-SQRT((1-D17)*($C$6-$C$4)*($C$6-$C$5))) -> 9.2030023
B18: 2 | C18: =RAND() -> 0.17642894 | D18: =RAND() -> 0.34367827 | E18: =IF(C18<=$C$10,1,2) -> 1 | F18: =IF(E18=1,$C$4+SQRT(D18*($C$6-$C$4)*($C$5-$C$4)),$C$6-SQRT((1-D18)*($C$6-$C$4)*($C$6-$C$5))) -> 8.8290697
B19: 3 | C19: =RAND() -> 0.62437814 | D19: =RAND() -> 0.4347957 | E19: =IF(C19<=$C$10,1,2) -> 2 | F19: =IF(E19=1,$C$4+SQRT(D19*($C$6-$C$4)*($C$5-$C$4)),$C$6-SQRT((1-D19)*($C$6-$C$4)*($C$6-$C$5))) -> 8.9367932
B20: 4 | C20: =RAND() -> 0.89771039 | D20: =RAND() -> 0.20628556 | E20: =IF(C20<=$C$10,1,2) -> 2 | F20: =IF(E20=1,$C$4+SQRT(D20*($C$6-$C$4)*($C$5-$C$4)),$C$6-SQRT((1-D20)*($C$6-$C$4)*($C$6-$C$5))) -> 8.7400679
B21: 5 | C21: =RAND() -> 0.21259379 | D21: =RAND() -> 0.30154255 | E21: =IF(C21<=$C$10,1,2) -> 1 | F21: =IF(E21=1,$C$4+SQRT(D21*($C$6-$C$4)*($C$5-$C$4)),$C$6-SQRT((1-D21)*($C$6-$C$4)*($C$6-$C$5))) -> 8.7765855
B22: 6 | C22: =RAND() -> 0.89425587 | D22: =RAND() -> 0.20207486 | E22: =IF(C22<=$C$10,1,2) -> 2 | F22: =IF(E22=1,$C$4+SQRT(D22*($C$6-$C$4)*($C$5-$C$4)),$C$6-SQRT((1-D22)*($C$6-$C$4)*($C$6-$C$5))) -> 8.7367303
B23: 7 | C23: =RAND() -> 0.79858053 | D23: =RAND() -> 0.26435538 | E23: =IF(C23<=$C$10,1,2) -> 2 | F23: =IF(E23=1,$C$4+SQRT(D23*($C$6-$C$4)*($C$5-$C$4)),$C$6-SQRT((1-D23)*($C$6-$C$4)*($C$6-$C$5))) -> 8.7870329
B24: 8 | C24: =RAND() -> 0.4767185 | D24: =RAND() -> 0.61853512 | E24: =IF(C24<=$C$10,1,2) -> 1 | F24: =IF(E24=1,$C$4+SQRT(D24*($C$6-$C$4)*($C$5-$C$4)),$C$6-SQRT((1-D24)*($C$6-$C$4)*($C$6-$C$5))) -> 9.1122366
B25: 9 | C25: =RAND() -> 0.026438389 | D25: =RAND() -> 0.76266291 | E25: =IF(C25<=$C$10,1,2) -> 1 | F25: =IF(E25=1,$C$4+SQRT(D25*($C$6-$C$4)*($C$5-$C$4)),$C$6-SQRT((1-D25)*($C$6-$C$4)*($C$6-$C$5))) -> 9.2350408
B26: 10 | C26: =RAND() -> 0.16560435 | D26: =RAND() -> 0.57434596 | E26: =IF(C26<=$C$10,1,2) -> 1 | F26: =IF(E26=1,$C$4+SQRT(D26*($C$6-$C$4)*($C$5-$C$4)),$C$6-SQRT((1-D26)*($C$6-$C$4)*($C$6-$C$5))) -> 9.0717705
B27: 11 | C27: =RAND() -> 0.48269134 | D27: =RAND() -> 0.71878955 | E27: =IF(C27<=$C$10,1,2) -> 1 | F27: =IF(E27=1,$C$4+SQRT(D27*($C$6-$C$4)*($C$5-$C$4)),$C$6-SQRT((1-D27)*($C$6-$C$4)*($C$6-$C$5))) -> 9.1989909
B28: 12 | C28: =RAND() -> 0.67832309 | D28: =RAND() -> 0.35218407 | E28: =IF(C28<=$C$10,1,2) -> 2 | F28: =IF(E28=1,$C$4+SQRT(D28*($C$6-$C$4)*($C$5-$C$4)),$C$6-SQRT((1-D28)*($C$6-$C$4)*($C$6-$C$5))) -> 8.8617417
... B1016: 1000 | C1016: =RAND() -> 0.32997644 | D1016: =RAND() -> 0.74283138 | E1016: =IF(C1016<=$C$10,1,2) -> 1 | F1016: =IF(E1016=1,$C$4+SQRT(D1016*($C$6-$C$4)*($C$5-$C$4)),$C$6-SQRT((1-D1016)*($C$6-$C$4)*($C$6-$C$5))) -> 9.2188777
B1018: Promedio X = | C1018: =AVERAGE(F17:F1016) -> 8.9869469
B1019: Mínimo X = | C1019: =MIN(F17:F1016) -> 8.1166267
B1020: Máximo X = | C1020: =MAX(F17:F1016) -> 9.9418915
B1023: Histograma vs. densidad teórica (dominio [a, b])
B1024: Bin | C1024: Lím. inf. | D1024: Lím. sup. | E1024: Punto medio | F1024: Frecuencia | G1024: Densidad emp. | H1024: Densidad teór.
B1025: 1 | C1025: =$C$4+(($C$6-$C$4)/20)*0 -> 8 | D1025: =$C$4+(($C$6-$C$4)/20)*1 -> 8.1 | E1025: =(C1025+D1025)/2 -> 8.05 | F1025: =COUNTIFS($F$17:$F$1016,">="&C1025,$F$17:$F$1016,"<"&D1025) -> 0 | G1025: =F1025/($C$7*(D1025-C1025)) -> 0 | H1025: =IF(E1025<=$C$5,2*(E1025-$C$4)/(($C$6-$C$4)*($C$5-$C$4)),2*($C$6-E1025)/(($C$6-$C$4)*($C$6-$C$5))) -> 0.05
B1026: 2 | C1026: =$C$4+(($C$6-$C$4)/20)*1 -> 8.1 | D1026: =$C$4+(($C$6-$C$4)/20)*2 -> 8.2 | E1026: =(C1026+D1026)/2 -> 8.15 | F1026: =COUNTIFS($F$17:$F$1016,">="&C1026,$F$17:$F$1016,"<"&D1026) -> 11 | G1026: =F1026/($C$7*(D1026-C1026)) -> 0.11 | H1026: =IF(E1026<=$C$5,2*(E1026-$C$4)/(($C$6-$C$4)*($C$5-$C$4)),2*($C$6-E1026)/(($C$6-$C$4)*($C$6-$C$5))) -> 0.15
B1027: 3 | C1027: =$C$4+(($C$6-$C$4)/20)*2 -> 8.2 | D1027: =$C$4+(($C$6-$C$4)/20)*3 -> 8.3 | E1027: =(C1027+D1027)/2 -> 8.25 | F1027: =COUNTIFS($F$17:$F$1016,">="&C1027,$F$17:$F$1016,"<"&D1027) -> 18 | G1027: =F1027/($C$7*(D1027-C1027)) -> 0.18 | H1027: =IF(E1027<=$C$5,2*(E1027-$C$4)/(($C$6-$C$4)*($C$5-$C$4)),2*($C$6-E1027)/(($C$6-$C$4)*($C$6-$C$5))) -> 0.25
B1028: 4 | C1028: =$C$4+(($C$6-$C$4)/20)*3 -> 8.3 | D1028: =$C$4+(($C$6-$C$4)/20)*4 -> 8.4 | E1028: =(C1028+D1028)/2 -> 8.35 | F1028: =COUNTIFS($F$17:$F$1016,">="&C1028,$F$17:$F$1016,"<"&D1028) -> 16 | G1028: =F1028/($C$7*(D1028-C1028)) -> 0.16 | H1028: =IF(E1028<=$C$5,2*(E1028-$C$4)/(($C$6-$C$4)*($C$5-$C$4)),2*($C$6-E1028)/(($C$6-$C$4)*($C$6-$C$5))) -> 0.35
B1029: 5 | C1029: =$C$4+(($C$6-$C$4)/20)*4 -> 8.4 | D1029: =$C$4+(($C$6-$C$4)/20)*5 -> 8.5 | E1029: =(C1029+D1029)/2 -> 8.45 | F1029: =COUNTIFS($F$17:$F$1016,">="&C1029,$F$17:$F$1016,"<"&D1029) -> 24 | G1029: =F1029/($C$7*(D1029-C1029)) -> 0.24 | H1029: =IF(E1029<=$C$5,2*(E1029-$C$4)/(($C$6-$C$4)*($C$5-$C$4)),2*($C$6-E1029)/(($C$6-$C$4)*($C$6-$C$5))) -> 0.45
B1030: 6 | C1030: =$C$4+(($C$6-$C$4)/20)*5 -> 8.5 | D1030: =$C$4+(($C$6-$C$4)/20)*6 -> 8.6 | E1030: =(C1030+D1030)/2 -> 8.55 | F1030: =COUNTIFS($F$17:$F$1016,">="&C1030,$F$17:$F$1016,"<"&D1030) -> 32 | G1030: =F1030/($C$7*(D1030-C1030)) -> 0.32 | H1030: =IF(E1030<=$C$5,2*(E1030-$C$4)/(($C$6-$C$4)*($C$5-$C$4)),2*($C$6-E1030)/(($C$6-$C$4)*($C$6-$C$5))) -> 0.55
B1031: 7 | C1031: =$C$4+(($C$6-$C$4)/20)*6 -> 8.6 | D1031: =$C$4+(($C$6-$C$4)/20)*7 -> 8.7 | E1031: =(C1031+D1031)/2 -> 8.65 | F1031: =COUNTIFS($F$17:$F$1016,">="&C1031,$F$17:$F$1016,"<"&D1031) -> 97 | G1031: =F1031/($C$7*(D1031-C1031)) -> 0.97 | H1031: =IF(E1031<=$C$5,2*(E1031-$C$4)/(($C$6-$C$4)*($C$5-$C$4)),2*($C$6-E1031)/(($C$6-$C$4)*($C$6-$C$5))) -> 0.65
B1032: 8 | C1032: =$C$4+(($C$6-$C$4)/20)*7 -> 8.7 | D1032: =$C$4+(($C$6-$C$4)/20)*8 -> 8.8 | E1032: =(C1032+D1032)/2 -> 8.75 | F1032: =COUNTIFS($F$17:$F$1016,">="&C1032,$F$17:$F$1016,"<"&D1032) -> 110 | G1032: =F1032/($C$7*(D1032-C1032)) -> 1.1 | H1032: =IF(E1032<=$C$5,2*(E1032-$C$4)/(($C$6-$C$4)*($C$5-$C$4)),2*($C$6-E1032)/(($C$6-$C$4)*($C$6-$C$5))) -> 0.75
B1033: 9 | C1033: =$C$4+(($C$6-$C$4)/20)*8 -> 8.8 | D1033: =$C$4+(($C$6-$C$4)/20)*9 -> 8.9 | E1033: =(C1033+D1033)/2 -> 8.85 | F1033: =COUNTIFS($F$17:$F$1016,">="&C1033,$F$17:$F$1016,"<"&D1033) -> 113 | G1033: =F1033/($C$7*(D1033-C1033)) -> 1.13 | H1033: =IF(E1033<=$C$5,2*(E1033-$C$4)/(($C$6-$C$4)*($C$5-$C$4)),2*($C$6-E1033)/(($C$6-$C$4)*($C$6-$C$5))) -> 0.85
B1034: 10 | C1034: =$C$4+(($C$6-$C$4)/20)*9 -> 8.9 | D1034: =$C$4+(($C$6-$C$4)/20)*10 -> 9 | E1034: =(C1034+D1034)/2 -> 8.95 | F1034: =COUNTIFS($F$17:$F$1016,">="&C1034,$F$17:$F$1016,"<"&D1034) -> 84 | G1034: =F1034/($C$7*(D1034-C1034)) -> 0.84 | H1034: =IF(E1034<=$C$5,2*(E1034-$C$4)/(($C$6-$C$4)*($C$5-$C$4)),2*($C$6-E1034)/(($C$6-$C$4)*($C$6-$C$5))) -> 0.95
B1035: 11 | C1035: =$C$4+(($C$6-$C$4)/20)*10 -> 9 | D1035: =$C$4+(($C$6-$C$4)/20)*11 -> 9.1 | E1035: =(C1035+D1035)/2 -> 9.05 | F1035: =COUNTIFS($F$17:$F$1016,">="&C1035,$F$17:$F$1016,"<"&D1035) -> 106 | G1035: =F1035/($C$7*(D1035-C1035)) -> 1.06 | H1035: =IF(E1035<=$C$5,2*(E1035-$C$4)/(($C$6-$C$4)*($C$5-$C$4)),2*($C$6-E1035)/(($C$6-$C$4)*($C$6-$C$5))) -> 0.95
...

Sheet Ejercicio 3 - TIR
B2: EJERCICIO 3 TIR del proyecto Compañía X
B4: Parámetros generales
B5: Tasa de impuestos (T) | D5: 0.5
B6: TREMA | D6: 0.15
B7: Vida fiscal del activo (años) | D7: 5
B8: Umbral de aceptación Prob(TIR>TREMA) | D8: 0.9
B9: Número de simulaciones | D9: 1000
B11: Activo fijo y activo circulante inicial (distribución triangular)
B12: Variable | C12: a (mínimo / optimista) | D12: b (moda / más probable) | E12: c (máximo / pesimista)
B13: Activo fijo inicial (AF) | C13: 60000 | D13: 70000 | E13: 100000
B14: Activo circulante inicial (AC) | C14: 25000 | D14: 30000 | E14: 40000
B16: Flujo de efectivo antes de impuestos, por año (triangular, igual los 5 años)
B17: Variable | C17: a (mínimo / optimista) | D17: b (moda / más probable) | E17: c (máximo / pesimista)
B18: Flujo antes de impuestos (x) | C18: 30000 | D18: 40000 | E18: 45000
B20: Tasas de inflación, por año (triangular)
B21: Año | C21: a (mínimo / optimista) | D21: b (moda / más probable) | E21: c (máximo / pesimista)
B22: 1 | C22: 0.12 | D22: 0.15 | E22: 0.18
B23: 2 | C23: 0.12 | D23: 0.15 | E23: 0.18
B24: 3 | C24: 0.15 | D24: 0.18 | E24: 0.22
B25: 4 | C25: 0.18 | D25: 0.2 | E25: 0.25
B26: 5 | C26: 0.19 | D26: 0.22 | E26: 0.28
B29: Extremos teóricos
B30: TIR mínima (todo pesimista) | D30: -0.031
B31: TIR máxima (todo optimista) | D31: 0.1991
B34: ── Resultados de la simulación ──
B35: Tabla de frecuencia acumulada de la TIR simulada (Pasos 3, 8 y 9)
B36: Intervalo # | C36: Límite inferior (%) | D36: Límite superior (%) | E36: Frecuencia | F36: Fracción | G36: Fracción acumulada
B37: 1 | C37: =$D$30*100 -> -3.1 | D37: =$D$30*100+($D$31*100-$D$30*100)/20*1 -> -1.9495 | E37: =COUNTIFS('Ejercicio 3 - Simulacion'!$BV$2:$BV$1001,">="&C37,'Ejercicio 3 - Simulacion'!$BV$2:$BV$1001,"<="&D37) -> 0 | F37: =E37/$D$9 -> 0 | G37: =F37 -> 0
B38: 2 | C38: =D37 -> -1.9495 | D38: =$D$30*100+($D$31*100-$D$30*100)/20*2 -> -0.799 | E38: =COUNTIFS('Ejercicio 3 - Simulacion'!$BV$2:$BV$1001,">"&C38,'Ejercicio 3 - Simulacion'!$BV$2:$BV$1001,"<="&D38) -> 0 | F38: =E38/$D$9 -> 0 | G38: =G37+F38 -> 0
B39: 3 | C39: =D38 -> -0.799 | D39: =$D$30*100+($D$31*100-$D$30*100)/20*3 -> 0.3515 | E39: =COUNTIFS('Ejercicio 3 - Simulacion'!$BV$2:$BV$1001,">"&C39,'Ejercicio 3 - Simulacion'!$BV$2:$BV$1001,"<="&D39) -> 0 | F39: =E39/$D$9 -> 0 | G39: =G38+F39 -> 0
B40: 4 | C40: =D39 -> 0.3515 | D40: =$D$30*100+($D$31*100-$D$30*100)/20*4 -> 1.502 | E40: =COUNTIFS('Ejercicio 3 - Simulacion'!$BV$2:$BV$1001,">"&C40,'Ejercicio 3 - Simulacion'!$BV$2:$BV$1001,"<="&D40) -> 0 | F40: =E40/$D$9 -> 0 | G40: =G39+F40 -> 0
B41: 5 | C41: =D40 -> 1.502 | D41: =$D$30*100+($D$31*100-$D$30*100)/20*5 -> 2.6525 | E41: =COUNTIFS('Ejercicio 3 - Simulacion'!$BV$2:$BV$1001,">"&C41,'Ejercicio 3 - Simulacion'!$BV$2:$BV$1001,"<="&D41) -> 3 | F41: =E41/$D$9 -> 0.003 | G41: =G40+F41 -> 0.003
B42: 6 | C42: =D41 -> 2.6525 | D42: =$D$30*100+($D$31*100-$D$30*100)/20*6 -> 3.803 | E42: =COUNTIFS('Ejercicio 3 - Simulacion'!$BV$2:$BV$1001,">"&C42,'Ejercicio 3 - Simulacion'!$BV$2:$BV$1001,"<="&D42) -> 30 | F42: =E42/$D$9 -> 0.03 | G42: =G41+F42 -> 0.033
B43: 7 | C43: =D42 -> 3.803 | D43: =$D$30*100+($D$31*100-$D$30*100)/20*7 -> 4.9535 | E43: =COUNTIFS('Ejercicio 3 - Simulacion'!$BV$2:$BV$1001,">"&C43,'Ejercicio 3 - Simulacion'!$BV$2:$BV$1001,"<="&D43) -> 74 | F43: =E43/$D$9 -> 0.074 | G43: =G42+F43 -> 0.107
B44: 8 | C44: =D43 -> 4.9535 | D44: =$D$30*100+($D$31*100-$D$30*100)/20*8 -> 6.104 | E44: =COUNTIFS('Ejercicio 3 - Simulacion'!$BV$2:$BV$1001,">"&C44,'Ejercicio 3 - Simulacion'!$BV$2:$BV$1001,"<="&D44) -> 146 | F44: =E44/$D$9 -> 0.146 | G44: =G43+F44 -> 0.253
B45: 9 | C45: =D44 -> 6.104 | D45: =$D$30*100+($D$31*100-$D$30*100)/20*9 -> 7.2545 | E45: =COUNTIFS('Ejercicio 3 - Simulacion'!$BV$2:$BV$1001,">"&C45,'Ejercicio 3 - Simulacion'!$BV$2:$BV$1001,"<="&D45) -> 176 | F45: =E45/$D$9 -> 0.176 | G45: =G44+F45 -> 0.429
B46: 10 | C46: =D45 -> 7.2545 | D46: =$D$30*100+($D$31*100-$D$30*100)/20*10 -> 8.405 | E46: =COUNTIFS('Ejercicio 3 - Simulacion'!$BV$2:$BV$1001,">"&C46,'Ejercicio 3 - Simulacion'!$BV$2:$BV$1001,"<="&D46) -> 193 | F46: =E46/$D$9 -> 0.193 | G46: =G45+F46 -> 0.622
B47: 11 | C47: =D46 -> 8.405 | D47: =$D$30*100+($D$31*100-$D$30*100)/20*11 -> 9.5555 | E47: =COUNTIFS('Ejercicio 3 - Simulacion'!$BV$2:$BV$1001,">"&C47,'Ejercicio 3 - Simulacion'!$BV$2:$BV$1001,"<="&D47) -> 187 | F47: =E47/$D$9 -> 0.187 | G47: =G46+F47 -> 0.809
B48: 12 | C48: =D47 -> 9.5555 | D48: =$D$30*100+($D$31*100-$D$30*100)/20*12 -> 10.706 | E48: =COUNTIFS('Ejercicio 3 - Simulacion'!$BV$2:$BV$1001,">"&C48,'Ejercicio 3 - Simulacion'!$BV$2:$BV$1001,"<="&D48) -> 112 | F48: =E48/$D$9 -> 0.112 | G48: =G47+F48 -> 0.921
B49: 13 | C49: =D48 -> 10.706 | D49: =$D$30*100+($D$31*100-$D$30*100)/20*13 -> 11.8565 | E49: =COUNTIFS('Ejercicio 3 - Simulacion'!$BV$2:$BV$1001,">"&C49,'Ejercicio 3 - Simulacion'!$BV$2:$BV$1001,"<="&D49) -> 52 | F49: =E49/$D$9 -> 0.052 | G49: =G48+F49 -> 0.973
...

Sheet Ejercicio 3 - Simulacion
A1: N° sim | B1: R (AF) | C1: AF simulado | D1: R (AC) | E1: AC simulado | F1: R (x año 1) | G1: x año 1 | H1: R (x año 2) | I1: x año 2 | J1: R (x año 3) | K1: x año 3 | L1: R (x año 4) | M1: x año 4 | N1: R (x año 5) | O1: x año 5 | P1: R (i año 1) | Q1: i año 1 | R1: R (i año 2) | S1: i año 2 | T1: R (i año 3) | U1: i año 3 | V1: R (i año 4) | W1: i año 4 | X1: R (i año 5) | Y1: i año 5 | Z1: Inflación acum. año 1 | AA1: Inflación acum. año 2 | AB1: Inflación acum. año 3 | AC1: Inflación acum. año 4 | AD1: Inflación acum. año 5 | AE1: Inv. adicional AC año 1 | AF1: Inv. adicional AC año 2 | AG1: Inv. adicional AC año 3 | AH1: Inv. adicional AC año 4 | AI1: Inv. adicional AC año 5 | AJ1: Flujo antes imp. año 1 (corriente) | AK1: Flujo antes imp. año 2 (corriente) | AL1: Flujo antes imp. año 3 (corriente) | AM1: Flujo antes imp. año 4 (corriente) | AN1: Flujo antes imp. año 5 (corriente) | AO1: Depreciación (fija) | AP1: Ingreso gravable año 1 | AQ1: Ingreso gravable año 2 | AR1: Ingreso gravable año 3 | AS1: Ingreso gravable año 4 | AT1: Ingreso gravable año 5 | AU1: Impuestos año 1 | AV1: Impuestos año 2 | AW1: Impuestos año 3 | AX1: Impuestos año 4 | AY1: Impuestos año 5 | AZ1: Flujo desp. imp. año 1 (corriente) | BA1: Flujo desp. imp. año 2 (corriente) | BB1: Flujo desp. imp. año 3 (corriente) | BC1: Flujo desp. imp. año 4 (corriente) | BD1: Flujo desp. imp. año 5 (corriente) | BE1: Flujo desp. imp. año 1 (constante) | BF1: Flujo desp. imp. año 2 (constante) | BG1: Flujo desp. imp. año 3 (constante) | BH1: Flujo desp. imp. año 4 (constante) | BI1: Flujo desp. imp. año 5 (constante) | BJ1: VR: AC recuperado (nominal) | BK1: VR: 20% AF recuperado (nominal) | BL1: VR antes de impuestos | BM1: VR impuestos | BN1: VR pesos corrientes | BO1: VR pesos constantes | BP1: Flujo año 0 | BQ1: Flujo año 1 | BR1: Flujo año 2 | BS1: Flujo año 3 | BT1: Flujo año 4 | BU1: Flujo año 5 | BV1: TIR simulada
A2: 1 | B2: =RAND() -> 0.77641167 | C2: =IF(B2<=('Ejercicio 3 - TIR'!$D$13-'Ejercicio 3 - TIR'!$C$13)/('Ejercicio 3 - TIR'!$E$13-'Ejercicio 3 - TIR'!$C$13),'Ejercicio 3 - TIR'!$C$13+SQRT(('Ejercicio 3 - TIR'!$E$13-'Ejercicio 3 - TIR'!$C$13)*('Ejercicio 3 - TIR'!$D$13-'Ejercicio 3 - TIR'!$C$13)*B2),'Ejercicio 3 - TIR'!$E$13-SQRT(('Ejercicio 3 - TIR'!$E$13-'Ejercicio 3 - TIR'!$C$13)*('Ejercicio 3 - TIR'!$E$13-'Ejercicio 3 - TIR'!$D$13)*(1-B2))) -> 83619.951 | D2: =RAND() -> 0.93080842 | E2: =IF(D2<=('Ejercicio 3 - TIR'!$D$14-'Ejercicio 3 - TIR'!$C$14)/('Ejercicio 3 - TIR'!$E$14-'Ejercicio 3 - TIR'!$C$14),'Ejercicio 3 - TIR'!$C$14+SQRT(('Ejercicio 3 - TIR'!$E$14-'Ejercicio 3 - TIR'!$C$14)*('Ejercicio 3 - TIR'!$D$14-'Ejercicio 3 - TIR'!$C$14)*D2),'Ejercicio 3 - TIR'!$E$14-SQRT(('Ejercicio 3 - TIR'!$E$14-'Ejercicio 3 - TIR'!$C$14)*('Ejercicio 3 - TIR'!$E$14-'Ejercicio 3 - TIR'!$D$14)*(1-D2))) -> 36778.395 | F2: =RAND() -> 0.21999643 | G2: =IF(F2<=('Ejercicio 3 - TIR'!$D$18-'Ejercicio 3 - TIR'!$C$18)/('Ejercicio 3 - TIR'!$E$18-'Ejercicio 3 - TIR'!$C$18),'Ejercicio 3 - TIR'!$C$18+SQRT(('Ejercicio 3 - TIR'!$E$18-'Ejercicio 3 - TIR'!$C$18)*('Ejercicio 3 - TIR'!$D$18-'Ejercicio 3 - TIR'!$C$18)*F2),'Ejercicio 3 - TIR'!$E$18-SQRT(('Ejercicio 3 - TIR'!$E$18-'Ejercicio 3 - TIR'!$C$18)*('Ejercicio 3 - TIR'!$E$18-'Ejercicio 3 - TIR'!$D$18)*(1-F2))) -> 35744.516 | H2: =RAND() -> 0.044823029 | I2: =IF(H2<=('Ejercicio 3 - TIR'!$D$18-'Ejercicio 3 - TIR'!$C$18)/('Ejercicio 3 - TIR'!$E$18-'Ejercicio 3 - TIR'!$C$18),'Ejercicio 3 - TIR'!$C$18+SQRT(('Ejercicio 3 - TIR'!$E$18-'Ejercicio 3 - TIR'!$C$18)*('Ejercicio 3 - TIR'!$D$18-'Ejercicio 3 - TIR'!$C$18)*H2),'Ejercicio 3 - TIR'!$E$18-SQRT(('Ejercicio 3 - TIR'!$E$18-'Ejercicio 3 - TIR'!$C$18)*('Ejercicio 3 - TIR'!$E$18-'Ejercicio 3 - TIR'!$D$18)*(1-H2))) -> 32592.962 | J2: =RAND() -> 0.25378243 | K2: =IF(J2<=('Ejercicio 3 - TIR'!$D$18-'Ejercicio 3 - TIR'!$C$18)/('Ejercicio 3 - TIR'!$E$18-'Ejercicio 3 - TIR'!$C$18),'Ejercicio 3 - TIR'!$C$18+SQRT(('Ejercicio 3 - TIR'!$E$18-'Ejercicio 3 - TIR'!$C$18)*('Ejercicio 3 - TIR'!$D$18-'Ejercicio 3 - TIR'!$C$18)*J2),'Ejercicio 3 - TIR'!$E$18-SQRT(('Ejercicio 3 - TIR'!$E$18-'Ejercicio 3 - TIR'!$C$18)*('Ejercicio 3 - TIR'!$E$18-'Ejercicio 3 - TIR'!$D$18)*(1-J2))) -> 36169.876 | L2: =RAND() -> 0.3962191 | M2: =IF(L2<=('Ejercicio 3 - TIR'!$D$18-'Ejercicio 3 - TIR'!$C$18)/('Ejercicio 3 - TIR'!$E$18-'Ejercicio 3 - TIR'!$C$18),'Ejercicio 3 - TIR'!$C$18+SQRT(('Ejercicio 3 - TIR'!$E$18-'Ejercicio 3 - TIR'!$C$18)*('Ejercicio 3 - TIR'!$D$18-'Ejercicio 3 - TIR'!$C$18)*L2),'Ejercicio 3 - TIR'!$E$18-SQRT(('Ejercicio 3 - TIR'!$E$18-'Ejercicio 3 - TIR'!$C$18)*('Ejercicio 3 - TIR'!$E$18-'Ejercicio 3 - TIR'!$D$18)*(1-L2))) -> 37709.271 | N2: =RAND() -> 0.93415073 | O2: =IF(N2<=('Ejercicio 3 - TIR'!$D$18-'Ejercicio 3 - TIR'!$C$18)/('Ejercicio 3 - TIR'!$E$18-'Ejercicio 3 - TIR'!$C$18),'Ejercicio 3 - TIR'!$C$18+SQRT(('Ejercicio 3 - TIR'!$E$18-'Ejercicio 3 - TIR'!$C$18)*('Ejercicio 3 - TIR'!$D$18-'Ejercicio 3 - TIR'!$C$18)*N2),'Ejercicio 3 - TIR'!$E$18-SQRT(('Ejercicio 3 - TIR'!$E$18-'Ejercicio 3 - TIR'!$C$18)*('Ejercicio 3 - TIR'!$E$18-'Ejercicio 3 - TIR'!$D$18)*(1-N2))) -> 42777.682 | P2: =RAND() -> 0.87452574 | Q2: =IF(P2<=('Ejercicio 3 - TIR'!$D$22-'Ejercicio 3 - TIR'!$C$22)/('Ejercicio 3 - TIR'!$E$22-'Ejercicio 3 - TIR'!$C$22),'Ejercicio 3 - TIR'!$C$22+SQRT(('Ejercicio 3 - TIR'!$E$22-'Ejercicio 3 - TIR'!$C$22)*('Ejercicio 3 - TIR'!$D$22-'Ejercicio 3 - TIR'!$C$22)*P2),'Ejercicio 3 - TIR'!$E$22-SQRT(('Ejercicio 3 - TIR'!$E$22-'Ejercicio 3 - TIR'!$C$22)*('Ejercicio 3 - TIR'!$E$22-'Ejercicio 3 - TIR'!$D$22)*(1-P2))) -> 0.16497157 | R2: =RAND() -> 0.7387549 | S2: =IF(R2<=('Ejercicio 3 - TIR'!$D$23-'Ejercicio 3 - TIR'!$C$23)/('Ejercicio 3 - TIR'!$E$23-'Ejercicio 3 - TIR'!$C$23),'Ejercicio 3 - TIR'!$C$23+SQRT(('Ejercicio 3 - TIR'!$E$23-'Ejercicio 3 - TIR'!$C$23)*('Ejercicio 3 - TIR'!$D$23-'Ejercicio 3 - TIR'!$C$23)*R2),'Ejercicio 3 - TIR'!$E$23-SQRT(('Ejercicio 3 - TIR'!$E$23-'Ejercicio 3 - TIR'!$C$23)*('Ejercicio 3 - TIR'!$E$23-'Ejercicio 3 - TIR'!$D$23)*(1-R2))) -> 0.15831495 | T2: =RAND() -> 0.13502568 | U2: =IF(T2<=('Ejercicio 3 - TIR'!$D$24-'Ejercicio 3 - TIR'!$C$24)/('Ejercicio 3 - TIR'!$E$24-'Ejercicio 3 - TIR'!$C$24),'Ejercicio 3 - TIR'!$C$24+SQRT(('Ejercicio 3 - TIR'!$E$24-'Ejercicio 3 - TIR'!$C$24)*('Ejercicio 3 - TIR'!$D$24-'Ejercicio 3 - TIR'!$C$24)*T2),'Ejercicio 3 - TIR'!$E$24-SQRT(('Ejercicio 3 - TIR'!$E$24-'Ejercicio 3 - TIR'!$C$24)*('Ejercicio 3 - TIR'!$E$24-'Ejercicio 3 - TIR'!$D$24)*(1-T2))) -> 0.16683906 | V2: =RAND() -> 0.32444266 | W2: =IF(V2<=('Ejercicio 3 - TIR'!$D$25-'Ejercicio 3 - TIR'!$C$25)/('Ejercicio 3 - TIR'!$E$25-'Ejercicio 3 - TIR'!$C$25),'Ejercicio 3 - TIR'!$C$25+SQRT(('Ejercicio 3 - TIR'!$E$25-'Ejercicio 3 - TIR'!$C$25)*('Ejercicio 3 - TIR'!$D$25-'Ejercicio 3 - TIR'!$C$25)*V2),'Ejercicio 3 - TIR'!$E$25-SQRT(('Ejercicio 3 - TIR'!$E$25-'Ejercicio 3 - TIR'!$C$25)*('Ejercicio 3 - TIR'!$E$25-'Ejercicio 3 - TIR'!$D$25)*(1-V2))) -> 0.20137438 | X2: =RAND() -> 0.83367503 | Y2: =IF(X2<=('Ejercicio 3 - TIR'!$D$26-'Ejercicio 3 - TIR'!$C$26)/('Ejercicio 3 - TIR'!$E$26-'Ejercicio 3 - TIR'!$C$26),'Ejercicio 3 - TIR'!$C$26+SQRT(('Ejercicio 3 - TIR'!$E$26-'Ejercicio 3 - TIR'!$C$26)*('Ejercicio 3 - TIR'!$D$26-'Ejercicio 3 - TIR'!$C$26)*X2),'Ejercicio 3 - TIR'!$E$26-SQRT(('Ejercicio 3 - TIR'!$E$26-'Ejercicio 3 - TIR'!$C$26)*('Ejercicio 3 - TIR'!$E$26-'Ejercicio 3 - TIR'!$D$26)*(1-X2))) -> 0.25003077 | Z2: =(1+Q2) -> 1.1649716 | AA2: =Z2*(1+S2) -> 1.349404 | AB2: =AA2*(1+U2) -> 1.5745373 | AC2: =AB2*(1+W2) -> 1.8916088 | AD2: =AC2*(1+Y2) -> 2.3645692 | AE2: =E2*Q2 -> 6067.3897 | AF2: =AE2*(1+S2) -> 7027.9482 | AG2: =AF2*(1+U2) -> 8200.4844 | AH2: =AG2*(1+W2) -> 9851.8519 | AI2: =AH2*(1+Y2) -> 12315.118 | AJ2: =G2*Z2 -> 41641.345 | AK2: =I2*AA2 -> 43981.074 | AL2: =K2*AB2 -> 56950.818 | AM2: =M2*AC2 -> 71331.188 | AN2: =O2*AD2 -> 101150.79 | AO2: =C2/'Ejercicio 3 - TIR'!$D$7 -> 16723.99 | AP2: =AJ2-AO2 -> 24917.355 | AQ2: =AK2-AO2 -> 27257.083 | AR2: =AL2-AO2 -> 40226.828 | AS2: =AM2-AO2 -> 54607.198 | AT2: =AN2-AO2 -> 84426.798 | AU2: =AP2*'Ejercicio 3 - TIR'!$D$5 -> 12458.677 | AV2: =AQ2*'Ejercicio 3 - TIR'!$D$5 -> 13628.542 | AW2: =AR2*'Ejercicio 3 - TIR'!$D$5 -> 20113.414 | AX2: =AS2*'Ejercicio 3 - TIR'!$D$5 -> 27303.599 | AY2: =AT2*'Ejercicio 3 - TIR'!$D$5 -> 42213.399 | AZ2: =AJ2-AU2-AE2 -> 23115.278 | BA2: =AK2-AV2-AF2 -> 23324.584 | BB2: =AL2-AW2-AG2 -> 28636.92 | BC2: =AM2-AX2-AH2 -> 34175.737 | BD2: =AN2-AY2-AI2 -> 46622.271 | BE2: =AZ2/Z2 -> 19841.925 | BF2: =BA2/AA2 -> 17285.101 | BG2: =BB2/AB2 -> 18187.514 | BH2: =BC2/AC2 -> 18067.022 | BI2: =BD2/AD2 -> 19717.026 | BJ2: =E2*AD2 -> 86965.059 | BK2: =0.2*C2*AD2 -> 39545.031 | BL2: =BJ2+BK2 -> 126510.09 | BM2: =BK2*'Ejercicio 3 - TIR'!$D$5 -> 19772.516 | BN2: =BL2-BM2 -> 106737.57 | BO2: =BN2/AD2 -> 45140.39 | BP2: =-(C2+E2) -> -120398.35 | BQ2: =BE2 -> 19841.925 | BR2: =BF2 -> 17285.101 | BS2: =BG2 -> 18187.514 | BT2: =BH2 -> 18067.022 | BU2: =BI2+BO2 -> 64857.416 | BV2: =IFERROR(IRR(BP2:BU2,0.1),NA())*100 -> 3.898642
A3: 2 | B3: =RAND() -> 0.20991637 | C3: =IF(B3<=('Ejercicio 3 - TIR'!$D$13-'Ejercicio 3 - TIR'!$C$13)/('Ejercicio 3 - TIR'!$E$13-'Ejercicio 3 - TIR'!$C$13),'Ejercicio 3 - TIR'!$C$13+SQRT(('Ejercicio 3 - TIR'!$E$13-'Ejercicio 3 - TIR'!$C$13)*('Ejercicio 3 - TIR'!$D$13-'Ejercicio 3 - TIR'!$C$13)*B3),'Ejercicio 3 - TIR'!$E$13-SQRT(('Ejercicio 3 - TIR'!$E$13-'Ejercicio 3 - TIR'!$C$13)*('Ejercicio 3 - TIR'!$E$13-'Ejercicio 3 - TIR'!$D$13)*(1-B3))) -> 69163.326 | D3: =RAND() -> 0.45181736 | E3: =IF(D3<=('Ejercicio 3 - TIR'!$D$14-'Ejercicio 3 - TIR'!$C$14)/('Ejercicio 3 - TIR'!$E$14-'Ejercicio 3 - TIR'!$C$14),'Ejercicio 3 - TIR'!$C$14+SQRT(('Ejercicio 3 - TIR'!$E$14-'Ejercicio 3 - TIR'!$C$14)*('Ejercicio 3 - TIR'!$D$14-'Ejercicio 3 - TIR'!$C$14)*D3),'Ejercicio 3 - TIR'!$E$14-SQRT(('Ejercicio 3 - TIR'!$E$14-'Ejercicio 3 - TIR'!$C$14)*('Ejercicio 3 - TIR'!$E$14-'Ejercicio 3 - TIR'!$D$14)*(1-D3))) -> 30932.068 | F3: =RAND() -> 0.52966332 | G3: =IF(F3<=('Ejercicio 3 - TIR'!$D$18-'Ejercicio 3 - TIR'!$C$18)/('Ejercicio 3 - TIR'!$E$18-'Ejercicio 3 - TIR'!$C$18),'Ejercicio 3 - TIR'!$C$18+SQRT(('Ejercicio 3 - TIR'!$E$18-'Ejercicio 3 - TIR'!$C$18)*('Ejercicio 3 - TIR'!$D$18-'Ejercicio 3 - TIR'!$C$18)*F3),'Ejercicio 3 - TIR'!$E$18-SQRT(('Ejercicio 3 - TIR'!$E$18-'Ejercicio 3 - TIR'!$C$18)*('Ejercicio 3 - TIR'!$E$18-'Ejercicio 3 - TIR'!$D$18)*(1-F3))) -> 38913.445 | H3: =RAND() -> 0.54846966 | I3: =IF(H3<=('Ejercicio 3 - TIR'!$D$18-'Ejercicio 3 - TIR'!$C$18)/('Ejercicio 3 - TIR'!$E$18-'Ejercicio 3 - TIR'!$C$18),'Ejercicio 3 - TIR'!$C$18+SQRT(('Ejercicio 3 - TIR'!$E$18-'Ejercicio 3 - TIR'!$C$18)*('Ejercicio 3 - TIR'!$D$18-'Ejercicio 3 - TIR'!$C$18)*H3),'Ejercicio 3 - TIR'!$E$18-SQRT(('Ejercicio 3 - TIR'!$E$18-'Ejercicio 3 - TIR'!$C$18)*('Ejercicio 3 - TIR'!$E$18-'Ejercicio 3 - TIR'!$D$18)*(1-H3))) -> 39070.306 | J3: =RAND() -> 0.45751991 | K3: =IF(J3<=('Ejercicio 3 - TIR'!$D$18-'Ejercicio 3 - TIR'!$C$18)/('Ejercicio 3 - TIR'!$E$18-'Ejercicio 3 - TIR'!$C$18),'Ejercicio 3 - TIR'!$C$18+SQRT(('Ejercicio 3 - TIR'!$E$18-'Ejercicio 3 - TIR'!$C$18)*('Ejercicio 3 - TIR'!$D$18-'Ejercicio 3 - TIR'!$C$18)*J3),'Ejercicio 3 - TIR'!$E$18-SQRT(('Ejercicio 3 - TIR'!$E$18-'Ejercicio 3 - TIR'!$C$18)*('Ejercicio 3 - TIR'!$E$18-'Ejercicio 3 - TIR'!$D$18)*(1-J3))) -> 38284.201 | L3: =RAND() -> 0.87288181 | M3: =IF(L3<=('Ejercicio 3 - TIR'!$D$18-'Ejercicio 3 - TIR'!$C$18)/('Ejercicio 3 - TIR'!$E$18-'Ejercicio 3 - TIR'!$C$18),'Ejercicio 3 - TIR'!$C$18+SQRT(('Ejercicio 3 - TIR'!$E$18-'Ejercicio 3 - TIR'!$C$18)*('Ejercicio 3 - TIR'!$D$18-'Ejercicio 3 - TIR'!$C$18)*L3),'Ejercicio 3 - TIR'!$E$18-SQRT(('Ejercicio 3 - TIR'!$E$18-'Ejercicio 3 - TIR'!$C$18)*('Ejercicio 3 - TIR'!$E$18-'Ejercicio 3 - TIR'!$D$18)*(1-L3))) -> 41912.304 | N3: =RAND() -> 0.21634229 | O3: =IF(N3<=('Ejercicio 3 - TIR'!$D$18-'Ejercicio 3 - TIR'!$C$18)/('Ejercicio 3 - TIR'!$E$18-'Ejercicio 3 - TIR'!$C$18),'Ejercicio 3 - TIR'!$C$18+SQRT(('Ejercicio 3 - TIR'!$E$18-'Ejercicio 3 - TIR'!$C$18)*('Ejercicio 3 - TIR'!$D$18-'Ejercicio 3 - TIR'!$C$18)*N3),'Ejercicio 3 - TIR'!$E$18-SQRT(('Ejercicio 3 - TIR'!$E$18-'Ejercicio 3 - TIR'!$C$18)*('Ejercicio 3 - TIR'!$E$18-'Ejercicio 3 - TIR'!$D$18)*(1-N3))) -> 35696.608 | P3: =RAND() -> 0.13961279 | Q3: =IF(P3<=('Ejercicio 3 - TIR'!$D$22-'Ejercicio 3 - TIR'!$C$22)/('Ejercicio 3 - TIR'!$E$22-'Ejercicio 3 - TIR'!$C$22),'Ejercicio 3 - TIR'!$C$22+SQRT(('Ejercicio 3 - TIR'!$E$22-'Ejercicio 3 - TIR'!$C$22)*('Ejercicio 3 - TIR'!$D$22-'Ejercicio 3 - TIR'!$C$22)*P3),'Ejercicio 3 - TIR'!$E$22-SQRT(('Ejercicio 3 - TIR'!$E$22-'Ejercicio 3 - TIR'!$C$22)*('Ejercicio 3 - TIR'!$E$22-'Ejercicio 3 - TIR'!$D$22)*(1-P3))) -> 0.13585254 | R3: =RAND() -> 0.15944188 | S3: =IF(R3<=('Ejercicio 3 - TIR'!$D$23-'Ejercicio 3 - TIR'!$C$23)/('Ejercicio 3 - TIR'!$E$23-'Ejercicio 3 - TIR'!$C$23),'Ejercicio 3 - TIR'!$C$23+SQRT(('Ejercicio 3 - TIR'!$E$23-'Ejercicio 3 - TIR'!$C$23)*('Ejercicio 3 - TIR'!$D$23-'Ejercicio 3 - TIR'!$C$23)*R3),'Ejercicio 3 - TIR'!$E$23-SQRT(('Ejercicio 3 - TIR'!$E$23-'Ejercicio 3 - TIR'!$C$23)*('Ejercicio 3 - TIR'!$E$23-'Ejercicio 3 - TIR'!$D$23)*(1-R3))) -> 0.13694094 | T3: =RAND() -> 0.22346911 | U3: =IF(T3<=('Ejercicio 3 - TIR'!$D$24-'Ejercicio 3 - TIR'!$C$24)/('Ejercicio 3 - TIR'!$E$24-'Ejercicio 3 - TIR'!$C$24),'Ejercicio 3 - TIR'!$C$24+SQRT(('Ejercicio 3 - TIR'!$E$24-'Ejercicio 3 - TIR'!$C$24)*('Ejercicio 3 - TIR'!$D$24-'Ejercicio 3 - TIR'!$C$24)*T3),'Ejercicio 3 - TIR'!$E$24-SQRT(('Ejercicio 3 - TIR'!$E$24-'Ejercicio 3 - TIR'!$C$24)*('Ejercicio 3 - TIR'!$E$24-'Ejercicio 3 - TIR'!$D$24)*(1-T3))) -> 0.17166299 | V3: =RAND() -> 0.037469736 | W3: =IF(V3<=('Ejercicio 3 - TIR'!$D$25-'Ejercicio 3 - TIR'!$C$25)/('Ejercicio 3 - TIR'!$E$25-'Ejercicio 3 - TIR'!$C$25),'Ejercicio 3 - TIR'!$C$25+SQRT(('Ejercicio 3 - TIR'!$E$25-'Ejercicio 3 - TIR'!$C$25)*('Ejercicio 3 - TIR'!$D$25-'Ejercicio 3 - TIR'!$C$25)*V3),'Ejercicio 3 - TIR'!$E$25-SQRT(('Ejercicio 3 - TIR'!$E$25-'Ejercicio 3 - TIR'!$C$25)*('Ejercicio 3 - TIR'!$E$25-'Ejercicio 3 - TIR'!$D$25)*(1-V3))) -> 0.18724276 | X3: =RAND() -> 0.00097366396 | Y3: =IF(X3<=('Ejercicio 3 - TIR'!$D$26-'Ejercicio 3 - TIR'!$C$26)/('Ejercicio 3 - TIR'!$E$26-'Ejercicio 3 - TIR'!$C$26),'Ejercicio 3 - TIR'!$C$26+SQRT(('Ejercicio 3 - TIR'!$E$26-'Ejercicio 3 - TIR'!$C$26)*('Ejercicio 3 - TIR'!$D$26-'Ejercicio 3 - TIR'!$C$26)*X3),'Ejercicio 3 - TIR'!$E$26-SQRT(('Ejercicio 3 - TIR'!$E$26-'Ejercicio 3 - TIR'!$C$26)*('Ejercicio 3 - TIR'!$E$26-'Ejercicio 3 - TIR'!$D$26)*(1-X3))) -> 0.19162139 | Z3: =(1+Q3) -> 1.1358525 | AA3: =Z3*(1+S3) -> 1.2913973 | AB3: =AA3*(1+U3) -> 1.5130824 | AC3: =AB3*(1+W3) -> 1.7963961 | AD3: =AC3*(1+Y3) -> 2.140624 | AE3: =E3*Q3 -> 4202.2 | AF3: =AE3*(1+S3) -> 4777.6532 | AG3: =AF3*(1+U3) -> 5597.7994 | AH3: =AG3*(1+W3) -> 6645.9468 | AI3: =AH3*(1+Y3) -> 7919.4524 | AJ3: =G3*Z3 -> 44199.935 | AK3: =I3*AA3 -> 50455.286 | AL3: =K3*AB3 -> 57927.149 | AM3: =M3*AC3 -> 75291.1 | AN3: =O3*AD3 -> 76413.016 | AO3: =C3/'Ejercicio 3 - TIR'!$D$7 -> 13832.665 | AP3: =AJ3-AO3 -> 30367.27 | AQ3: =AK3-AO3 -> 36622.62 | AR3: =AL3-AO3 -> 44094.484 | AS3: =AM3-AO3 -> 61458.434 | AT3: =AN3-AO3 -> 62580.351 | AU3: =AP3*'Ejercicio 3 - TIR'!$D$5 -> 15183.635 | AV3: =AQ3*'Ejercicio 3 - TIR'!$D$5 -> 18311.31 | AW3: =AR3*'Ejercicio 3 - TIR'!$D$5 -> 22047.242 | AX3: =AS3*'Ejercicio 3 - TIR'!$D$5 -> 30729.217 | AY3: =AT3*'Ejercicio 3 - TIR'!$D$5 -> 31290.175 | AZ3: =AJ3-AU3-AE3 -> 24814.1 | BA3: =AK3-AV3-AF3 -> 27366.322 | BB3: =AL3-AW3-AG3 -> 30282.108 | BC3: =AM3-AX3-AH3 -> 37915.936 | BD3: =AN3-AY3-AI3 -> 37203.388 | BE3: =AZ3/Z3 -> 21846.234 | BF3: =BA3/AA3 -> 21191.25 | BG3: =BB3/AB3 -> 20013.522 | BH3: =BC3/AC3 -> 21106.668 | BI3: =BD3/AD3 -> 17379.693 | BJ3: =E3*AD3 -> 66213.927 | BK3: =0.2*C3*AD3 -> 29610.535 | BL3: =BJ3+BK3 -> 95824.462 | BM3: =BK3*'Ejercicio 3 - TIR'!$D$5 -> 14805.268 | BN3: =BL3-BM3 -> 81019.194 | BO3: =BN3/AD3 -> 37848.4 | BP3: =-(C3+E3) -> -100095.39 | BQ3: =BE3 -> 21846.234 | BR3: =BF3 -> 21191.25 | BS3: =BG3 -> 20013.522 | BT3: =BH3 -> 21106.668 | BU3: =BI3+BO3 -> 55228.093 | BV3: =IFERROR(IRR(BP3:BU3,0.1),NA())*100 -> 10.344633
A4: 3 | B4: =RAND() -> 0.91224235 | C4: =IF(B4<=('Ejercicio 3 - TIR'!$D$13-'Ejercicio 3 - TIR'!$C$13)/('Ejercicio 3 - TIR'!$E$13-'Ejercicio 3 - TIR'!$C$13),'Ejercicio 3 - TIR'!$C$13+SQRT(('Ejercicio 3 - TIR'!$E$13-'Ejercicio 3 - TIR'!$C$13)*('Ejercicio 3 - TIR'!$D$13-'Ejercicio 3 - TIR'!$C$13)*B4),'Ejercicio 3 - TIR'!$E$13-SQRT(('Ejercicio 3 - TIR'!$E$13-'Ejercicio 3 - TIR'!$C$13)*('Ejercicio 3 - TIR'!$E$13-'Ejercicio 3 - TIR'!$D$13)*(1-B4))) -> 89737.974 | D4: =RAND() -> 0.70715225 | E4: =IF(D4<=('Ejercicio 3 - TIR'!$D$14-'Ejercicio 3 - TIR'!$C$14)/('Ejercicio 3 - TIR'!$E$14-'Ejercicio 3 - TIR'!$C$14),'Ejercicio 3 - TIR'!$C$14+SQRT(('Ejercicio 3 - TIR'!$E$14-'Ejercicio 3 - TIR'!$C$14)*('Ejercicio 3 - TIR'!$D$14-'Ejercicio 3 - TIR'!$C$14)*D4),'Ejercicio 3 - TIR'!$E$14-SQRT(('Ejercicio 3 - TIR'!$E$14-'Ejercicio 3 - TIR'!$C$14)*('Ejercicio 3 - TIR'!$E$14-'Ejercicio 3 - TIR'!$D$14)*(1-D4))) -> 33372.243 | F4: =RAND() -> 0.11336018 | G4: =IF(F4<=('Ejercicio 3 - TIR'!$D$18-'Ejercicio 3 - TIR'!$C$18)/('Ejercicio 3 - TIR'!$E$18-'Ejercicio 3 - TIR'!$C$18),'Ejercicio 3 - TIR'!$C$18+SQRT(('Ejercicio 3 - TIR'!$E$18-'Ejercicio 3 - TIR'!$C$18)*('Ejercicio 3 - TIR'!$D$18-'Ejercicio 3 - TIR'!$C$18)*F4),'Ejercicio 3 - TIR'!$E$18-SQRT(('Ejercicio 3 - TIR'!$E$18-'Ejercicio 3 - TIR'!$C$18)*('Ejercicio 3 - TIR'!$E$18-'Ejercicio 3 - TIR'!$D$18)*(1-F4))) -> 34123.594 | H4: =RAND() -> 0.44365394 | I4: =IF(H4<=('Ejercicio 3 - TIR'!$D$18-'Ejercicio 3 - TIR'!$C$18)/('Ejercicio 3 - TIR'!$E$18-'Ejercicio 3 - TIR'!$C$18),'Ejercicio 3 - TIR'!$C$18+SQRT(('Ejercicio 3 - TIR'!$E$18-'Ejercicio 3 - TIR'!$C$18)*('Ejercicio 3 - TIR'!$D$18-'Ejercicio 3 - TIR'!$C$18)*H4),'Ejercicio 3 - TIR'!$E$18-SQRT(('Ejercicio 3 - TIR'!$E$18-'Ejercicio 3 - TIR'!$C$18)*('Ejercicio 3 - TIR'!$E$18-'Ejercicio 3 - TIR'!$D$18)*(1-H4))) -> 38157.701 | J4: =RAND() -> 0.66856365 | K4: =IF(J4<=('Ejercicio 3 - TIR'!$D$18-'Ejercicio 3 - TIR'!$C$18)/('Ejercicio 3 - TIR'!$E$18-'Ejercicio 3 - TIR'!$C$18),'Ejercicio 3 - TIR'!$C$18+SQRT(('Ejercicio 3 - TIR'!$E$18-'Ejercicio 3 - TIR'!$C$18)*('Ejercicio 3 - TIR'!$D$18-'Ejercicio 3 - TIR'!$C$18)*J4),'Ejercicio 3 - TIR'!$E$18-SQRT(('Ejercicio 3 - TIR'!$E$18-'Ejercicio 3 - TIR'!$C$18)*('Ejercicio 3 - TIR'!$E$18-'Ejercicio 3 - TIR'!$D$18)*(1-J4))) -> 40014.248 | L4: =RAND() -> 0.55123902 | M4: =IF(L4<=('Ejercicio 3 - TIR'!$D$18-'Ejercicio 3 - TIR'!$C$18)/('Ejercicio 3 - TIR'!$E$18-'Ejercicio 3 - TIR'!$C$18),'Ejercicio 3 - TIR'!$C$18+SQRT(('Ejercicio 3 - TIR'!$E$18-'Ejercicio 3 - TIR'!$C$18)*('Ejercicio 3 - TIR'!$D$18-'Ejercicio 3 - TIR'!$C$18)*L4),'Ejercicio 3 - TIR'!$E$18-SQRT(('Ejercicio 3 - TIR'!$E$18-'Ejercicio 3 - TIR'!$C$18)*('Ejercicio 3 - TIR'!$E$18-'Ejercicio 3 - TIR'!$D$18)*(1-L4))) -> 39093.176 | N4: =RAND() -> 0.98830406 | O4: =IF(N4<=('Ejercicio 3 - TIR'!$D$18-'Ejercicio 3 - TIR'!$C$18)/('Ejercicio 3 - TIR'!$E$18-'Ejercicio 3 - TIR'!$C$18),'Ejercicio 3 - TIR'!$C$18+SQRT(('Ejercicio 3 - TIR'!$E$18-'Ejercicio 3 - TIR'!$C$18)*('Ejercicio 3 - TIR'!$D$18-'Ejercicio 3 - TIR'!$C$18)*N4),'Ejercicio 3 - TIR'!$E$18-SQRT(('Ejercicio 3 - TIR'!$E$18-'Ejercicio 3 - TIR'!$C$18)*('Ejercicio 3 - TIR'!$E$18-'Ejercicio 3 - TIR'!$D$18)*(1-N4))) -> 44063.413 | P4: =RAND() -> 0.64108511 | Q4: =IF(P4<=('Ejercicio 3 - TIR'!$D$22-'Ejercicio 3 - TIR'!$C$22)/('Ejercicio 3 - TIR'!$E$22-'Ejercicio 3 - TIR'!$C$22),'Ejercicio 3 - TIR'!$C$22+SQRT(('Ejercicio 3 - TIR'!$E$22-'Ejercicio 3 - TIR'!$C$22)*('Ejercicio 3 - TIR'!$D$22-'Ejercicio 3 - TIR'!$C$22)*P4),'Ejercicio 3 - TIR'!$E$22-SQRT(('Ejercicio 3 - TIR'!$E$22-'Ejercicio 3 - TIR'!$C$22)*('Ejercicio 3 - TIR'!$E$22-'Ejercicio 3 - TIR'!$D$22)*(1-P4))) -> 0.15458255 | R4: =RAND() -> 0.039168953 | S4: =IF(R4<=('Ejercicio 3 - TIR'!$D$23-'Ejercicio 3 - TIR'!$C$23)/('Ejercicio 3 - TIR'!$E$23-'Ejercicio 3 - TIR'!$C$23),'Ejercicio 3 - TIR'!$C$23+SQRT(('Ejercicio 3 - TIR'!$E$23-'Ejercicio 3 - TIR'!$C$23)*('Ejercicio 3 - TIR'!$D$23-'Ejercicio 3 - TIR'!$C$23)*R4),'Ejercicio 3 - TIR'!$E$23-SQRT(('Ejercicio 3 - TIR'!$E$23-'Ejercicio 3 - TIR'!$C$23)*('Ejercicio 3 - TIR'!$E$23-'Ejercicio 3 - TIR'!$D$23)*(1-R4))) -> 0.12839667 | T4: =RAND() -> 0.50551714 | U4: =IF(T4<=('Ejercicio 3 - TIR'!$D$24-'Ejercicio 3 - TIR'!$C$24)/('Ejercicio 3 - TIR'!$E$24-'Ejercicio 3 - TIR'!$C$24),'Ejercicio 3 - TIR'!$C$24+SQRT(('Ejercicio 3 - TIR'!$E$24-'Ejercicio 3 - TIR'!$C$24)*('Ejercicio 3 - TIR'!$D$24-'Ejercicio 3 - TIR'!$C$24)*T4),'Ejercicio 3 - TIR'!$E$24-SQRT(('Ejercicio 3 - TIR'!$E$24-'Ejercicio 3 - TIR'!$C$24)*('Ejercicio 3 - TIR'!$E$24-'Ejercicio 3 - TIR'!$D$24)*(1-T4))) -> 0.18279043 | V4: =RAND() -> 0.53482972 | W4: =IF(V4<=('Ejercicio 3 - TIR'!$D$25-'Ejercicio 3 - TIR'!$C$25)/('Ejercicio 3 - TIR'!$E$25-'Ejercicio 3 - TIR'!$C$25),'Ejercicio 3 - TIR'!$C$25+SQRT(('Ejercicio 3 - TIR'!$E$25-'Ejercicio 3 - TIR'!$C$25)*('Ejercicio 3 - TIR'!$D$25-'Ejercicio 3 - TIR'!$C$25)*V4),'Ejercicio 3 - TIR'!$E$25-SQRT(('Ejercicio 3 - TIR'!$E$25-'Ejercicio 3 - TIR'!$C$25)*('Ejercicio 3 - TIR'!$E$25-'Ejercicio 3 - TIR'!$D$25)*(1-V4))) -> 0.20965033 | X4: =RAND() -> 0.63112144 | Y4: =IF(X4<=('Ejercicio 3 - TIR'!$D$26-'Ejercicio 3 - TIR'!$C$26)/('Ejercicio 3 - TIR'!$E$26-'Ejercicio 3 - TIR'!$C$26),'Ejercicio 3 - TIR'!$C$26+SQRT(('Ejercicio 3 - TIR'!$E$26-'Ejercicio 3 - TIR'!$C$26)*('Ejercicio 3 - TIR'!$D$26-'Ejercicio 3 - TIR'!$C$26)*X4),'Ejercicio 3 - TIR'!$E$26-SQRT(('Ejercicio 3 - TIR'!$E$26-'Ejercicio 3 - TIR'!$C$26)*('Ejercicio 3 - TIR'!$E$26-'Ejercicio 3 - TIR'!$D$26)*(1-X4))) -> 0.2353688 | Z4: =(1+Q4) -> 1.1545825 | AA4: =Z4*(1+S4) -> 1.3028271 | AB4: =AA4*(1+U4) -> 1.5409714 | AC4: =AB4*(1+W4) -> 1.8640366 | AD4: =AC4*(1+Y4) -> 2.3027727 | AE4: =E4*Q4 -> 5158.7664 | AF4: =AE4*(1+S4) -> 5821.1348 | AG4: =AF4*(1+U4) -> 6885.1826 | AH4: =AG4*(1+W4) -> 8328.6634 | AI4: =AH4*(1+Y4) -> 10288.971 | AJ4: =G4*Z4 -> 39398.506 | AK4: =I4*AA4 -> 49712.888 | AL4: =K4*AB4 -> 61660.813 | AM4: =M4*AC4 -> 72871.111 | AN4: =O4*AD4 -> 101468.02 | AO4: =C4/'Ejercicio 3 - TIR'!$D$7 -> 17947.595 | AP4: =AJ4-AO4 -> 21450.911 | AQ4: =AK4-AO4 -> 31765.293 | AR4: =AL4-AO4 -> 43713.218 | AS4: =AM4-AO4 -> 54923.517 | AT4: =AN4-AO4 -> 83520.428 | AU4: =AP4*'Ejercicio 3 - TIR'!$D$5 -> 10725.456 | AV4: =AQ4*'Ejercicio 3 - TIR'!$D$5 -> 15882.646 | AW4: =AR4*'Ejercicio 3 - TIR'!$D$5 -> 21856.609 | AX4: =AS4*'Ejercicio 3 - TIR'!$D$5 -> 27461.758 | AY4: =AT4*'Ejercicio 3 - TIR'!$D$5 -> 41760.214 | AZ4: =AJ4-AU4-AE4 -> 23514.284 | BA4: =AK4-AV4-AF4 -> 28009.106 | BB4: =AL4-AW4-AG4 -> 32919.021 | BC4: =AM4-AX4-AH4 -> 37080.69 | BD4: =AN4-AY4-AI4 -> 49418.838 | BE4: =AZ4/Z4 -> 20366.048 | BF4: =BA4/AA4 -> 21498.713 | BG4: =BB4/AB4 -> 21362.512 | BH4: =BC4/AC4 -> 19892.683 | BI4: =BD4/AD4 -> 21460.58 | BJ4: =E4*AD4 -> 76848.689 | BK4: =0.2*C4*AD4 -> 41329.231 | BL4: =BJ4+BK4 -> 118177.92 | BM4: =BK4*'Ejercicio 3 - TIR'!$D$5 -> 20664.615 | BN4: =BL4-BM4 -> 97513.304 | BO4: =BN4/AD4 -> 42346.04 | BP4: =-(C4+E4) -> -123110.22 | BQ4: =BE4 -> 20366.048 | BR4: =BF4 -> 21498.713 | BS4: =BG4 -> 21362.512 | BT4: =BH4 -> 19892.683 | BU4: =BI4+BO4 -> 63806.621 | BV4: =IFERROR(IRR(BP4:BU4,0.1),NA())*100 -> 5.1472293
A5: 4 | B5: =RAND() -> 0.54810799 | C5: =IF(B5<=('Ejercicio 3 - TIR'!$D$13-'Ejercicio 3 - TIR'!$C$13)/('Ejercicio 3 - TIR'!$E$13-'Ejercicio 3 - TIR'!$C$13),'Ejercicio 3 - TIR'!$C$13+SQRT(('Ejercicio 3 - TIR'!$E$13-'Ejercicio 3 - TIR'!$C$13)*('Ejercicio 3 - TIR'!$D$13-'Ejercicio 3 - TIR'!$C$13)*B5),'Ejercicio 3 - TIR'!$E$13-SQRT(('Ejercicio 3 - TIR'!$E$13-'Ejercicio 3 - TIR'!$C$13)*('Ejercicio 3 - TIR'!$E$13-'Ejercicio 3 - TIR'!$D$13)*(1-B5))) -> 76713.3 | D5: =RAND() -> 0.55845588 | E5: =IF(D5<=('Ejercicio 3 - TIR'!$D$14-'Ejercicio 3 - TIR'!$C$14)/('Ejercicio 3 - TIR'!$E$14-'Ejercicio 3 - TIR'!$C$14),'Ejercicio 3 - TIR'!$C$14+SQRT(('Ejercicio 3 - TIR'!$E$14-'Ejercicio 3 - TIR'!$C$14)*('Ejercicio 3 - TIR'!$D$14-'Ejercicio 3 - TIR'!$C$14)*D5),'Ejercicio 3 - TIR'!$E$14-SQRT(('Ejercicio 3 - TIR'!$E$14-'Ejercicio 3 - TIR'!$C$14)*('Ejercicio 3 - TIR'!$E$14-'Ejercicio 3 - TIR'!$D$14)*(1-D5))) -> 31861.719 | F5: =RAND() -> 0.021106608 | G5: =IF(F5<=('Ejercicio 3 - TIR'!$D$18-'Ejercicio 3 - TIR'!$C$18)/('Ejercicio 3 - TIR'!$E$18-'Ejercicio 3 - TIR'!$C$18),'Ejercicio 3 - TIR'!$C$18+SQRT(('Ejercicio 3 - TIR'!$E$18-'Ejercicio 3 - TIR'!$C$18)*('Ejercicio 3 - TIR'!$D$18-'Ejercicio 3 - TIR'!$C$18)*F5),'Ejercicio 3 - TIR'!$E$18-SQRT(('Ejercicio 3 - TIR'!$E$18-'Ejercicio 3 - TIR'!$C$18)*('Ejercicio 3 - TIR'!$E$18-'Ejercicio 3 - TIR'!$D$18)*(1-F5))) -> 31779.323 | H5: =RAND() -> 0.2822403 | I5: =IF(H5<=('Ejercicio 3 - TIR'!$D$18-'Ejercicio 3 - TIR'!$C$18)/('Ejercicio 3 - TIR'!$E$18-'Ejercicio 3 - TIR'!$C$18),'Ejercicio 3 - TIR'!$C$18+SQRT(('Ejercicio 3 - TIR'!$E$18-'Ejercicio 3 - TIR'!$C$18)*('Ejercicio 3 - TIR'!$D$18-'Ejercicio 3 - TIR'!$C$18)*H5),'Ejercicio 3 - TIR'!$E$18-SQRT(('Ejercicio 3 - TIR'!$E$18-'Ejercicio 3 - TIR'!$C$18)*('Ejercicio 3 - TIR'!$E$18-'Ejercicio 3 - TIR'!$D$18)*(1-H5))) -> 36506.616 | J5: =RAND() -> 0.17418071 | K5: =IF(J5<=('Ejercicio 3 - TIR'!$D$18-'Ejercicio 3 - TIR'!$C$18)/('Ejercicio 3 - TIR'!$E$18-'Ejercicio 3 - TIR'!$C$18),'Ejercicio 3 - TIR'!$C$18+SQRT(('Ejercicio 3 - TIR'!$E$18-'Ejercicio 3 - TIR'!$C$18)*('Ejercicio 3 - TIR'!$D$18-'Ejercicio 3 - TIR'!$C$18)*J5),'Ejercicio 3 - TIR'!$E$18-SQRT(('Ejercicio 3 - TIR'!$E$18-'Ejercicio 3 - TIR'!$C$18)*('Ejercicio 3 - TIR'!$E$18-'Ejercicio 3 - TIR'!$D$18)*(1-J5))) -> 35111.468 | L5: =RAND() -> 0.60446073 | M5: =IF(L5<=('Ejercicio 3 - TIR'!$D$18-'Ejercicio 3 - TIR'!$C$18)/('Ejercicio 3 - TIR'!$E$18-'Ejercicio 3 - TIR'!$C$18),'Ejercicio 3 - TIR'!$C$18+SQRT(('Ejercicio 3 - TIR'!$E$18-'Ejercicio 3 - TIR'!$C$18)*('Ejercicio 3 - TIR'!$D$18-'Ejercicio 3 - TIR'!$C$18)*L5),'Ejercicio 3 - TIR'!$E$18-SQRT(('Ejercicio 3 - TIR'!$E$18-'Ejercicio 3 - TIR'!$C$18)*('Ejercicio 3 - TIR'!$E$18-'Ejercicio 3 - TIR'!$D$18)*(1-L5))) -> 39522.033 | N5: =RAND() -> 0.86205715 | O5: =IF(N5<=('Ejercicio 3 - TIR'!$D$18-'Ejercicio 3 - TIR'!$C$18)/('Ejercicio 3 - TIR'!$E$18-'Ejercicio 3 - TIR'!$C$18),'Ejercicio 3 - TIR'!$C$18+SQRT(('Ejercicio 3 - TIR'!$E$18-'Ejercicio 3 - TIR'!$C$18)*('Ejercicio 3 - TIR'!$D$18-'Ejercicio 3 - TIR'!$C$18)*N5),'Ejercicio 3 - TIR'!$E$18-SQRT(('Ejercicio 3 - TIR'!$E$18-'Ejercicio 3 - TIR'!$C$18)*('Ejercicio 3 - TIR'!$E$18-'Ejercicio 3 - TIR'!$D$18)*(1-N5))) -> 41783.525 | P5: =RAND() -> 0.28659078 | Q5: =IF(P5<=('Ejercicio 3 - TIR'!$D$22-'Ejercicio 3 - TIR'!$C$22)/('Ejercicio 3 - TIR'!$E$22-'Ejercicio 3 - TIR'!$C$22),'Ejercicio 3 - TIR'!$C$22+SQRT(('Ejercicio 3 - TIR'!$E$22-'Ejercicio 3 - TIR'!$C$22)*('Ejercicio 3 - TIR'!$D$22-'Ejercicio 3 - TIR'!$C$22)*P5),'Ejercicio 3 - TIR'!$E$22-SQRT(('Ejercicio 3 - TIR'!$E$22-'Ejercicio 3 - TIR'!$C$22)*('Ejercicio 3 - TIR'!$E$22-'Ejercicio 3 - TIR'!$D$22)*(1-P5))) -> 0.14271263 | R5: =RAND() -> 0.53401304 | S5: =IF(R5<=('Ejercicio 3 - TIR'!$D$23-'Ejercicio 3 - TIR'!$C$23)/('Ejercicio 3 - TIR'!$E$23-'Ejercicio 3 - TIR'!$C$23),'Ejercicio 3 - TIR'!$C$23+SQRT(('Ejercicio 3 - TIR'!$E$23-'Ejercicio 3 - TIR'!$C$23)*('Ejercicio 3 - TIR'!$D$23-'Ejercicio 3 - TIR'!$C$23)*R5),'Ejercicio 3 - TIR'!$E$23-SQRT(('Ejercicio 3 - TIR'!$E$23-'Ejercicio 3 - TIR'!$C$23)*('Ejercicio 3 - TIR'!$E$23-'Ejercicio 3 - TIR'!$D$23)*(1-R5))) -> 0.15103836 | T5: =RAND() -> 0.34205846 | U5: =IF(T5<=('Ejercicio 3 - TIR'!$D$24-'Ejercicio 3 - TIR'!$C$24)/('Ejercicio 3 - TIR'!$E$24-'Ejercicio 3 - TIR'!$C$24),'Ejercicio 3 - TIR'!$C$24+SQRT(('Ejercicio 3 - TIR'!$E$24-'Ejercicio 3 - TIR'!$C$24)*('Ejercicio 3 - TIR'!$D$24-'Ejercicio 3 - TIR'!$C$24)*T5),'Ejercicio 3 - TIR'!$E$24-SQRT(('Ejercicio 3 - TIR'!$E$24-'Ejercicio 3 - TIR'!$C$24)*('Ejercicio 3 - TIR'!$E$24-'Ejercicio 3 - TIR'!$D$24)*(1-T5))) -> 0.17680154 | V5: =RAND() -> 0.16898323 | W5: =IF(V5<=('Ejercicio 3 - TIR'!$D$25-'Ejercicio 3 - TIR'!$C$25)/('Ejercicio 3 - TIR'!$E$25-'Ejercicio 3 - TIR'!$C$25),'Ejercicio 3 - TIR'!$C$25+SQRT(('Ejercicio 3 - TIR'!$E$25-'Ejercicio 3 - TIR'!$C$25)*('Ejercicio 3 - TIR'!$D$25-'Ejercicio 3 - TIR'!$C$25)*V5),'Ejercicio 3 - TIR'!$E$25-SQRT(('Ejercicio 3 - TIR'!$E$25-'Ejercicio 3 - TIR'!$C$25)*('Ejercicio 3 - TIR'!$E$25-'Ejercicio 3 - TIR'!$D$25)*(1-V5))) -> 0.19538104 | X5: =RAND() -> 0.50662536 | Y5: =IF(X5<=('Ejercicio 3 - TIR'!$D$26-'Ejercicio 3 - TIR'!$C$26)/('Ejercicio 3 - TIR'!$E$26-'Ejercicio 3 - TIR'!$C$26),'Ejercicio 3 - TIR'!$C$26+SQRT(('Ejercicio 3 - TIR'!$E$26-'Ejercicio 3 - TIR'!$C$26)*('Ejercicio 3 - TIR'!$D$26-'Ejercicio 3 - TIR'!$C$26)*X5),'Ejercicio 3 - TIR'!$E$26-SQRT(('Ejercicio 3 - TIR'!$E$26-'Ejercicio 3 - TIR'!$C$26)*('Ejercicio 3 - TIR'!$E$26-'Ejercicio 3 - TIR'!$D$26)*(1-X5))) -> 0.22838389 | Z5: =(1+Q5) -> 1.1427126 | AA5: =Z5*(1+S5) -> 1.3153061 | AB5: =AA5*(1+U5) -> 1.5478542 | AC5: =AB5*(1+W5) -> 1.8502756 | AD5: =AC5*(1+Y5) -> 2.2728487 | AE5: =E5*Q5 -> 4547.0696 | AF5: =AE5*(1+S5) -> 5233.8515 | AG5: =AF5*(1+U5) -> 6159.2046 | AH5: =AG5*(1+W5) -> 7362.5964 | AI5: =AH5*(1+Y5) -> 9044.0948 | AJ5: =G5*Z5 -> 36314.634 | AK5: =I5*AA5 -> 48017.373 | AL5: =K5*AB5 -> 54347.434 | AM5: =M5*AC5 -> 73126.652 | AN5: =O5*AD5 -> 94967.63 | AO5: =C5/'Ejercicio 3 - TIR'!$D$7 -> 15342.66 | AP5: =AJ5-AO5 -> 20971.974 | AQ5: =AK5-AO5 -> 32674.713 | AR5: =AL5-AO5 -> 39004.774 | AS5: =AM5-AO5 -> 57783.993 | AT5: =AN5-AO5 -> 79624.97 | AU5: =AP5*'Ejercicio 3 - TIR'!$D$5 -> 10485.987 | AV5: =AQ5*'Ejercicio 3 - TIR'!$D$5 -> 16337.356 | AW5: =AR5*'Ejercicio 3 - TIR'!$D$5 -> 19502.387 | AX5: =AS5*'Ejercicio 3 - TIR'!$D$5 -> 28891.996 | AY5: =AT5*'Ejercicio 3 - TIR'!$D$5 -> 39812.485 | AZ5: =AJ5-AU5-AE5 -> 21281.577 | BA5: =AK5-AV5-AF5 -> 26446.165 | BB5: =AL5-AW5-AG5 -> 28685.842 | BC5: =AM5-AX5-AH5 -> 36872.06 | BD5: =AN5-AY5-AI5 -> 46111.05 | BE5: =AZ5/Z5 -> 18623.735 | BF5: =BA5/AA5 -> 20106.472 | BG5: =BB5/AB5 -> 18532.651 | BH5: =BC5/AC5 -> 19927.875 | BI5: =BD5/AD5 -> 20287.778 | BJ5: =E5*AD5 -> 72416.867 | BK5: =0.2*C5*AD5 -> 34871.545 | BL5: =BJ5+BK5 -> 107288.41 | BM5: =BK5*'Ejercicio 3 - TIR'!$D$5 -> 17435.772 | BN5: =BL5-BM5 -> 89852.639 | BO5: =BN5/AD5 -> 39533.049 | BP5: =-(C5+E5) -> -108575.02 | BQ5: =BE5 -> 18623.735 | BR5: =BF5 -> 20106.472 | BS5: =BG5 -> 18532.651 | BT5: =BH5 -> 19927.875 | BU5: =BI5+BO5 -> 59820.827 | BV5: =IFERROR(IRR(BP5:BU5,0.1),NA())*100 -> 6.8208697
A6: 5 | B6: =RAND() -> 0.091627714 | C6: =IF(B6<=('Ejercicio 3 - TIR'!$D$13-'Ejercicio 3 - TIR'!$C$13)/('Ejercicio 3 - TIR'!$E$13-'Ejercicio 3 - TIR'!$C$13),'Ejercicio 3 - TIR'!$C$13+SQRT(('Ejercicio 3 - TIR'!$E$13-'Ejercicio 3 - TIR'!$C$13)*('Ejercicio 3 - TIR'!$D$13-'Ejercicio 3 - TIR'!$C$13)*B6),'Ejercicio 3 - TIR'!$E$13-SQRT(('Ejercicio 3 - TIR'!$E$13-'Ejercicio 3 - TIR'!$C$13)*('Ejercicio 3 - TIR'!$E$13-'Ejercicio 3 - TIR'!$D$13)*(1-B6))) -> 66054.014 | D6: =RAND() -> 0.26604877 | E6: =IF(D6<=('Ejercicio 3 - TIR'!$D$14-'Ejercicio 3 - TIR'!$C$14)/('Ejercicio 3 - TIR'!$E$14-'Ejercicio 3 - TIR'!$C$14),'Ejercicio 3 - TIR'!$C$14+SQRT(('Ejercicio 3 - TIR'!$E$14-'Ejercicio 3 - TIR'!$C$14)*('Ejercicio 3 - TIR'!$D$14-'Ejercicio 3 - TIR'!$C$14)*D6),'Ejercicio 3 - TIR'!$E$14-SQRT(('Ejercicio 3 - TIR'!$E$14-'Ejercicio 3 - TIR'!$C$14)*('Ejercicio 3 - TIR'!$E$14-'Ejercicio 3 - TIR'!$D$14)*(1-D6))) -> 29466.952 | F6: =RAND() -> 0.85567868 | G6: =IF(F6<=('Ejercicio 3 - TIR'!$D$18-'Ejercicio 3 - TIR'!$C$18)/('Ejercicio 3 - TIR'!$E$18-'Ejercicio 3 - TIR'!$C$18),'Ejercicio 3 - TIR'!$C$18+SQRT(('Ejercicio 3 - TIR'!$E$18-'Ejercicio 3 - TIR'!$C$18)*('Ejercicio 3 - TIR'!$D$18-'Ejercicio 3 - TIR'!$C$18)*F6),'Ejercicio 3 - TIR'!$E$18-SQRT(('Ejercicio 3 - TIR'!$E$18-'Ejercicio 3 - TIR'!$C$18)*('Ejercicio 3 - TIR'!$E$18-'Ejercicio 3 - TIR'!$D$18)*(1-F6))) -> 41710 | H6: =RAND() -> 0.83634117 | I6: =IF(H6<=('Ejercicio 3 - TIR'!$D$18-'Ejercicio 3 - TIR'!$C$18)/('Ejercicio 3 - TIR'!$E$18-'Ejercicio 3 - TIR'!$C$18),'Ejercicio 3 - TIR'!$C$18+SQRT(('Ejercicio 3 - TIR'!$E$18-'Ejercicio 3 - TIR'!$C$18)*('Ejercicio 3 - TIR'!$D$18-'Ejercicio 3 - TIR'!$C$18)*H6),'Ejercicio 3 - TIR'!$E$18-SQRT(('Ejercicio 3 - TIR'!$E$18-'Ejercicio 3 - TIR'!$C$18)*('Ejercicio 3 - TIR'!$E$18-'Ejercicio 3 - TIR'!$D$18)*(1-H6))) -> 41496.514 | J6: =RAND() -> 0.43190898 | K6: =IF(J6<=('Ejercicio 3 - TIR'!$D$18-'Ejercicio 3 - TIR'!$C$18)/('Ejercicio 3 - TIR'!$E$18-'Ejercicio 3 - TIR'!$C$18),'Ejercicio 3 - TIR'!$C$18+SQRT(('Ejercicio 3 - TIR'!$E$18-'Ejercicio 3 - TIR'!$C$18)*('Ejercicio 3 - TIR'!$D$18-'Ejercicio 3 - TIR'!$C$18)*J6),'Ejercicio 3 - TIR'!$E$18-SQRT(('Ejercicio 3 - TIR'!$E$18-'Ejercicio 3 - TIR'!$C$18)*('Ejercicio 3 - TIR'!$E$18-'Ejercicio 3 - TIR'!$D$18)*(1-J6))) -> 38048.997 | L6: =RAND() -> 0.62223274 | M6: =IF(L6<=('Ejercicio 3 - TIR'!$D$18-'Ejercicio 3 - TIR'!$C$18)/('Ejercicio 3 - TIR'!$E$18-'Ejercicio 3 - TIR'!$C$18),'Ejercicio 3 - TIR'!$C$18+SQRT(('Ejercicio 3 - TIR'!$E$18-'Ejercicio 3 - TIR'!$C$18)*('Ejercicio 3 - TIR'!$D$18-'Ejercicio 3 - TIR'!$C$18)*L6),'Ejercicio 3 - TIR'!$E$18-SQRT(('Ejercicio 3 - TIR'!$E$18-'Ejercicio 3 - TIR'!$C$18)*('Ejercicio 3 - TIR'!$E$18-'Ejercicio 3 - TIR'!$D$18)*(1-L6))) -> 39661 | N6: =RAND() -> 0.41563681 | O6: =IF(N6<=('Ejercicio 3 - TIR'!$D$18-'Ejercicio 3 - TIR'!$C$18)/('Ejercicio 3 - TIR'!$E$18-'Ejercicio 3 - TIR'!$C$18),'Ejercicio 3 - TIR'!$C$18+SQRT(('Ejercicio 3 - TIR'!$E$18-'Ejercicio 3 - TIR'!$C$18)*('Ejercicio 3 - TIR'!$D$18-'Ejercicio 3 - TIR'!$C$18)*N6),'Ejercicio 3 - TIR'!$E$18-SQRT(('Ejercicio 3 - TIR'!$E$18-'Ejercicio 3 - TIR'!$C$18)*('Ejercicio 3 - TIR'!$E$18-'Ejercicio 3 - TIR'!$D$18)*(1-N6))) -> 37895.918 | P6: =RAND() -> 0.12678853 | Q6: =IF(P6<=('Ejercicio 3 - TIR'!$D$22-'Ejercicio 3 - TIR'!$C$22)/('Ejercicio 3 - TIR'!$E$22-'Ejercicio 3 - TIR'!$C$22),'Ejercicio 3 - TIR'!$C$22+SQRT(('Ejercicio 3 - TIR'!$E$22-'Ejercicio 3 - TIR'!$C$22)*('Ejercicio 3 - TIR'!$D$22-'Ejercicio 3 - TIR'!$C$22)*P6),'Ejercicio 3 - TIR'!$E$22-SQRT(('Ejercicio 3 - TIR'!$E$22-'Ejercicio 3 - TIR'!$C$22)*('Ejercicio 3 - TIR'!$E$22-'Ejercicio 3 - TIR'!$D$22)*(1-P6))) -> 0.13510693 | R6: =RAND() -> 0.0051692551 | S6: =IF(R6<=('Ejercicio 3 - TIR'!$D$23-'Ejercicio 3 - TIR'!$C$23)/('Ejercicio 3 - TIR'!$E$23-'Ejercicio 3 - TIR'!$C$23),'Ejercicio 3 - TIR'!$C$23+SQRT(('Ejercicio 3 - TIR'!$E$23-'Ejercicio 3 - TIR'!$C$23)*('Ejercicio 3 - TIR'!$D$23-'Ejercicio 3 - TIR'!$C$23)*R6),'Ejercicio 3 - TIR'!$E$23-SQRT(('Ejercicio 3 - TIR'!$E$23-'Ejercicio 3 - TIR'!$C$23)*('Ejercicio 3 - TIR'!$E$23-'Ejercicio 3 - TIR'!$D$23)*(1-R6))) -> 0.12305035 | T6: =RAND() -> 0.29772719 | U6: =IF(T6<=('Ejercicio 3 - TIR'!$D$24-'Ejercicio 3 - TIR'!$C$24)/('Ejercicio 3 - TIR'!$E$24-'Ejercicio 3 - TIR'!$C$24),'Ejercicio 3 - TIR'!$C$24+SQRT(('Ejercicio 3 - TIR'!$E$24-'Ejercicio 3 - TIR'!$C$24)*('Ejercicio 3 - TIR'!$D$24-'Ejercicio 3 - TIR'!$C$24)*T6),'Ejercicio 3 - TIR'!$E$24-SQRT(('Ejercicio 3 - TIR'!$E$24-'Ejercicio 3 - TIR'!$C$24)*('Ejercicio 3 - TIR'!$E$24-'Ejercicio 3 - TIR'!$D$24)*(1-T6))) -> 0.17500454 | V6: =RAND() -> 0.19458483 | W6: =IF(V6<=('Ejercicio 3 - TIR'!$D$25-'Ejercicio 3 - TIR'!$C$25)/('Ejercicio 3 - TIR'!$E$25-'Ejercicio 3 - TIR'!$C$25),'Ejercicio 3 - TIR'!$C$25+SQRT(('Ejercicio 3 - TIR'!$E$25-'Ejercicio 3 - TIR'!$C$25)*('Ejercicio 3 - TIR'!$D$25-'Ejercicio 3 - TIR'!$C$25)*V6),'Ejercicio 3 - TIR'!$E$25-SQRT(('Ejercicio 3 - TIR'!$E$25-'Ejercicio 3 - TIR'!$C$25)*('Ejercicio 3 - TIR'!$E$25-'Ejercicio 3 - TIR'!$D$25)*(1-V6))) -> 0.19650511 | X6: =RAND() -> 0.82361611 | Y6: =IF(X6<=('Ejercicio 3 - TIR'!$D$26-'Ejercicio 3 - TIR'!$C$26)/('Ejercicio 3 - TIR'!$E$26-'Ejercicio 3 - TIR'!$C$26),'Ejercicio 3 - TIR'!$C$26+SQRT(('Ejercicio 3 - TIR'!$E$26-'Ejercicio 3 - TIR'!$C$26)*('Ejercicio 3 - TIR'!$D$26-'Ejercicio 3 - TIR'!$C$26)*X6),'Ejercicio 3 - TIR'!$E$26-SQRT(('Ejercicio 3 - TIR'!$E$26-'Ejercicio 3 - TIR'!$C$26)*('Ejercicio 3 - TIR'!$E$26-'Ejercicio 3 - TIR'!$D$26)*(1-X6))) -> 0.24913784 | Z6: =(1+Q6) -> 1.1351069 | AA6: =Z6*(1+S6) -> 1.2747822 | AB6: =AA6*(1+U6) -> 1.4978749 | AC6: =AB6*(1+W6) -> 1.792215 | AD6: =AC6*(1+Y6) -> 2.2387236 | AE6: =E6*Q6 -> 3981.1894 | AF6: =AE6*(1+S6) -> 4471.0762 | AG6: =AF6*(1+U6) -> 5253.5348 | AH6: =AG6*(1+W6) -> 6285.8813 | AI6: =AH6*(1+Y6) -> 7851.9321 | AJ6: =G6*Z6 -> 47345.31 | AK6: =I6*AA6 -> 52899.019 | AL6: =K6*AB6 -> 56992.638 | AM6: =M6*AC6 -> 71081.038 | AN6: =O6*AD6 -> 84838.485 | AO6: =C6/'Ejercicio 3 - TIR'!$D$7 -> 13210.803 | AP6: =AJ6-AO6 -> 34134.507 | AQ6: =AK6-AO6 -> 39688.217 | AR6: =AL6-AO6 -> 43781.835 | AS6: =AM6-AO6 -> 57870.236 | AT6: =AN6-AO6 -> 71627.682 | AU6: =AP6*'Ejercicio 3 - TIR'!$D$5 -> 17067.254 | AV6: =AQ6*'Ejercicio 3 - TIR'!$D$5 -> 19844.108 | AW6: =AR6*'Ejercicio 3 - TIR'!$D$5 -> 21890.917 | AX6: =AS6*'Ejercicio 3 - TIR'!$D$5 -> 28935.118 | AY6: =AT6*'Ejercicio 3 - TIR'!$D$5 -> 35813.841 | AZ6: =AJ6-AU6-AE6 -> 26296.867 | BA6: =AK6-AV6-AF6 -> 28583.835 | BB6: =AL6-AW6-AG6 -> 29848.185 | BC6: =AM6-AX6-AH6 -> 35860.039 | BD6: =AN6-AY6-AI6 -> 41172.712 | BE6: =AZ6/Z6 -> 23166.863 | BF6: =BA6/AA6 -> 22422.524 | BG6: =BB6/AB6 -> 19927.021 | BH6: =BC6/AC6 -> 20008.782 | BI6: =BD6/AD6 -> 18391.155 | BJ6: =E6*AD6 -> 65968.36 | BK6: =0.2*C6*AD6 -> 29575.336 | BL6: =BJ6+BK6 -> 95543.695 | BM6: =BK6*'Ejercicio 3 - TIR'!$D$5 -> 14787.668 | BN6: =BL6-BM6 -> 80756.027 | BO6: =BN6/AD6 -> 36072.353 | BP6: =-(C6+E6) -> -95520.966 | BQ6: =BE6 -> 23166.863 | BR6: =BF6 -> 22422.524 | BS6: =BG6 -> 19927.021 | BT6: =BH6 -> 20008.782 | BU6: =BI6+BO6 -> 54463.508 | BV6: =IFERROR(IRR(BP6:BU6,0.1),NA())*100 -> 12.312146
