Workbook

Sheet Ejercicio 1 - Trapezoidal V
B1: Ejercicio 1
B3: Parámetros
B4: a = | C4: 3 | G4: Debe cumplirse: 0 < a < b < c
B5: b = | C5: 7
B6: c = | C6: 10
B7: N° simulaciones = | C7: 1000
B9: Áreas (deducidas en la teoría, Paso 1)
B10: A1 = | C10: =C4/(-C4+C5+C6) -> 0.21428571
B11: A2 = | C11: =(2*C5-2*C4)/(-C4+C5+C6) -> 0.57142857
B12: A3 = | C12: =(C6-C5)/(-C4+C5+C6) -> 0.21428571
B13: Suma = | C13: =C10+C11+C12 -> 1 | F13: Región 1: X = a*√R Región 2: X = a + (b−a)*R Región 3: X = c − (c−b)*√(1−R)
B16: i | C16: R_region | D16: R_valor | E16: Región | F16: X | G16: Fórmula de X según región (Paso 5 de la teoría): Región 1 -> a*SQRT(R_valor) | Región 2 -> a+(b-a)*R_valor | Región 3 -> c-(c-b)*SQRT(1-R_valor)
B17: 1 | C17: =RAND() -> 0.38098408 | D17: =RAND() -> 0.4504255 | E17: =IF(C17<=$C$10,1,IF(C17<=$C$10+$C$11,2,3)) -> 2 | F17: =IF(E17=1,$C$4*SQRT(D17),IF(E17=2,$C$4+($C$5-$C$4)*D17,$C$6-($C$6-$C$5)*SQRT(1-D17))) -> 4.801702
B18: 2 | C18: =RAND() -> 0.99956711 | D18: =RAND() -> 0.55026678 | E18: =IF(C18<=$C$10,1,IF(C18<=$C$10+$C$11,2,3)) -> 3 | F18: =IF(E18=1,$C$4*SQRT(D18),IF(E18=2,$C$4+($C$5-$C$4)*D18,$C$6-($C$6-$C$5)*SQRT(1-D18))) -> 7.9881355
B19: 3 | C19: =RAND() -> 0.21235295 | D19: =RAND() -> 0.13169998 | E19: =IF(C19<=$C$10,1,IF(C19<=$C$10+$C$11,2,3)) -> 1 | F19: =IF(E19=1,$C$4*SQRT(D19),IF(E19=2,$C$4+($C$5-$C$4)*D19,$C$6-($C$6-$C$5)*SQRT(1-D19))) -> 1.0887147
B20: 4 | C20: =RAND() -> 0.58462084 | D20: =RAND() -> 0.036259224 | E20: =IF(C20<=$C$10,1,IF(C20<=$C$10+$C$11,2,3)) -> 2 | F20: =IF(E20=1,$C$4*SQRT(D20),IF(E20=2,$C$4+($C$5-$C$4)*D20,$C$6-($C$6-$C$5)*SQRT(1-D20))) -> 3.1450369
B21: 5 | C21: =RAND() -> 0.34015705 | D21: =RAND() -> 0.40886414 | E21: =IF(C21<=$C$10,1,IF(C21<=$C$10+$C$11,2,3)) -> 2 | F21: =IF(E21=1,$C$4*SQRT(D21),IF(E21=2,$C$4+($C$5-$C$4)*D21,$C$6-($C$6-$C$5)*SQRT(1-D21))) -> 4.6354565
B22: 6 | C22: =RAND() -> 0.6942453 | D22: =RAND() -> 0.697366 | E22: =IF(C22<=$C$10,1,IF(C22<=$C$10+$C$11,2,3)) -> 2 | F22: =IF(E22=1,$C$4*SQRT(D22),IF(E22=2,$C$4+($C$5-$C$4)*D22,$C$6-($C$6-$C$5)*SQRT(1-D22))) -> 5.789464
B23: 7 | C23: =RAND() -> 0.64659635 | D23: =RAND() -> 0.45362541 | E23: =IF(C23<=$C$10,1,IF(C23<=$C$10+$C$11,2,3)) -> 2 | F23: =IF(E23=1,$C$4*SQRT(D23),IF(E23=2,$C$4+($C$5-$C$4)*D23,$C$6-($C$6-$C$5)*SQRT(1-D23))) -> 4.8145016
B24: 8 | C24: =RAND() -> 0.44746 | D24: =RAND() -> 0.36927872 | E24: =IF(C24<=$C$10,1,IF(C24<=$C$10+$C$11,2,3)) -> 2 | F24: =IF(E24=1,$C$4*SQRT(D24),IF(E24=2,$C$4+($C$5-$C$4)*D24,$C$6-($C$6-$C$5)*SQRT(1-D24))) -> 4.4771149
B25: 9 | C25: =RAND() -> 0.025573764 | D25: =RAND() -> 0.65713832 | E25: =IF(C25<=$C$10,1,IF(C25<=$C$10+$C$11,2,3)) -> 1 | F25: =IF(E25=1,$C$4*SQRT(D25),IF(E25=2,$C$4+($C$5-$C$4)*D25,$C$6-($C$6-$C$5)*SQRT(1-D25))) -> 2.431922
B26: 10 | C26: =RAND() -> 0.23219517 | D26: =RAND() -> 0.78676206 | E26: =IF(C26<=$C$10,1,IF(C26<=$C$10+$C$11,2,3)) -> 2 | F26: =IF(E26=1,$C$4*SQRT(D26),IF(E26=2,$C$4+($C$5-$C$4)*D26,$C$6-($C$6-$C$5)*SQRT(1-D26))) -> 6.1470483
B27: 11 | C27: =RAND() -> 0.4023865 | D27: =RAND() -> 0.0039764677 | E27: =IF(C27<=$C$10,1,IF(C27<=$C$10+$C$11,2,3)) -> 2 | F27: =IF(E27=1,$C$4*SQRT(D27),IF(E27=2,$C$4+($C$5-$C$4)*D27,$C$6-($C$6-$C$5)*SQRT(1-D27))) -> 3.0159059
B28: 12 | C28: =RAND() -> 0.87593753 | D28: =RAND() -> 0.78755093 | E28: =IF(C28<=$C$10,1,IF(C28<=$C$10+$C$11,2,3)) -> 3 | F28: =IF(E28=1,$C$4*SQRT(D28),IF(E28=2,$C$4+($C$5-$C$4)*D28,$C$6-($C$6-$C$5)*SQRT(1-D28))) -> 8.6172341
... B1016: 1000 | C1016: =RAND() -> 0.56485633 | D1016: =RAND() -> 0.73735232 | E1016: =IF(C1016<=$C$10,1,IF(C1016<=$C$10+$C$11,2,3)) -> 2 | F1016: =IF(E1016=1,$C$4*SQRT(D1016),IF(E1016=2,$C$4+($C$5-$C$4)*D1016,$C$6-($C$6-$C$5)*SQRT(1-D1016))) -> 5.9494093
B1018: Promedio X = | C1018: =AVERAGE(F17:F1016) -> 5.0035354
B1019: Mínimo X = | C1019: =MIN(F17:F1016) -> 0.053967765
B1020: Máximo X = | C1020: =MAX(F17:F1016) -> 9.8988731
B1023: Histograma vs. densidad teórica (dominio [0, c])
H1024: h (altura meseta) = | I1024: =2/(-C4+C5+C6) -> 0.14285714
B1025: Bin | C1025: Lím. inf. | D1025: Lím. sup. | E1025: Punto medio | F1025: Frecuencia | G1025: Densidad emp. | H1025: Densidad teór.
B1026: 1 | C1026: =($C$6/20)*0 -> 0 | D1026: =($C$6/20)*1 -> 0.5 | E1026: =(C1026+D1026)/2 -> 0.25 | F1026: =COUNTIFS($F$17:$F$1016,">="&C1026,$F$17:$F$1016,"<"&D1026) -> 8 | G1026: =F1026/($C$7*(D1026-C1026)) -> 0.016 | H1026: =IF(E1026<=$C$4,$I$1024*E1026/$C$4,IF(E1026<=$C$5,$I$1024,$I$1024*($C$6-E1026)/($C$6-$C$5))) -> 0.011904762
B1027: 2 | C1027: =($C$6/20)*1 -> 0.5 | D1027: =($C$6/20)*2 -> 1 | E1027: =(C1027+D1027)/2 -> 0.75 | F1027: =COUNTIFS($F$17:$F$1016,">="&C1027,$F$17:$F$1016,"<"&D1027) -> 15 | G1027: =F1027/($C$7*(D1027-C1027)) -> 0.03 | H1027: =IF(E1027<=$C$4,$I$1024*E1027/$C$4,IF(E1027<=$C$5,$I$1024,$I$1024*($C$6-E1027)/($C$6-$C$5))) -> 0.035714286
B1028: 3 | C1028: =($C$6/20)*2 -> 1 | D1028: =($C$6/20)*3 -> 1.5 | E1028: =(C1028+D1028)/2 -> 1.25 | F1028: =COUNTIFS($F$17:$F$1016,">="&C1028,$F$17:$F$1016,"<"&D1028) -> 27 | G1028: =F1028/($C$7*(D1028-C1028)) -> 0.054 | H1028: =IF(E1028<=$C$4,$I$1024*E1028/$C$4,IF(E1028<=$C$5,$I$1024,$I$1024*($C$6-E1028)/($C$6-$C$5))) -> 0.05952381
B1029: 4 | C1029: =($C$6/20)*3 -> 1.5 | D1029: =($C$6/20)*4 -> 2 | E1029: =(C1029+D1029)/2 -> 1.75 | F1029: =COUNTIFS($F$17:$F$1016,">="&C1029,$F$17:$F$1016,"<"&D1029) -> 35 | G1029: =F1029/($C$7*(D1029-C1029)) -> 0.07 | H1029: =IF(E1029<=$C$4,$I$1024*E1029/$C$4,IF(E1029<=$C$5,$I$1024,$I$1024*($C$6-E1029)/($C$6-$C$5))) -> 0.083333333
B1030: 5 | C1030: =($C$6/20)*4 -> 2 | D1030: =($C$6/20)*5 -> 2.5 | E1030: =(C1030+D1030)/2 -> 2.25 | F1030: =COUNTIFS($F$17:$F$1016,">="&C1030,$F$17:$F$1016,"<"&D1030) -> 55 | G1030: =F1030/($C$7*(D1030-C1030)) -> 0.11 | H1030: =IF(E1030<=$C$4,$I$1024*E1030/$C$4,IF(E1030<=$C$5,$I$1024,$I$1024*($C$6-E1030)/($C$6-$C$5))) -> 0.10714286
B1031: 6 | C1031: =($C$6/20)*5 -> 2.5 | D1031: =($C$6/20)*6 -> 3 | E1031: =(C1031+D1031)/2 -> 2.75 | F1031: =COUNTIFS($F$17:$F$1016,">="&C1031,$F$17:$F$1016,"<"&D1031) -> 56 | G1031: =F1031/($C$7*(D1031-C1031)) -> 0.112 | H1031: =IF(E1031<=$C$4,$I$1024*E1031/$C$4,IF(E1031<=$C$5,$I$1024,$I$1024*($C$6-E1031)/($C$6-$C$5))) -> 0.13095238
B1032: 7 | C1032: =($C$6/20)*6 -> 3 | D1032: =($C$6/20)*7 -> 3.5 | E1032: =(C1032+D1032)/2 -> 3.25 | F1032: =COUNTIFS($F$17:$F$1016,">="&C1032,$F$17:$F$1016,"<"&D1032) -> 74 | G1032: =F1032/($C$7*(D1032-C1032)) -> 0.148 | H1032: =IF(E1032<=$C$4,$I$1024*E1032/$C$4,IF(E1032<=$C$5,$I$1024,$I$1024*($C$6-E1032)/($C$6-$C$5))) -> 0.14285714
B1033: 8 | C1033: =($C$6/20)*7 -> 3.5 | D1033: =($C$6/20)*8 -> 4 | E1033: =(C1033+D1033)/2 -> 3.75 | F1033: =COUNTIFS($F$17:$F$1016,">="&C1033,$F$17:$F$1016,"<"&D1033) -> 88 | G1033: =F1033/($C$7*(D1033-C1033)) -> 0.176 | H1033: =IF(E1033<=$C$4,$I$1024*E1033/$C$4,IF(E1033<=$C$5,$I$1024,$I$1024*($C$6-E1033)/($C$6-$C$5))) -> 0.14285714
B1034: 9 | C1034: =($C$6/20)*8 -> 4 | D1034: =($C$6/20)*9 -> 4.5 | E1034: =(C1034+D1034)/2 -> 4.25 | F1034: =COUNTIFS($F$17:$F$1016,">="&C1034,$F$17:$F$1016,"<"&D1034) -> 62 | G1034: =F1034/($C$7*(D1034-C1034)) -> 0.124 | H1034: =IF(E1034<=$C$4,$I$1024*E1034/$C$4,IF(E1034<=$C$5,$I$1024,$I$1024*($C$6-E1034)/($C$6-$C$5))) -> 0.14285714
...

Sheet Ejercicio 2 - Triangular V
B1: Ejercicio 2
B3: Parámetros
B4: a (punto 1) = | C4: 8 | G4: Debe cumplirse: a < c < b
B5: c (vértice) = | C5: 9
B6: b (punto 3) = | C6: 10
B7: N° simulaciones = | C7: 1000
B9: Áreas (Paso 1 de la teoría)
B10: A1 = | C10: =(C5-C4)/(C6-C4) -> 0.5
B11: A2 = | C11: =(C6-C5)/(C6-C4) -> 0.5
B12: Suma = | C12: =C10+C11 -> 1
B16: iteracion | C16: R_region | D16: R_valor | E16: Region | F16: X
B17: 1 | C17: =RAND() -> 0.43798882 | D17: =RAND() -> 0.8375502 | E17: =IF(C17<=$C$10,1,2) -> 1 | F17: =IF(E17=1,$C$4+SQRT(D17*($C$6-$C$4)*($C$5-$C$4)),$C$6-SQRT((1-D17)*($C$6-$C$4)*($C$6-$C$5))) -> 9.2942567
B18: 2 | C18: =RAND() -> 0.30992138 | D18: =RAND() -> 0.20959272 | E18: =IF(C18<=$C$10,1,2) -> 1 | F18: =IF(E18=1,$C$4+SQRT(D18*($C$6-$C$4)*($C$5-$C$4)),$C$6-SQRT((1-D18)*($C$6-$C$4)*($C$6-$C$5))) -> 8.6474453
B19: 3 | C19: =RAND() -> 0.16697596 | D19: =RAND() -> 0.8691507 | E19: =IF(C19<=$C$10,1,2) -> 1 | F19: =IF(E19=1,$C$4+SQRT(D19*($C$6-$C$4)*($C$5-$C$4)),$C$6-SQRT((1-D19)*($C$6-$C$4)*($C$6-$C$5))) -> 9.3184466
B20: 4 | C20: =RAND() -> 0.16982072 | D20: =RAND() -> 0.72258929 | E20: =IF(C20<=$C$10,1,2) -> 1 | F20: =IF(E20=1,$C$4+SQRT(D20*($C$6-$C$4)*($C$5-$C$4)),$C$6-SQRT((1-D20)*($C$6-$C$4)*($C$6-$C$5))) -> 9.2021558
B21: 5 | C21: =RAND() -> 0.21299243 | D21: =RAND() -> 0.78557649 | E21: =IF(C21<=$C$10,1,2) -> 1 | F21: =IF(E21=1,$C$4+SQRT(D21*($C$6-$C$4)*($C$5-$C$4)),$C$6-SQRT((1-D21)*($C$6-$C$4)*($C$6-$C$5))) -> 9.2534564
B22: 6 | C22: =RAND() -> 0.89389787 | D22: =RAND() -> 0.23784977 | E22: =IF(C22<=$C$10,1,2) -> 2 | F22: =IF(E22=1,$C$4+SQRT(D22*($C$6-$C$4)*($C$5-$C$4)),$C$6-SQRT((1-D22)*($C$6-$C$4)*($C$6-$C$5))) -> 8.7653744
B23: 7 | C23: =RAND() -> 0.77079164 | D23: =RAND() -> 0.63292486 | E23: =IF(C23<=$C$10,1,2) -> 2 | F23: =IF(E23=1,$C$4+SQRT(D23*($C$6-$C$4)*($C$5-$C$4)),$C$6-SQRT((1-D23)*($C$6-$C$4)*($C$6-$C$5))) -> 9.1431743
B24: 8 | C24: =RAND() -> 0.27247167 | D24: =RAND() -> 0.77521819 | E24: =IF(C24<=$C$10,1,2) -> 1 | F24: =IF(E24=1,$C$4+SQRT(D24*($C$6-$C$4)*($C$5-$C$4)),$C$6-SQRT((1-D24)*($C$6-$C$4)*($C$6-$C$5))) -> 9.2451652
B25: 9 | C25: =RAND() -> 0.70952535 | D25: =RAND() -> 0.49954541 | E25: =IF(C25<=$C$10,1,2) -> 2 | F25: =IF(E25=1,$C$4+SQRT(D25*($C$6-$C$4)*($C$5-$C$4)),$C$6-SQRT((1-D25)*($C$6-$C$4)*($C$6-$C$5))) -> 8.9995455
B26: 10 | C26: =RAND() -> 0.53390172 | D26: =RAND() -> 0.61524758 | E26: =IF(C26<=$C$10,1,2) -> 2 | F26: =IF(E26=1,$C$4+SQRT(D26*($C$6-$C$4)*($C$5-$C$4)),$C$6-SQRT((1-D26)*($C$6-$C$4)*($C$6-$C$5))) -> 9.1227857
B27: 11 | C27: =RAND() -> 0.68455095 | D27: =RAND() -> 0.35070772 | E27: =IF(C27<=$C$10,1,2) -> 2 | F27: =IF(E27=1,$C$4+SQRT(D27*($C$6-$C$4)*($C$5-$C$4)),$C$6-SQRT((1-D27)*($C$6-$C$4)*($C$6-$C$5))) -> 8.8604455
B28: 12 | C28: =RAND() -> 0.37921058 | D28: =RAND() -> 0.63241274 | E28: =IF(C28<=$C$10,1,2) -> 1 | F28: =IF(E28=1,$C$4+SQRT(D28*($C$6-$C$4)*($C$5-$C$4)),$C$6-SQRT((1-D28)*($C$6-$C$4)*($C$6-$C$5))) -> 9.1246446
... B1016: 1000 | C1016: =RAND() -> 0.93423704 | D1016: =RAND() -> 0.82588804 | E1016: =IF(C1016<=$C$10,1,2) -> 2 | F1016: =IF(E1016=1,$C$4+SQRT(D1016*($C$6-$C$4)*($C$5-$C$4)),$C$6-SQRT((1-D1016)*($C$6-$C$4)*($C$6-$C$5))) -> 9.409895
B1018: Promedio X = | C1018: =AVERAGE(F17:F1016) -> 9.0061818
B1019: Mínimo X = | C1019: =MIN(F17:F1016) -> 8.0278119
B1020: Máximo X = | C1020: =MAX(F17:F1016) -> 9.9433951
B1023: Histograma vs. densidad teórica (dominio [a, b])
B1024: Bin | C1024: Lím. inf. | D1024: Lím. sup. | E1024: Punto medio | F1024: Frecuencia | G1024: Densidad emp. | H1024: Densidad teór.
B1025: 1 | C1025: =$C$4+(($C$6-$C$4)/20)*0 -> 8 | D1025: =$C$4+(($C$6-$C$4)/20)*1 -> 8.1 | E1025: =(C1025+D1025)/2 -> 8.05 | F1025: =COUNTIFS($F$17:$F$1016,">="&C1025,$F$17:$F$1016,"<"&D1025) -> 4 | G1025: =F1025/($C$7*(D1025-C1025)) -> 0.04 | H1025: =IF(E1025<=$C$5,2*(E1025-$C$4)/(($C$6-$C$4)*($C$5-$C$4)),2*($C$6-E1025)/(($C$6-$C$4)*($C$6-$C$5))) -> 0.05
B1026: 2 | C1026: =$C$4+(($C$6-$C$4)/20)*1 -> 8.1 | D1026: =$C$4+(($C$6-$C$4)/20)*2 -> 8.2 | E1026: =(C1026+D1026)/2 -> 8.15 | F1026: =COUNTIFS($F$17:$F$1016,">="&C1026,$F$17:$F$1016,"<"&D1026) -> 8 | G1026: =F1026/($C$7*(D1026-C1026)) -> 0.08 | H1026: =IF(E1026<=$C$5,2*(E1026-$C$4)/(($C$6-$C$4)*($C$5-$C$4)),2*($C$6-E1026)/(($C$6-$C$4)*($C$6-$C$5))) -> 0.15
B1027: 3 | C1027: =$C$4+(($C$6-$C$4)/20)*2 -> 8.2 | D1027: =$C$4+(($C$6-$C$4)/20)*3 -> 8.3 | E1027: =(C1027+D1027)/2 -> 8.25 | F1027: =COUNTIFS($F$17:$F$1016,">="&C1027,$F$17:$F$1016,"<"&D1027) -> 6 | G1027: =F1027/($C$7*(D1027-C1027)) -> 0.06 | H1027: =IF(E1027<=$C$5,2*(E1027-$C$4)/(($C$6-$C$4)*($C$5-$C$4)),2*($C$6-E1027)/(($C$6-$C$4)*($C$6-$C$5))) -> 0.25
B1028: 4 | C1028: =$C$4+(($C$6-$C$4)/20)*3 -> 8.3 | D1028: =$C$4+(($C$6-$C$4)/20)*4 -> 8.4 | E1028: =(C1028+D1028)/2 -> 8.35 | F1028: =COUNTIFS($F$17:$F$1016,">="&C1028,$F$17:$F$1016,"<"&D1028) -> 15 | G1028: =F1028/($C$7*(D1028-C1028)) -> 0.15 | H1028: =IF(E1028<=$C$5,2*(E1028-$C$4)/(($C$6-$C$4)*($C$5-$C$4)),2*($C$6-E1028)/(($C$6-$C$4)*($C$6-$C$5))) -> 0.35
B1029: 5 | C1029: =$C$4+(($C$6-$C$4)/20)*4 -> 8.4 | D1029: =$C$4+(($C$6-$C$4)/20)*5 -> 8.5 | E1029: =(C1029+D1029)/2 -> 8.45 | F1029: =COUNTIFS($F$17:$F$1016,">="&C1029,$F$17:$F$1016,"<"&D1029) -> 33 | G1029: =F1029/($C$7*(D1029-C1029)) -> 0.33 | H1029: =IF(E1029<=$C$5,2*(E1029-$C$4)/(($C$6-$C$4)*($C$5-$C$4)),2*($C$6-E1029)/(($C$6-$C$4)*($C$6-$C$5))) -> 0.45
B1030: 6 | C1030: =$C$4+(($C$6-$C$4)/20)*5 -> 8.5 | D1030: =$C$4+(($C$6-$C$4)/20)*6 -> 8.6 | E1030: =(C1030+D1030)/2 -> 8.55 | F1030: =COUNTIFS($F$17:$F$1016,">="&C1030,$F$17:$F$1016,"<"&D1030) -> 29 | G1030: =F1030/($C$7*(D1030-C1030)) -> 0.29 | H1030: =IF(E1030<=$C$5,2*(E1030-$C$4)/(($C$6-$C$4)*($C$5-$C$4)),2*($C$6-E1030)/(($C$6-$C$4)*($C$6-$C$5))) -> 0.55
B1031: 7 | C1031: =$C$4+(($C$6-$C$4)/20)*6 -> 8.6 | D1031: =$C$4+(($C$6-$C$4)/20)*7 -> 8.7 | E1031: =(C1031+D1031)/2 -> 8.65 | F1031: =COUNTIFS($F$17:$F$1016,">="&C1031,$F$17:$F$1016,"<"&D1031) -> 105 | G1031: =F1031/($C$7*(D1031-C1031)) -> 1.05 | H1031: =IF(E1031<=$C$5,2*(E1031-$C$4)/(($C$6-$C$4)*($C$5-$C$4)),2*($C$6-E1031)/(($C$6-$C$4)*($C$6-$C$5))) -> 0.65
B1032: 8 | C1032: =$C$4+(($C$6-$C$4)/20)*7 -> 8.7 | D1032: =$C$4+(($C$6-$C$4)/20)*8 -> 8.8 | E1032: =(C1032+D1032)/2 -> 8.75 | F1032: =COUNTIFS($F$17:$F$1016,">="&C1032,$F$17:$F$1016,"<"&D1032) -> 98 | G1032: =F1032/($C$7*(D1032-C1032)) -> 0.98 | H1032: =IF(E1032<=$C$5,2*(E1032-$C$4)/(($C$6-$C$4)*($C$5-$C$4)),2*($C$6-E1032)/(($C$6-$C$4)*($C$6-$C$5))) -> 0.75
B1033: 9 | C1033: =$C$4+(($C$6-$C$4)/20)*8 -> 8.8 | D1033: =$C$4+(($C$6-$C$4)/20)*9 -> 8.9 | E1033: =(C1033+D1033)/2 -> 8.85 | F1033: =COUNTIFS($F$17:$F$1016,">="&C1033,$F$17:$F$1016,"<"&D1033) -> 100 | G1033: =F1033/($C$7*(D1033-C1033)) -> 1 | H1033: =IF(E1033<=$C$5,2*(E1033-$C$4)/(($C$6-$C$4)*($C$5-$C$4)),2*($C$6-E1033)/(($C$6-$C$4)*($C$6-$C$5))) -> 0.85
B1034: 10 | C1034: =$C$4+(($C$6-$C$4)/20)*9 -> 8.9 | D1034: =$C$4+(($C$6-$C$4)/20)*10 -> 9 | E1034: =(C1034+D1034)/2 -> 8.95 | F1034: =COUNTIFS($F$17:$F$1016,">="&C1034,$F$17:$F$1016,"<"&D1034) -> 87 | G1034: =F1034/($C$7*(D1034-C1034)) -> 0.87 | H1034: =IF(E1034<=$C$5,2*(E1034-$C$4)/(($C$6-$C$4)*($C$5-$C$4)),2*($C$6-E1034)/(($C$6-$C$4)*($C$6-$C$5))) -> 0.95
B1035: 11 | C1035: =$C$4+(($C$6-$C$4)/20)*10 -> 9 | D1035: =$C$4+(($C$6-$C$4)/20)*11 -> 9.1 | E1035: =(C1035+D1035)/2 -> 9.05 | F1035: =COUNTIFS($F$17:$F$1016,">="&C1035,$F$17:$F$1016,"<"&D1035) -> 96 | G1035: =F1035/($C$7*(D1035-C1035)) -> 0.96 | H1035: =IF(E1035<=$C$5,2*(E1035-$C$4)/(($C$6-$C$4)*($C$5-$C$4)),2*($C$6-E1035)/(($C$6-$C$4)*($C$6-$C$5))) -> 0.95
...

Sheet Ejercicio 3 - TIR
B2: EJERCICIO 3
B4: Parámetros generales
B5: Tasa de impuestos (T) | D5: 0.5
B6: TREMA | D6: 0.15
B7: Vida fiscal del activo (años) | D7: 5
B8: Umbral de aceptación Prob(TIR>TREMA) | D8: 0.9
B9: Número de simulaciones | D9: 1000
B11: Activo fijo y activo circulante inicial (distribución triangular)
B12: Variable | C12: a (mínimo / optimista) | D12: b (moda / más probable) | E12: c (máximo / pesimista)
B13: Activo fijo inicial (AF) | C13: 60000 | D13: 70000 | E13: 100000
B14: Activo circulante inicial (AC) | C14: 25000 | D14: 30000 | E14: 40000
B16: Flujo de efectivo antes de impuestos, por año (triangular, igual los 5 años)
B17: Variable | C17: a (mínimo / optimista) | D17: b (moda / más probable) | E17: c (máximo / pesimista)
B18: Flujo antes de impuestos (x) | C18: 30000 | D18: 40000 | E18: 45000
B20: Tasas de inflación, por año (triangular)
B21: Año | C21: a (mínimo / optimista) | D21: b (moda / más probable) | E21: c (máximo / pesimista)
B22: 1 | C22: 0.12 | D22: 0.15 | E22: 0.18
B23: 2 | C23: 0.12 | D23: 0.15 | E23: 0.18
B24: 3 | C24: 0.15 | D24: 0.18 | E24: 0.22
B25: 4 | C25: 0.18 | D25: 0.2 | E25: 0.25
B26: 5 | C26: 0.19 | D26: 0.22 | E26: 0.28
B29: Extremos teóricos
B30: TIR mínima (todo pesimista) | D30: -0.031
B31: TIR máxima (todo optimista) | D31: 0.1991
B34: ── Resultados de la simulación ──
B35: Tabla de frecuencia acumulada de la TIR simulada (Pasos 3, 8 y 9)
B36: Intervalo # | C36: Límite inferior (%) | D36: Límite superior (%) | E36: Frecuencia | F36: Fracción | G36: Fracción acumulada
B37: 1 | C37: =$D$30*100 -> -3.1 | D37: =$D$30*100+($D$31*100-$D$30*100)/20*1 -> -1.9495 | E37: =COUNTIFS('Ejercicio 3 - Simulacion'!$BV$2:$BV$1001,">="&C37,'Ejercicio 3 - Simulacion'!$BV$2:$BV$1001,"<="&D37) -> 0 | F37: =E37/$D$9 -> 0 | G37: =F37 -> 0
B38: 2 | C38: =D37 -> -1.9495 | D38: =$D$30*100+($D$31*100-$D$30*100)/20*2 -> -0.799 | E38: =COUNTIFS('Ejercicio 3 - Simulacion'!$BV$2:$BV$1001,">"&C38,'Ejercicio 3 - Simulacion'!$BV$2:$BV$1001,"<="&D38) -> 0 | F38: =E38/$D$9 -> 0 | G38: =G37+F38 -> 0
B39: 3 | C39: =D38 -> -0.799 | D39: =$D$30*100+($D$31*100-$D$30*100)/20*3 -> 0.3515 | E39: =COUNTIFS('Ejercicio 3 - Simulacion'!$BV$2:$BV$1001,">"&C39,'Ejercicio 3 - Simulacion'!$BV$2:$BV$1001,"<="&D39) -> 0 | F39: =E39/$D$9 -> 0 | G39: =G38+F39 -> 0
B40: 4 | C40: =D39 -> 0.3515 | D40: =$D$30*100+($D$31*100-$D$30*100)/20*4 -> 1.502 | E40: =COUNTIFS('Ejercicio 3 - Simulacion'!$BV$2:$BV$1001,">"&C40,'Ejercicio 3 - Simulacion'!$BV$2:$BV$1001,"<="&D40) -> 0 | F40: =E40/$D$9 -> 0 | G40: =G39+F40 -> 0
B41: 5 | C41: =D40 -> 1.502 | D41: =$D$30*100+($D$31*100-$D$30*100)/20*5 -> 2.6525 | E41: =COUNTIFS('Ejercicio 3 - Simulacion'!$BV$2:$BV$1001,">"&C41,'Ejercicio 3 - Simulacion'!$BV$2:$BV$1001,"<="&D41) -> 0 | F41: =E41/$D$9 -> 0 | G41: =G40+F41 -> 0
B42: 6 | C42: =D41 -> 2.6525 | D42: =$D$30*100+($D$31*100-$D$30*100)/20*6 -> 3.803 | E42: =COUNTIFS('Ejercicio 3 - Simulacion'!$BV$2:$BV$1001,">"&C42,'Ejercicio 3 - Simulacion'!$BV$2:$BV$1001,"<="&D42) -> 16 | F42: =E42/$D$9 -> 0.016 | G42: =G41+F42 -> 0.016
B43: 7 | C43: =D42 -> 3.803 | D43: =$D$30*100+($D$31*100-$D$30*100)/20*7 -> 4.9535 | E43: =COUNTIFS('Ejercicio 3 - Simulacion'!$BV$2:$BV$1001,">"&C43,'Ejercicio 3 - Simulacion'!$BV$2:$BV$1001,"<="&D43) -> 67 | F43: =E43/$D$9 -> 0.067 | G43: =G42+F43 -> 0.083
B44: 8 | C44: =D43 -> 4.9535 | D44: =$D$30*100+($D$31*100-$D$30*100)/20*8 -> 6.104 | E44: =COUNTIFS('Ejercicio 3 - Simulacion'!$BV$2:$BV$1001,">"&C44,'Ejercicio 3 - Simulacion'!$BV$2:$BV$1001,"<="&D44) -> 119 | F44: =E44/$D$9 -> 0.119 | G44: =G43+F44 -> 0.202
B45: 9 | C45: =D44 -> 6.104 | D45: =$D$30*100+($D$31*100-$D$30*100)/20*9 -> 7.2545 | E45: =COUNTIFS('Ejercicio 3 - Simulacion'!$BV$2:$BV$1001,">"&C45,'Ejercicio 3 - Simulacion'!$BV$2:$BV$1001,"<="&D45) -> 195 | F45: =E45/$D$9 -> 0.195 | G45: =G44+F45 -> 0.397
B46: 10 | C46: =D45 -> 7.2545 | D46: =$D$30*100+($D$31*100-$D$30*100)/20*10 -> 8.405 | E46: =COUNTIFS('Ejercicio 3 - Simulacion'!$BV$2:$BV$1001,">"&C46,'Ejercicio 3 - Simulacion'!$BV$2:$BV$1001,"<="&D46) -> 214 | F46: =E46/$D$9 -> 0.214 | G46: =G45+F46 -> 0.611
B47: 11 | C47: =D46 -> 8.405 | D47: =$D$30*100+($D$31*100-$D$30*100)/20*11 -> 9.5555 | E47: =COUNTIFS('Ejercicio 3 - Simulacion'!$BV$2:$BV$1001,">"&C47,'Ejercicio 3 - Simulacion'!$BV$2:$BV$1001,"<="&D47) -> 189 | F47: =E47/$D$9 -> 0.189 | G47: =G46+F47 -> 0.8
B48: 12 | C48: =D47 -> 9.5555 | D48: =$D$30*100+($D$31*100-$D$30*100)/20*12 -> 10.706 | E48: =COUNTIFS('Ejercicio 3 - Simulacion'!$BV$2:$BV$1001,">"&C48,'Ejercicio 3 - Simulacion'!$BV$2:$BV$1001,"<="&D48) -> 110 | F48: =E48/$D$9 -> 0.11 | G48: =G47+F48 -> 0.91
B49: 13 | C49: =D48 -> 10.706 | D49: =$D$30*100+($D$31*100-$D$30*100)/20*13 -> 11.8565 | E49: =COUNTIFS('Ejercicio 3 - Simulacion'!$BV$2:$BV$1001,">"&C49,'Ejercicio 3 - Simulacion'!$BV$2:$BV$1001,"<="&D49) -> 70 | F49: =E49/$D$9 -> 0.07 | G49: =G48+F49 -> 0.98
...

Sheet Ejercicio 3 - Simulacion
A1: N° sim | B1: R (AF) | C1: AF simulado | D1: R (AC) | E1: AC simulado | F1: R (x año 1) | G1: x año 1 | H1: R (x año 2) | I1: x año 2 | J1: R (x año 3) | K1: x año 3 | L1: R (x año 4) | M1: x año 4 | N1: R (x año 5) | O1: x año 5 | P1: R (i año 1) | Q1: i año 1 | R1: R (i año 2) | S1: i año 2 | T1: R (i año 3) | U1: i año 3 | V1: R (i año 4) | W1: i año 4 | X1: R (i año 5) | Y1: i año 5 | Z1: Inflación acum. año 1 | AA1: Inflación acum. año 2 | AB1: Inflación acum. año 3 | AC1: Inflación acum. año 4 | AD1: Inflación acum. año 5 | AE1: Inv. adicional AC año 1 | AF1: Inv. adicional AC año 2 | AG1: Inv. adicional AC año 3 | AH1: Inv. adicional AC año 4 | AI1: Inv. adicional AC año 5 | AJ1: Flujo antes imp. año 1 (corriente) | AK1: Flujo antes imp. año 2 (corriente) | AL1: Flujo antes imp. año 3 (corriente) | AM1: Flujo antes imp. año 4 (corriente) | AN1: Flujo antes imp. año 5 (corriente) | AO1: Depreciación (fija) | AP1: Ingreso gravable año 1 | AQ1: Ingreso gravable año 2 | AR1: Ingreso gravable año 3 | AS1: Ingreso gravable año 4 | AT1: Ingreso gravable año 5 | AU1: Impuestos año 1 | AV1: Impuestos año 2 | AW1: Impuestos año 3 | AX1: Impuestos año 4 | AY1: Impuestos año 5 | AZ1: Flujo desp. imp. año 1 (corriente) | BA1: Flujo desp. imp. año 2 (corriente) | BB1: Flujo desp. imp. año 3 (corriente) | BC1: Flujo desp. imp. año 4 (corriente) | BD1: Flujo desp. imp. año 5 (corriente) | BE1: Flujo desp. imp. año 1 (constante) | BF1: Flujo desp. imp. año 2 (constante) | BG1: Flujo desp. imp. año 3 (constante) | BH1: Flujo desp. imp. año 4 (constante) | BI1: Flujo desp. imp. año 5 (constante) | BJ1: VR: AC recuperado (nominal) | BK1: VR: 20% AF recuperado (nominal) | BL1: VR antes de impuestos | BM1: VR impuestos | BN1: VR pesos corrientes | BO1: VR pesos constantes | BP1: Flujo año 0 | BQ1: Flujo año 1 | BR1: Flujo año 2 | BS1: Flujo año 3 | BT1: Flujo año 4 | BU1: Flujo año 5 | BV1: TIR simulada
A2: 1 | B2: =RAND() -> 0.17604283 | C2: =IF(B2<=('Ejercicio 3 - TIR'!$D$13-'Ejercicio 3 - TIR'!$C$13)/('Ejercicio 3 - TIR'!$E$13-'Ejercicio 3 - TIR'!$C$13),'Ejercicio 3 - TIR'!$C$13+SQRT(('Ejercicio 3 - TIR'!$E$13-'Ejercicio 3 - TIR'!$C$13)*('Ejercicio 3 - TIR'!$D$13-'Ejercicio 3 - TIR'!$C$13)*B2),'Ejercicio 3 - TIR'!$E$13-SQRT(('Ejercicio 3 - TIR'!$E$13-'Ejercicio 3 - TIR'!$C$13)*('Ejercicio 3 - TIR'!$E$13-'Ejercicio 3 - TIR'!$D$13)*(1-B2))) -> 68391.492 | D2: =RAND() -> 0.43599568 | E2: =IF(D2<=('Ejercicio 3 - TIR'!$D$14-'Ejercicio 3 - TIR'!$C$14)/('Ejercicio 3 - TIR'!$E$14-'Ejercicio 3 - TIR'!$C$14),'Ejercicio 3 - TIR'!$C$14+SQRT(('Ejercicio 3 - TIR'!$E$14-'Ejercicio 3 - TIR'!$C$14)*('Ejercicio 3 - TIR'!$D$14-'Ejercicio 3 - TIR'!$C$14)*D2),'Ejercicio 3 - TIR'!$E$14-SQRT(('Ejercicio 3 - TIR'!$E$14-'Ejercicio 3 - TIR'!$C$14)*('Ejercicio 3 - TIR'!$E$14-'Ejercicio 3 - TIR'!$D$14)*(1-D2))) -> 30802.139 | F2: =RAND() -> 0.74322412 | G2: =IF(F2<=('Ejercicio 3 - TIR'!$D$18-'Ejercicio 3 - TIR'!$C$18)/('Ejercicio 3 - TIR'!$E$18-'Ejercicio 3 - TIR'!$C$18),'Ejercicio 3 - TIR'!$C$18+SQRT(('Ejercicio 3 - TIR'!$E$18-'Ejercicio 3 - TIR'!$C$18)*('Ejercicio 3 - TIR'!$D$18-'Ejercicio 3 - TIR'!$C$18)*F2),'Ejercicio 3 - TIR'!$E$18-SQRT(('Ejercicio 3 - TIR'!$E$18-'Ejercicio 3 - TIR'!$C$18)*('Ejercicio 3 - TIR'!$E$18-'Ejercicio 3 - TIR'!$D$18)*(1-F2))) -> 40611.584 | H2: =RAND() -> 0.11371915 | I2: =IF(H2<=('Ejercicio 3 - TIR'!$D$18-'Ejercicio 3 - TIR'!$C$18)/('Ejercicio 3 - TIR'!$E$18-'Ejercicio 3 - TIR'!$C$18),'Ejercicio 3 - TIR'!$C$18+SQRT(('Ejercicio 3 - TIR'!$E$18-'Ejercicio 3 - TIR'!$C$18)*('Ejercicio 3 - TIR'!$D$18-'Ejercicio 3 - TIR'!$C$18)*H2),'Ejercicio 3 - TIR'!$E$18-SQRT(('Ejercicio 3 - TIR'!$E$18-'Ejercicio 3 - TIR'!$C$18)*('Ejercicio 3 - TIR'!$E$18-'Ejercicio 3 - TIR'!$D$18)*(1-H2))) -> 34130.118 | J2: =RAND() -> 0.57794757 | K2: =IF(J2<=('Ejercicio 3 - TIR'!$D$18-'Ejercicio 3 - TIR'!$C$18)/('Ejercicio 3 - TIR'!$E$18-'Ejercicio 3 - TIR'!$C$18),'Ejercicio 3 - TIR'!$C$18+SQRT(('Ejercicio 3 - TIR'!$E$18-'Ejercicio 3 - TIR'!$C$18)*('Ejercicio 3 - TIR'!$D$18-'Ejercicio 3 - TIR'!$C$18)*J2),'Ejercicio 3 - TIR'!$E$18-SQRT(('Ejercicio 3 - TIR'!$E$18-'Ejercicio 3 - TIR'!$C$18)*('Ejercicio 3 - TIR'!$E$18-'Ejercicio 3 - TIR'!$D$18)*(1-J2))) -> 39310.861 | L2: =RAND() -> 0.23226942 | M2: =IF(L2<=('Ejercicio 3 - TIR'!$D$18-'Ejercicio 3 - TIR'!$C$18)/('Ejercicio 3 - TIR'!$E$18-'Ejercicio 3 - TIR'!$C$18),'Ejercicio 3 - TIR'!$C$18+SQRT(('Ejercicio 3 - TIR'!$E$18-'Ejercicio 3 - TIR'!$C$18)*('Ejercicio 3 - TIR'!$D$18-'Ejercicio 3 - TIR'!$C$18)*L2),'Ejercicio 3 - TIR'!$E$18-SQRT(('Ejercicio 3 - TIR'!$E$18-'Ejercicio 3 - TIR'!$C$18)*('Ejercicio 3 - TIR'!$E$18-'Ejercicio 3 - TIR'!$D$18)*(1-L2))) -> 35902.577 | N2: =RAND() -> 0.6200061 | O2: =IF(N2<=('Ejercicio 3 - TIR'!$D$18-'Ejercicio 3 - TIR'!$C$18)/('Ejercicio 3 - TIR'!$E$18-'Ejercicio 3 - TIR'!$C$18),'Ejercicio 3 - TIR'!$C$18+SQRT(('Ejercicio 3 - TIR'!$E$18-'Ejercicio 3 - TIR'!$C$18)*('Ejercicio 3 - TIR'!$D$18-'Ejercicio 3 - TIR'!$C$18)*N2),'Ejercicio 3 - TIR'!$E$18-SQRT(('Ejercicio 3 - TIR'!$E$18-'Ejercicio 3 - TIR'!$C$18)*('Ejercicio 3 - TIR'!$E$18-'Ejercicio 3 - TIR'!$D$18)*(1-N2))) -> 39643.698 | P2: =RAND() -> 0.32887827 | Q2: =IF(P2<=('Ejercicio 3 - TIR'!$D$22-'Ejercicio 3 - TIR'!$C$22)/('Ejercicio 3 - TIR'!$E$22-'Ejercicio 3 - TIR'!$C$22),'Ejercicio 3 - TIR'!$C$22+SQRT(('Ejercicio 3 - TIR'!$E$22-'Ejercicio 3 - TIR'!$C$22)*('Ejercicio 3 - TIR'!$D$22-'Ejercicio 3 - TIR'!$C$22)*P2),'Ejercicio 3 - TIR'!$E$22-SQRT(('Ejercicio 3 - TIR'!$E$22-'Ejercicio 3 - TIR'!$C$22)*('Ejercicio 3 - TIR'!$E$22-'Ejercicio 3 - TIR'!$D$22)*(1-P2))) -> 0.14433066 | R2: =RAND() -> 0.94153219 | S2: =IF(R2<=('Ejercicio 3 - TIR'!$D$23-'Ejercicio 3 - TIR'!$C$23)/('Ejercicio 3 - TIR'!$E$23-'Ejercicio 3 - TIR'!$C$23),'Ejercicio 3 - TIR'!$C$23+SQRT(('Ejercicio 3 - TIR'!$E$23-'Ejercicio 3 - TIR'!$C$23)*('Ejercicio 3 - TIR'!$D$23-'Ejercicio 3 - TIR'!$C$23)*R2),'Ejercicio 3 - TIR'!$E$23-SQRT(('Ejercicio 3 - TIR'!$E$23-'Ejercicio 3 - TIR'!$C$23)*('Ejercicio 3 - TIR'!$E$23-'Ejercicio 3 - TIR'!$D$23)*(1-R2))) -> 0.16974124 | T2: =RAND() -> 0.72587293 | U2: =IF(T2<=('Ejercicio 3 - TIR'!$D$24-'Ejercicio 3 - TIR'!$C$24)/('Ejercicio 3 - TIR'!$E$24-'Ejercicio 3 - TIR'!$C$24),'Ejercicio 3 - TIR'!$C$24+SQRT(('Ejercicio 3 - TIR'!$E$24-'Ejercicio 3 - TIR'!$C$24)*('Ejercicio 3 - TIR'!$D$24-'Ejercicio 3 - TIR'!$C$24)*T2),'Ejercicio 3 - TIR'!$E$24-SQRT(('Ejercicio 3 - TIR'!$E$24-'Ejercicio 3 - TIR'!$C$24)*('Ejercicio 3 - TIR'!$E$24-'Ejercicio 3 - TIR'!$D$24)*(1-T2))) -> 0.1922952 | V2: =RAND() -> 0.70192371 | W2: =IF(V2<=('Ejercicio 3 - TIR'!$D$25-'Ejercicio 3 - TIR'!$C$25)/('Ejercicio 3 - TIR'!$E$25-'Ejercicio 3 - TIR'!$C$25),'Ejercicio 3 - TIR'!$C$25+SQRT(('Ejercicio 3 - TIR'!$E$25-'Ejercicio 3 - TIR'!$C$25)*('Ejercicio 3 - TIR'!$D$25-'Ejercicio 3 - TIR'!$C$25)*V2),'Ejercicio 3 - TIR'!$E$25-SQRT(('Ejercicio 3 - TIR'!$E$25-'Ejercicio 3 - TIR'!$C$25)*('Ejercicio 3 - TIR'!$E$25-'Ejercicio 3 - TIR'!$D$25)*(1-V2))) -> 0.21770036 | X2: =RAND() -> 0.97192974 | Y2: =IF(X2<=('Ejercicio 3 - TIR'!$D$26-'Ejercicio 3 - TIR'!$C$26)/('Ejercicio 3 - TIR'!$E$26-'Ejercicio 3 - TIR'!$C$26),'Ejercicio 3 - TIR'!$C$26+SQRT(('Ejercicio 3 - TIR'!$E$26-'Ejercicio 3 - TIR'!$C$26)*('Ejercicio 3 - TIR'!$D$26-'Ejercicio 3 - TIR'!$C$26)*X2),'Ejercicio 3 - TIR'!$E$26-SQRT(('Ejercicio 3 - TIR'!$E$26-'Ejercicio 3 - TIR'!$C$26)*('Ejercicio 3 - TIR'!$E$26-'Ejercicio 3 - TIR'!$D$26)*(1-X2))) -> 0.26768824 | Z2: =(1+Q2) -> 1.1443307 | AA2: =Z2*(1+S2) -> 1.3385708 | AB2: =AA2*(1+U2) -> 1.5959715 | AC2: =AB2*(1+W2) -> 1.9434151 | AD2: =AC2*(1+Y2) -> 2.4636444 | AE2: =E2*Q2 -> 4445.693 | AF2: =AE2*(1+S2) -> 5200.3104 | AG2: =AF2*(1+U2) -> 6200.3052 | AH2: =AG2*(1+W2) -> 7550.1138 | AI2: =AH2*(1+Y2) -> 9571.1905 | AJ2: =G2*Z2 -> 46473.081 | AK2: =I2*AA2 -> 45685.578 | AL2: =K2*AB2 -> 62739.014 | AM2: =M2*AC2 -> 69773.609 | AN2: =O2*AD2 -> 97667.976 | AO2: =C2/'Ejercicio 3 - TIR'!$D$7 -> 13678.298 | AP2: =AJ2-AO2 -> 32794.783 | AQ2: =AK2-AO2 -> 32007.279 | AR2: =AL2-AO2 -> 49060.716 | AS2: =AM2-AO2 -> 56095.31 | AT2: =AN2-AO2 -> 83989.678 | AU2: =AP2*'Ejercicio 3 - TIR'!$D$5 -> 16397.391 | AV2: =AQ2*'Ejercicio 3 - TIR'!$D$5 -> 16003.64 | AW2: =AR2*'Ejercicio 3 - TIR'!$D$5 -> 24530.358 | AX2: =AS2*'Ejercicio 3 - TIR'!$D$5 -> 28047.655 | AY2: =AT2*'Ejercicio 3 - TIR'!$D$5 -> 41994.839 | AZ2: =AJ2-AU2-AE2 -> 25629.997 | BA2: =AK2-AV2-AF2 -> 24481.628 | BB2: =AL2-AW2-AG2 -> 32008.351 | BC2: =AM2-AX2-AH2 -> 34175.84 | BD2: =AN2-AY2-AI2 -> 46101.947 | BE2: =AZ2/Z2 -> 22397.37 | BF2: =BA2/AA2 -> 18289.379 | BG2: =BB2/AB2 -> 20055.716 | BH2: =BC2/AC2 -> 17585.456 | BI2: =BD2/AD2 -> 18712.906 | BJ2: =E2*AD2 -> 75885.518 | BK2: =0.2*C2*AD2 -> 33698.464 | BL2: =BJ2+BK2 -> 109583.98 | BM2: =BK2*'Ejercicio 3 - TIR'!$D$5 -> 16849.232 | BN2: =BL2-BM2 -> 92734.75 | BO2: =BN2/AD2 -> 37641.288 | BP2: =-(C2+E2) -> -99193.631 | BQ2: =BE2 -> 22397.37 | BR2: =BF2 -> 18289.379 | BS2: =BG2 -> 20055.716 | BT2: =BH2 -> 17585.456 | BU2: =BI2+BO2 -> 56354.194 | BV2: =IFERROR(IRR(BP2:BU2,0.1),NA())*100 -> 9.4391741
A3: 2 | B3: =RAND() -> 0.79830747 | C3: =IF(B3<=('Ejercicio 3 - TIR'!$D$13-'Ejercicio 3 - TIR'!$C$13)/('Ejercicio 3 - TIR'!$E$13-'Ejercicio 3 - TIR'!$C$13),'Ejercicio 3 - TIR'!$C$13+SQRT(('Ejercicio 3 - TIR'!$E$13-'Ejercicio 3 - TIR'!$C$13)*('Ejercicio 3 - TIR'!$D$13-'Ejercicio 3 - TIR'!$C$13)*B3),'Ejercicio 3 - TIR'!$E$13-SQRT(('Ejercicio 3 - TIR'!$E$13-'Ejercicio 3 - TIR'!$C$13)*('Ejercicio 3 - TIR'!$E$13-'Ejercicio 3 - TIR'!$D$13)*(1-B3))) -> 84442.653 | D3: =RAND() -> 0.51342874 | E3: =IF(D3<=('Ejercicio 3 - TIR'!$D$14-'Ejercicio 3 - TIR'!$C$14)/('Ejercicio 3 - TIR'!$E$14-'Ejercicio 3 - TIR'!$C$14),'Ejercicio 3 - TIR'!$C$14+SQRT(('Ejercicio 3 - TIR'!$E$14-'Ejercicio 3 - TIR'!$C$14)*('Ejercicio 3 - TIR'!$D$14-'Ejercicio 3 - TIR'!$C$14)*D3),'Ejercicio 3 - TIR'!$E$14-SQRT(('Ejercicio 3 - TIR'!$E$14-'Ejercicio 3 - TIR'!$C$14)*('Ejercicio 3 - TIR'!$E$14-'Ejercicio 3 - TIR'!$D$14)*(1-D3))) -> 31456.834 | F3: =RAND() -> 0.50048557 | G3: =IF(F3<=('Ejercicio 3 - TIR'!$D$18-'Ejercicio 3 - TIR'!$C$18)/('Ejercicio 3 - TIR'!$E$18-'Ejercicio 3 - TIR'!$C$18),'Ejercicio 3 - TIR'!$C$18+SQRT(('Ejercicio 3 - TIR'!$E$18-'Ejercicio 3 - TIR'!$C$18)*('Ejercicio 3 - TIR'!$D$18-'Ejercicio 3 - TIR'!$C$18)*F3),'Ejercicio 3 - TIR'!$E$18-SQRT(('Ejercicio 3 - TIR'!$E$18-'Ejercicio 3 - TIR'!$C$18)*('Ejercicio 3 - TIR'!$E$18-'Ejercicio 3 - TIR'!$D$18)*(1-F3))) -> 38664.458 | H3: =RAND() -> 0.26263857 | I3: =IF(H3<=('Ejercicio 3 - TIR'!$D$18-'Ejercicio 3 - TIR'!$C$18)/('Ejercicio 3 - TIR'!$E$18-'Ejercicio 3 - TIR'!$C$18),'Ejercicio 3 - TIR'!$C$18+SQRT(('Ejercicio 3 - TIR'!$E$18-'Ejercicio 3 - TIR'!$C$18)*('Ejercicio 3 - TIR'!$D$18-'Ejercicio 3 - TIR'!$C$18)*H3),'Ejercicio 3 - TIR'!$E$18-SQRT(('Ejercicio 3 - TIR'!$E$18-'Ejercicio 3 - TIR'!$C$18)*('Ejercicio 3 - TIR'!$E$18-'Ejercicio 3 - TIR'!$D$18)*(1-H3))) -> 36276.606 | J3: =RAND() -> 0.97490481 | K3: =IF(J3<=('Ejercicio 3 - TIR'!$D$18-'Ejercicio 3 - TIR'!$C$18)/('Ejercicio 3 - TIR'!$E$18-'Ejercicio 3 - TIR'!$C$18),'Ejercicio 3 - TIR'!$C$18+SQRT(('Ejercicio 3 - TIR'!$E$18-'Ejercicio 3 - TIR'!$C$18)*('Ejercicio 3 - TIR'!$D$18-'Ejercicio 3 - TIR'!$C$18)*J3),'Ejercicio 3 - TIR'!$E$18-SQRT(('Ejercicio 3 - TIR'!$E$18-'Ejercicio 3 - TIR'!$C$18)*('Ejercicio 3 - TIR'!$E$18-'Ejercicio 3 - TIR'!$D$18)*(1-J3))) -> 43628.089 | L3: =RAND() -> 0.51139775 | M3: =IF(L3<=('Ejercicio 3 - TIR'!$D$18-'Ejercicio 3 - TIR'!$C$18)/('Ejercicio 3 - TIR'!$E$18-'Ejercicio 3 - TIR'!$C$18),'Ejercicio 3 - TIR'!$C$18+SQRT(('Ejercicio 3 - TIR'!$E$18-'Ejercicio 3 - TIR'!$C$18)*('Ejercicio 3 - TIR'!$D$18-'Ejercicio 3 - TIR'!$C$18)*L3),'Ejercicio 3 - TIR'!$E$18-SQRT(('Ejercicio 3 - TIR'!$E$18-'Ejercicio 3 - TIR'!$C$18)*('Ejercicio 3 - TIR'!$E$18-'Ejercicio 3 - TIR'!$D$18)*(1-L3))) -> 38758.405 | N3: =RAND() -> 0.99215931 | O3: =IF(N3<=('Ejercicio 3 - TIR'!$D$18-'Ejercicio 3 - TIR'!$C$18)/('Ejercicio 3 - TIR'!$E$18-'Ejercicio 3 - TIR'!$C$18),'Ejercicio 3 - TIR'!$C$18+SQRT(('Ejercicio 3 - TIR'!$E$18-'Ejercicio 3 - TIR'!$C$18)*('Ejercicio 3 - TIR'!$D$18-'Ejercicio 3 - TIR'!$C$18)*N3),'Ejercicio 3 - TIR'!$E$18-SQRT(('Ejercicio 3 - TIR'!$E$18-'Ejercicio 3 - TIR'!$C$18)*('Ejercicio 3 - TIR'!$E$18-'Ejercicio 3 - TIR'!$D$18)*(1-N3))) -> 44233.155 | P3: =RAND() -> 0.9550529 | Q3: =IF(P3<=('Ejercicio 3 - TIR'!$D$22-'Ejercicio 3 - TIR'!$C$22)/('Ejercicio 3 - TIR'!$E$22-'Ejercicio 3 - TIR'!$C$22),'Ejercicio 3 - TIR'!$C$22+SQRT(('Ejercicio 3 - TIR'!$E$22-'Ejercicio 3 - TIR'!$C$22)*('Ejercicio 3 - TIR'!$D$22-'Ejercicio 3 - TIR'!$C$22)*P3),'Ejercicio 3 - TIR'!$E$22-SQRT(('Ejercicio 3 - TIR'!$E$22-'Ejercicio 3 - TIR'!$C$22)*('Ejercicio 3 - TIR'!$E$22-'Ejercicio 3 - TIR'!$D$22)*(1-P3))) -> 0.17100529 | R3: =RAND() -> 0.50818638 | S3: =IF(R3<=('Ejercicio 3 - TIR'!$D$23-'Ejercicio 3 - TIR'!$C$23)/('Ejercicio 3 - TIR'!$E$23-'Ejercicio 3 - TIR'!$C$23),'Ejercicio 3 - TIR'!$C$23+SQRT(('Ejercicio 3 - TIR'!$E$23-'Ejercicio 3 - TIR'!$C$23)*('Ejercicio 3 - TIR'!$D$23-'Ejercicio 3 - TIR'!$C$23)*R3),'Ejercicio 3 - TIR'!$E$23-SQRT(('Ejercicio 3 - TIR'!$E$23-'Ejercicio 3 - TIR'!$C$23)*('Ejercicio 3 - TIR'!$E$23-'Ejercicio 3 - TIR'!$D$23)*(1-R3))) -> 0.15024661 | T3: =RAND() -> 0.068333505 | U3: =IF(T3<=('Ejercicio 3 - TIR'!$D$24-'Ejercicio 3 - TIR'!$C$24)/('Ejercicio 3 - TIR'!$E$24-'Ejercicio 3 - TIR'!$C$24),'Ejercicio 3 - TIR'!$C$24+SQRT(('Ejercicio 3 - TIR'!$E$24-'Ejercicio 3 - TIR'!$C$24)*('Ejercicio 3 - TIR'!$D$24-'Ejercicio 3 - TIR'!$C$24)*T3),'Ejercicio 3 - TIR'!$E$24-SQRT(('Ejercicio 3 - TIR'!$E$24-'Ejercicio 3 - TIR'!$C$24)*('Ejercicio 3 - TIR'!$E$24-'Ejercicio 3 - TIR'!$D$24)*(1-T3))) -> 0.16197916 | V3: =RAND() -> 0.54082263 | W3: =IF(V3<=('Ejercicio 3 - TIR'!$D$25-'Ejercicio 3 - TIR'!$C$25)/('Ejercicio 3 - TIR'!$E$25-'Ejercicio 3 - TIR'!$C$25),'Ejercicio 3 - TIR'!$C$25+SQRT(('Ejercicio 3 - TIR'!$E$25-'Ejercicio 3 - TIR'!$C$25)*('Ejercicio 3 - TIR'!$D$25-'Ejercicio 3 - TIR'!$C$25)*V3),'Ejercicio 3 - TIR'!$E$25-SQRT(('Ejercicio 3 - TIR'!$E$25-'Ejercicio 3 - TIR'!$C$25)*('Ejercicio 3 - TIR'!$E$25-'Ejercicio 3 - TIR'!$D$25)*(1-V3))) -> 0.20991109 | X3: =RAND() -> 0.046361504 | Y3: =IF(X3<=('Ejercicio 3 - TIR'!$D$26-'Ejercicio 3 - TIR'!$C$26)/('Ejercicio 3 - TIR'!$E$26-'Ejercicio 3 - TIR'!$C$26),'Ejercicio 3 - TIR'!$C$26+SQRT(('Ejercicio 3 - TIR'!$E$26-'Ejercicio 3 - TIR'!$C$26)*('Ejercicio 3 - TIR'!$D$26-'Ejercicio 3 - TIR'!$C$26)*X3),'Ejercicio 3 - TIR'!$E$26-SQRT(('Ejercicio 3 - TIR'!$E$26-'Ejercicio 3 - TIR'!$C$26)*('Ejercicio 3 - TIR'!$E$26-'Ejercicio 3 - TIR'!$D$26)*(1-X3))) -> 0.20118821 | Z3: =(1+Q3) -> 1.1710053 | AA3: =Z3*(1+S3) -> 1.3469449 | AB3: =AA3*(1+U3) -> 1.5651219 | AC3: =AB3*(1+W3) -> 1.8936583 | AD3: =AC3*(1+Y3) -> 2.27464 | AE3: =E3*Q3 -> 5379.2851 | AF3: =AE3*(1+S3) -> 6187.5044 | AG3: =AF3*(1+U3) -> 7189.7512 | AH3: =AG3*(1+W3) -> 8698.9596 | AI3: =AH3*(1+Y3) -> 10449.088 | AJ3: =G3*Z3 -> 45276.285 | AK3: =I3*AA3 -> 48862.588 | AL3: =K3*AB3 -> 68283.276 | AM3: =M3*AC3 -> 73395.176 | AN3: =O3*AD3 -> 100614.5 | AO3: =C3/'Ejercicio 3 - TIR'!$D$7 -> 16888.531 | AP3: =AJ3-AO3 -> 28387.754 | AQ3: =AK3-AO3 -> 31974.058 | AR3: =AL3-AO3 -> 51394.745 | AS3: =AM3-AO3 -> 56506.645 | AT3: =AN3-AO3 -> 83725.973 | AU3: =AP3*'Ejercicio 3 - TIR'!$D$5 -> 14193.877 | AV3: =AQ3*'Ejercicio 3 - TIR'!$D$5 -> 15987.029 | AW3: =AR3*'Ejercicio 3 - TIR'!$D$5 -> 25697.373 | AX3: =AS3*'Ejercicio 3 - TIR'!$D$5 -> 28253.323 | AY3: =AT3*'Ejercicio 3 - TIR'!$D$5 -> 41862.987 | AZ3: =AJ3-AU3-AE3 -> 25703.123 | BA3: =AK3-AV3-AF3 -> 26688.055 | BB3: =AL3-AW3-AG3 -> 35396.152 | BC3: =AM3-AX3-AH3 -> 36442.894 | BD3: =AN3-AY3-AI3 -> 48302.429 | BE3: =AZ3/Z3 -> 21949.621 | BF3: =BA3/AA3 -> 19813.77 | BG3: =BB3/AB3 -> 22615.589 | BH3: =BC3/AC3 -> 19244.704 | BI3: =BD3/AD3 -> 21235.197 | BJ3: =E3*AD3 -> 71552.973 | BK3: =0.2*C3*AD3 -> 38415.328 | BL3: =BJ3+BK3 -> 109968.3 | BM3: =BK3*'Ejercicio 3 - TIR'!$D$5 -> 19207.664 | BN3: =BL3-BM3 -> 90760.637 | BO3: =BN3/AD3 -> 39901.099 | BP3: =-(C3+E3) -> -115899.49 | BQ3: =BE3 -> 21949.621 | BR3: =BF3 -> 19813.77 | BS3: =BG3 -> 22615.589 | BT3: =BH3 -> 19244.704 | BU3: =BI3+BO3 -> 61136.296 | BV3: =IFERROR(IRR(BP3:BU3,0.1),NA())*100 -> 6.6308369
A4: 3 | B4: =RAND() -> 0.57055546 | C4: =IF(B4<=('Ejercicio 3 - TIR'!$D$13-'Ejercicio 3 - TIR'!$C$13)/('Ejercicio 3 - TIR'!$E$13-'Ejercicio 3 - TIR'!$C$13),'Ejercicio 3 - TIR'!$C$13+SQRT(('Ejercicio 3 - TIR'!$E$13-'Ejercicio 3 - TIR'!$C$13)*('Ejercicio 3 - TIR'!$D$13-'Ejercicio 3 - TIR'!$C$13)*B4),'Ejercicio 3 - TIR'!$E$13-SQRT(('Ejercicio 3 - TIR'!$E$13-'Ejercicio 3 - TIR'!$C$13)*('Ejercicio 3 - TIR'!$E$13-'Ejercicio 3 - TIR'!$D$13)*(1-B4))) -> 77299.043 | D4: =RAND() -> 0.4011356 | E4: =IF(D4<=('Ejercicio 3 - TIR'!$D$14-'Ejercicio 3 - TIR'!$C$14)/('Ejercicio 3 - TIR'!$E$14-'Ejercicio 3 - TIR'!$C$14),'Ejercicio 3 - TIR'!$C$14+SQRT(('Ejercicio 3 - TIR'!$E$14-'Ejercicio 3 - TIR'!$C$14)*('Ejercicio 3 - TIR'!$D$14-'Ejercicio 3 - TIR'!$C$14)*D4),'Ejercicio 3 - TIR'!$E$14-SQRT(('Ejercicio 3 - TIR'!$E$14-'Ejercicio 3 - TIR'!$C$14)*('Ejercicio 3 - TIR'!$E$14-'Ejercicio 3 - TIR'!$D$14)*(1-D4))) -> 30522.149 | F4: =RAND() -> 0.62274308 | G4: =IF(F4<=('Ejercicio 3 - TIR'!$D$18-'Ejercicio 3 - TIR'!$C$18)/('Ejercicio 3 - TIR'!$E$18-'Ejercicio 3 - TIR'!$C$18),'Ejercicio 3 - TIR'!$C$18+SQRT(('Ejercicio 3 - TIR'!$E$18-'Ejercicio 3 - TIR'!$C$18)*('Ejercicio 3 - TIR'!$D$18-'Ejercicio 3 - TIR'!$C$18)*F4),'Ejercicio 3 - TIR'!$E$18-SQRT(('Ejercicio 3 - TIR'!$E$18-'Ejercicio 3 - TIR'!$C$18)*('Ejercicio 3 - TIR'!$E$18-'Ejercicio 3 - TIR'!$D$18)*(1-F4))) -> 39664.961 | H4: =RAND() -> 0.56507133 | I4: =IF(H4<=('Ejercicio 3 - TIR'!$D$18-'Ejercicio 3 - TIR'!$C$18)/('Ejercicio 3 - TIR'!$E$18-'Ejercicio 3 - TIR'!$C$18),'Ejercicio 3 - TIR'!$C$18+SQRT(('Ejercicio 3 - TIR'!$E$18-'Ejercicio 3 - TIR'!$C$18)*('Ejercicio 3 - TIR'!$D$18-'Ejercicio 3 - TIR'!$C$18)*H4),'Ejercicio 3 - TIR'!$E$18-SQRT(('Ejercicio 3 - TIR'!$E$18-'Ejercicio 3 - TIR'!$C$18)*('Ejercicio 3 - TIR'!$E$18-'Ejercicio 3 - TIR'!$D$18)*(1-H4))) -> 39206.557 | J4: =RAND() -> 0.89923617 | K4: =IF(J4<=('Ejercicio 3 - TIR'!$D$18-'Ejercicio 3 - TIR'!$C$18)/('Ejercicio 3 - TIR'!$E$18-'Ejercicio 3 - TIR'!$C$18),'Ejercicio 3 - TIR'!$C$18+SQRT(('Ejercicio 3 - TIR'!$E$18-'Ejercicio 3 - TIR'!$C$18)*('Ejercicio 3 - TIR'!$D$18-'Ejercicio 3 - TIR'!$C$18)*J4),'Ejercicio 3 - TIR'!$E$18-SQRT(('Ejercicio 3 - TIR'!$E$18-'Ejercicio 3 - TIR'!$C$18)*('Ejercicio 3 - TIR'!$E$18-'Ejercicio 3 - TIR'!$D$18)*(1-J4))) -> 42250.948 | L4: =RAND() -> 0.23184138 | M4: =IF(L4<=('Ejercicio 3 - TIR'!$D$18-'Ejercicio 3 - TIR'!$C$18)/('Ejercicio 3 - TIR'!$E$18-'Ejercicio 3 - TIR'!$C$18),'Ejercicio 3 - TIR'!$C$18+SQRT(('Ejercicio 3 - TIR'!$E$18-'Ejercicio 3 - TIR'!$C$18)*('Ejercicio 3 - TIR'!$D$18-'Ejercicio 3 - TIR'!$C$18)*L4),'Ejercicio 3 - TIR'!$E$18-SQRT(('Ejercicio 3 - TIR'!$E$18-'Ejercicio 3 - TIR'!$C$18)*('Ejercicio 3 - TIR'!$E$18-'Ejercicio 3 - TIR'!$D$18)*(1-L4))) -> 35897.135 | N4: =RAND() -> 0.41248435 | O4: =IF(N4<=('Ejercicio 3 - TIR'!$D$18-'Ejercicio 3 - TIR'!$C$18)/('Ejercicio 3 - TIR'!$E$18-'Ejercicio 3 - TIR'!$C$18),'Ejercicio 3 - TIR'!$C$18+SQRT(('Ejercicio 3 - TIR'!$E$18-'Ejercicio 3 - TIR'!$C$18)*('Ejercicio 3 - TIR'!$D$18-'Ejercicio 3 - TIR'!$C$18)*N4),'Ejercicio 3 - TIR'!$E$18-SQRT(('Ejercicio 3 - TIR'!$E$18-'Ejercicio 3 - TIR'!$C$18)*('Ejercicio 3 - TIR'!$E$18-'Ejercicio 3 - TIR'!$D$18)*(1-N4))) -> 37865.917 | P4: =RAND() -> 0.62892038 | Q4: =IF(P4<=('Ejercicio 3 - TIR'!$D$22-'Ejercicio 3 - TIR'!$C$22)/('Ejercicio 3 - TIR'!$E$22-'Ejercicio 3 - TIR'!$C$22),'Ejercicio 3 - TIR'!$C$22+SQRT(('Ejercicio 3 - TIR'!$E$22-'Ejercicio 3 - TIR'!$C$22)*('Ejercicio 3 - TIR'!$D$22-'Ejercicio 3 - TIR'!$C$22)*P4),'Ejercicio 3 - TIR'!$E$22-SQRT(('Ejercicio 3 - TIR'!$E$22-'Ejercicio 3 - TIR'!$C$22)*('Ejercicio 3 - TIR'!$E$22-'Ejercicio 3 - TIR'!$D$22)*(1-P4))) -> 0.1541554 | R4: =RAND() -> 0.61410445 | S4: =IF(R4<=('Ejercicio 3 - TIR'!$D$23-'Ejercicio 3 - TIR'!$C$23)/('Ejercicio 3 - TIR'!$E$23-'Ejercicio 3 - TIR'!$C$23),'Ejercicio 3 - TIR'!$C$23+SQRT(('Ejercicio 3 - TIR'!$E$23-'Ejercicio 3 - TIR'!$C$23)*('Ejercicio 3 - TIR'!$D$23-'Ejercicio 3 - TIR'!$C$23)*R4),'Ejercicio 3 - TIR'!$E$23-SQRT(('Ejercicio 3 - TIR'!$E$23-'Ejercicio 3 - TIR'!$C$23)*('Ejercicio 3 - TIR'!$E$23-'Ejercicio 3 - TIR'!$D$23)*(1-R4))) -> 0.15364451 | T4: =RAND() -> 0.53932903 | U4: =IF(T4<=('Ejercicio 3 - TIR'!$D$24-'Ejercicio 3 - TIR'!$C$24)/('Ejercicio 3 - TIR'!$E$24-'Ejercicio 3 - TIR'!$C$24),'Ejercicio 3 - TIR'!$C$24+SQRT(('Ejercicio 3 - TIR'!$E$24-'Ejercicio 3 - TIR'!$C$24)*('Ejercicio 3 - TIR'!$D$24-'Ejercicio 3 - TIR'!$C$24)*T4),'Ejercicio 3 - TIR'!$E$24-SQRT(('Ejercicio 3 - TIR'!$E$24-'Ejercicio 3 - TIR'!$C$24)*('Ejercicio 3 - TIR'!$E$24-'Ejercicio 3 - TIR'!$D$24)*(1-T4))) -> 0.18408512 | V4: =RAND() -> 0.41767713 | W4: =IF(V4<=('Ejercicio 3 - TIR'!$D$25-'Ejercicio 3 - TIR'!$C$25)/('Ejercicio 3 - TIR'!$E$25-'Ejercicio 3 - TIR'!$C$25),'Ejercicio 3 - TIR'!$C$25+SQRT(('Ejercicio 3 - TIR'!$E$25-'Ejercicio 3 - TIR'!$C$25)*('Ejercicio 3 - TIR'!$D$25-'Ejercicio 3 - TIR'!$C$25)*V4),'Ejercicio 3 - TIR'!$E$25-SQRT(('Ejercicio 3 - TIR'!$E$25-'Ejercicio 3 - TIR'!$C$25)*('Ejercicio 3 - TIR'!$E$25-'Ejercicio 3 - TIR'!$D$25)*(1-V4))) -> 0.20485435 | X4: =RAND() -> 0.092008793 | Y4: =IF(X4<=('Ejercicio 3 - TIR'!$D$26-'Ejercicio 3 - TIR'!$C$26)/('Ejercicio 3 - TIR'!$E$26-'Ejercicio 3 - TIR'!$C$26),'Ejercicio 3 - TIR'!$C$26+SQRT(('Ejercicio 3 - TIR'!$E$26-'Ejercicio 3 - TIR'!$C$26)*('Ejercicio 3 - TIR'!$D$26-'Ejercicio 3 - TIR'!$C$26)*X4),'Ejercicio 3 - TIR'!$E$26-SQRT(('Ejercicio 3 - TIR'!$E$26-'Ejercicio 3 - TIR'!$C$26)*('Ejercicio 3 - TIR'!$E$26-'Ejercicio 3 - TIR'!$D$26)*(1-X4))) -> 0.20576146 | Z4: =(1+Q4) -> 1.1541554 | AA4: =Z4*(1+S4) -> 1.331485 | AB4: =AA4*(1+U4) -> 1.5765916 | AC4: =AB4*(1+W4) -> 1.8995633 | AD4: =AC4*(1+Y4) -> 2.2904202 | AE4: =E4*Q4 -> 4705.1541 | AF4: =AE4*(1+S4) -> 5428.0752 | AG4: =AF4*(1+U4) -> 6427.3031 | AH4: =AG4*(1+W4) -> 7743.964 | AI4: =AH4*(1+Y4) -> 9337.3734 | AJ4: =G4*Z4 -> 45779.528 | AK4: =I4*AA4 -> 52202.945 | AL4: =K4*AB4 -> 66612.491 | AM4: =M4*AC4 -> 68188.88 | AN4: =O4*AD4 -> 86728.861 | AO4: =C4/'Ejercicio 3 - TIR'!$D$7 -> 15459.809 | AP4: =AJ4-AO4 -> 30319.72 | AQ4: =AK4-AO4 -> 36743.136 | AR4: =AL4-AO4 -> 51152.682 | AS4: =AM4-AO4 -> 52729.071 | AT4: =AN4-AO4 -> 71269.052 | AU4: =AP4*'Ejercicio 3 - TIR'!$D$5 -> 15159.86 | AV4: =AQ4*'Ejercicio 3 - TIR'!$D$5 -> 18371.568 | AW4: =AR4*'Ejercicio 3 - TIR'!$D$5 -> 25576.341 | AX4: =AS4*'Ejercicio 3 - TIR'!$D$5 -> 26364.536 | AY4: =AT4*'Ejercicio 3 - TIR'!$D$5 -> 35634.526 | AZ4: =AJ4-AU4-AE4 -> 25914.514 | BA4: =AK4-AV4-AF4 -> 28403.301 | BB4: =AL4-AW4-AG4 -> 34608.847 | BC4: =AM4-AX4-AH4 -> 34080.38 | BD4: =AN4-AY4-AI4 -> 41756.961 | BE4: =AZ4/Z4 -> 22453.228 | BF4: =BA4/AA4 -> 21332.047 | BG4: =BB4/AB4 -> 21951.687 | BH4: =BC4/AC4 -> 17941.166 | BI4: =BD4/AD4 -> 18231.136 | BJ4: =E4*AD4 -> 69908.546 | BK4: =0.2*C4*AD4 -> 35409.458 | BL4: =BJ4+BK4 -> 105318 | BM4: =BK4*'Ejercicio 3 - TIR'!$D$5 -> 17704.729 | BN4: =BL4-BM4 -> 87613.275 | BO4: =BN4/AD4 -> 38252.053 | BP4: =-(C4+E4) -> -107821.19 | BQ4: =BE4 -> 22453.228 | BR4: =BF4 -> 21332.047 | BS4: =BG4 -> 21951.687 | BT4: =BH4 -> 17941.166 | BU4: =BI4+BO4 -> 56483.189 | BV4: =IFERROR(IRR(BP4:BU4,0.1),NA())*100 -> 8.0953527
A5: 4 | B5: =RAND() -> 0.3502263 | C5: =IF(B5<=('Ejercicio 3 - TIR'!$D$13-'Ejercicio 3 - TIR'!$C$13)/('Ejercicio 3 - TIR'!$E$13-'Ejercicio 3 - TIR'!$C$13),'Ejercicio 3 - TIR'!$C$13+SQRT(('Ejercicio 3 - TIR'!$E$13-'Ejercicio 3 - TIR'!$C$13)*('Ejercicio 3 - TIR'!$D$13-'Ejercicio 3 - TIR'!$C$13)*B5),'Ejercicio 3 - TIR'!$E$13-SQRT(('Ejercicio 3 - TIR'!$E$13-'Ejercicio 3 - TIR'!$C$13)*('Ejercicio 3 - TIR'!$E$13-'Ejercicio 3 - TIR'!$D$13)*(1-B5))) -> 72076.382 | D5: =RAND() -> 0.89972942 | E5: =IF(D5<=('Ejercicio 3 - TIR'!$D$14-'Ejercicio 3 - TIR'!$C$14)/('Ejercicio 3 - TIR'!$E$14-'Ejercicio 3 - TIR'!$C$14),'Ejercicio 3 - TIR'!$C$14+SQRT(('Ejercicio 3 - TIR'!$E$14-'Ejercicio 3 - TIR'!$C$14)*('Ejercicio 3 - TIR'!$D$14-'Ejercicio 3 - TIR'!$C$14)*D5),'Ejercicio 3 - TIR'!$E$14-SQRT(('Ejercicio 3 - TIR'!$E$14-'Ejercicio 3 - TIR'!$C$14)*('Ejercicio 3 - TIR'!$E$14-'Ejercicio 3 - TIR'!$D$14)*(1-D5))) -> 36121.78 | F5: =RAND() -> 0.098215042 | G5: =IF(F5<=('Ejercicio 3 - TIR'!$D$18-'Ejercicio 3 - TIR'!$C$18)/('Ejercicio 3 - TIR'!$E$18-'Ejercicio 3 - TIR'!$C$18),'Ejercicio 3 - TIR'!$C$18+SQRT(('Ejercicio 3 - TIR'!$E$18-'Ejercicio 3 - TIR'!$C$18)*('Ejercicio 3 - TIR'!$D$18-'Ejercicio 3 - TIR'!$C$18)*F5),'Ejercicio 3 - TIR'!$E$18-SQRT(('Ejercicio 3 - TIR'!$E$18-'Ejercicio 3 - TIR'!$C$18)*('Ejercicio 3 - TIR'!$E$18-'Ejercicio 3 - TIR'!$D$18)*(1-F5))) -> 33838.262 | H5: =RAND() -> 0.53625286 | I5: =IF(H5<=('Ejercicio 3 - TIR'!$D$18-'Ejercicio 3 - TIR'!$C$18)/('Ejercicio 3 - TIR'!$E$18-'Ejercicio 3 - TIR'!$C$18),'Ejercicio 3 - TIR'!$C$18+SQRT(('Ejercicio 3 - TIR'!$E$18-'Ejercicio 3 - TIR'!$C$18)*('Ejercicio 3 - TIR'!$D$18-'Ejercicio 3 - TIR'!$C$18)*H5),'Ejercicio 3 - TIR'!$E$18-SQRT(('Ejercicio 3 - TIR'!$E$18-'Ejercicio 3 - TIR'!$C$18)*('Ejercicio 3 - TIR'!$E$18-'Ejercicio 3 - TIR'!$D$18)*(1-H5))) -> 38968.719 | J5: =RAND() -> 0.28868354 | K5: =IF(J5<=('Ejercicio 3 - TIR'!$D$18-'Ejercicio 3 - TIR'!$C$18)/('Ejercicio 3 - TIR'!$E$18-'Ejercicio 3 - TIR'!$C$18),'Ejercicio 3 - TIR'!$C$18+SQRT(('Ejercicio 3 - TIR'!$E$18-'Ejercicio 3 - TIR'!$C$18)*('Ejercicio 3 - TIR'!$D$18-'Ejercicio 3 - TIR'!$C$18)*J5),'Ejercicio 3 - TIR'!$E$18-SQRT(('Ejercicio 3 - TIR'!$E$18-'Ejercicio 3 - TIR'!$C$18)*('Ejercicio 3 - TIR'!$E$18-'Ejercicio 3 - TIR'!$D$18)*(1-J5))) -> 36580.466 | L5: =RAND() -> 0.099619092 | M5: =IF(L5<=('Ejercicio 3 - TIR'!$D$18-'Ejercicio 3 - TIR'!$C$18)/('Ejercicio 3 - TIR'!$E$18-'Ejercicio 3 - TIR'!$C$18),'Ejercicio 3 - TIR'!$C$18+SQRT(('Ejercicio 3 - TIR'!$E$18-'Ejercicio 3 - TIR'!$C$18)*('Ejercicio 3 - TIR'!$D$18-'Ejercicio 3 - TIR'!$C$18)*L5),'Ejercicio 3 - TIR'!$E$18-SQRT(('Ejercicio 3 - TIR'!$E$18-'Ejercicio 3 - TIR'!$C$18)*('Ejercicio 3 - TIR'!$E$18-'Ejercicio 3 - TIR'!$D$18)*(1-L5))) -> 33865.6 | N5: =RAND() -> 0.88488717 | O5: =IF(N5<=('Ejercicio 3 - TIR'!$D$18-'Ejercicio 3 - TIR'!$C$18)/('Ejercicio 3 - TIR'!$E$18-'Ejercicio 3 - TIR'!$C$18),'Ejercicio 3 - TIR'!$C$18+SQRT(('Ejercicio 3 - TIR'!$E$18-'Ejercicio 3 - TIR'!$C$18)*('Ejercicio 3 - TIR'!$D$18-'Ejercicio 3 - TIR'!$C$18)*N5),'Ejercicio 3 - TIR'!$E$18-SQRT(('Ejercicio 3 - TIR'!$E$18-'Ejercicio 3 - TIR'!$C$18)*('Ejercicio 3 - TIR'!$E$18-'Ejercicio 3 - TIR'!$D$18)*(1-N5))) -> 42061.725 | P5: =RAND() -> 0.34488789 | Q5: =IF(P5<=('Ejercicio 3 - TIR'!$D$22-'Ejercicio 3 - TIR'!$C$22)/('Ejercicio 3 - TIR'!$E$22-'Ejercicio 3 - TIR'!$C$22),'Ejercicio 3 - TIR'!$C$22+SQRT(('Ejercicio 3 - TIR'!$E$22-'Ejercicio 3 - TIR'!$C$22)*('Ejercicio 3 - TIR'!$D$22-'Ejercicio 3 - TIR'!$C$22)*P5),'Ejercicio 3 - TIR'!$E$22-SQRT(('Ejercicio 3 - TIR'!$E$22-'Ejercicio 3 - TIR'!$C$22)*('Ejercicio 3 - TIR'!$E$22-'Ejercicio 3 - TIR'!$D$22)*(1-P5))) -> 0.14491582 | R5: =RAND() -> 0.73083214 | S5: =IF(R5<=('Ejercicio 3 - TIR'!$D$23-'Ejercicio 3 - TIR'!$C$23)/('Ejercicio 3 - TIR'!$E$23-'Ejercicio 3 - TIR'!$C$23),'Ejercicio 3 - TIR'!$C$23+SQRT(('Ejercicio 3 - TIR'!$E$23-'Ejercicio 3 - TIR'!$C$23)*('Ejercicio 3 - TIR'!$D$23-'Ejercicio 3 - TIR'!$C$23)*R5),'Ejercicio 3 - TIR'!$E$23-SQRT(('Ejercicio 3 - TIR'!$E$23-'Ejercicio 3 - TIR'!$C$23)*('Ejercicio 3 - TIR'!$E$23-'Ejercicio 3 - TIR'!$D$23)*(1-R5))) -> 0.15798859 | T5: =RAND() -> 0.057329767 | U5: =IF(T5<=('Ejercicio 3 - TIR'!$D$24-'Ejercicio 3 - TIR'!$C$24)/('Ejercicio 3 - TIR'!$E$24-'Ejercicio 3 - TIR'!$C$24),'Ejercicio 3 - TIR'!$C$24+SQRT(('Ejercicio 3 - TIR'!$E$24-'Ejercicio 3 - TIR'!$C$24)*('Ejercicio 3 - TIR'!$D$24-'Ejercicio 3 - TIR'!$C$24)*T5),'Ejercicio 3 - TIR'!$E$24-SQRT(('Ejercicio 3 - TIR'!$E$24-'Ejercicio 3 - TIR'!$C$24)*('Ejercicio 3 - TIR'!$E$24-'Ejercicio 3 - TIR'!$D$24)*(1-T5))) -> 0.16097235 | V5: =RAND() -> 0.30429683 | W5: =IF(V5<=('Ejercicio 3 - TIR'!$D$25-'Ejercicio 3 - TIR'!$C$25)/('Ejercicio 3 - TIR'!$E$25-'Ejercicio 3 - TIR'!$C$25),'Ejercicio 3 - TIR'!$C$25+SQRT(('Ejercicio 3 - TIR'!$E$25-'Ejercicio 3 - TIR'!$C$25)*('Ejercicio 3 - TIR'!$D$25-'Ejercicio 3 - TIR'!$C$25)*V5),'Ejercicio 3 - TIR'!$E$25-SQRT(('Ejercicio 3 - TIR'!$E$25-'Ejercicio 3 - TIR'!$C$25)*('Ejercicio 3 - TIR'!$E$25-'Ejercicio 3 - TIR'!$D$25)*(1-V5))) -> 0.20065467 | X5: =RAND() -> 0.40115031 | Y5: =IF(X5<=('Ejercicio 3 - TIR'!$D$26-'Ejercicio 3 - TIR'!$C$26)/('Ejercicio 3 - TIR'!$E$26-'Ejercicio 3 - TIR'!$C$26),'Ejercicio 3 - TIR'!$C$26+SQRT(('Ejercicio 3 - TIR'!$E$26-'Ejercicio 3 - TIR'!$C$26)*('Ejercicio 3 - TIR'!$D$26-'Ejercicio 3 - TIR'!$C$26)*X5),'Ejercicio 3 - TIR'!$E$26-SQRT(('Ejercicio 3 - TIR'!$E$26-'Ejercicio 3 - TIR'!$C$26)*('Ejercicio 3 - TIR'!$E$26-'Ejercicio 3 - TIR'!$D$26)*(1-X5))) -> 0.22313359 | Z5: =(1+Q5) -> 1.1449158 | AA5: =Z5*(1+S5) -> 1.3257995 | AB5: =AA5*(1+U5) -> 1.5392165 | AC5: =AB5*(1+W5) -> 1.8480675 | AD5: =AC5*(1+Y5) -> 2.2604334 | AE5: =E5*Q5 -> 5234.6175 | AF5: =AE5*(1+S5) -> 6061.6274 | AG5: =AF5*(1+U5) -> 7037.3818 | AH5: =AG5*(1+W5) -> 8449.4653 | AI5: =AH5*(1+Y5) -> 10334.825 | AJ5: =G5*Z5 -> 38741.962 | AK5: =I5*AA5 -> 51664.707 | AL5: =K5*AB5 -> 56305.257 | AM5: =M5*AC5 -> 62585.915 | AN5: =O5*AD5 -> 95077.729 | AO5: =C5/'Ejercicio 3 - TIR'!$D$7 -> 14415.276 | AP5: =AJ5-AO5 -> 24326.685 | AQ5: =AK5-AO5 -> 37249.431 | AR5: =AL5-AO5 -> 41889.981 | AS5: =AM5-AO5 -> 48170.639 | AT5: =AN5-AO5 -> 80662.453 | AU5: =AP5*'Ejercicio 3 - TIR'!$D$5 -> 12163.343 | AV5: =AQ5*'Ejercicio 3 - TIR'!$D$5 -> 18624.715 | AW5: =AR5*'Ejercicio 3 - TIR'!$D$5 -> 20944.99 | AX5: =AS5*'Ejercicio 3 - TIR'!$D$5 -> 24085.319 | AY5: =AT5*'Ejercicio 3 - TIR'!$D$5 -> 40331.226 | AZ5: =AJ5-AU5-AE5 -> 21344.002 | BA5: =AK5-AV5-AF5 -> 26978.364 | BB5: =AL5-AW5-AG5 -> 28322.885 | BC5: =AM5-AX5-AH5 -> 30051.13 | BD5: =AN5-AY5-AI5 -> 44411.678 | BE5: =AZ5/Z5 -> 18642.42 | BF5: =BA5/AA5 -> 20348.752 | BG5: =BB5/AB5 -> 18400.845 | BH5: =BC5/AC5 -> 16260.84 | BI5: =BD5/AD5 -> 19647.417 | BJ5: =E5*AD5 -> 81650.881 | BK5: =0.2*C5*AD5 -> 32584.773 | BL5: =BJ5+BK5 -> 114235.65 | BM5: =BK5*'Ejercicio 3 - TIR'!$D$5 -> 16292.386 | BN5: =BL5-BM5 -> 97943.267 | BO5: =BN5/AD5 -> 43329.419 | BP5: =-(C5+E5) -> -108198.16 | BQ5: =BE5 -> 18642.42 | BR5: =BF5 -> 20348.752 | BS5: =BG5 -> 18400.845 | BT5: =BH5 -> 16260.84 | BU5: =BI5+BO5 -> 62976.835 | BV5: =IFERROR(IRR(BP5:BU5,0.1),NA())*100 -> 6.8069886
A6: 5 | B6: =RAND() -> 0.34982436 | C6: =IF(B6<=('Ejercicio 3 - TIR'!$D$13-'Ejercicio 3 - TIR'!$C$13)/('Ejercicio 3 - TIR'!$E$13-'Ejercicio 3 - TIR'!$C$13),'Ejercicio 3 - TIR'!$C$13+SQRT(('Ejercicio 3 - TIR'!$E$13-'Ejercicio 3 - TIR'!$C$13)*('Ejercicio 3 - TIR'!$D$13-'Ejercicio 3 - TIR'!$C$13)*B6),'Ejercicio 3 - TIR'!$E$13-SQRT(('Ejercicio 3 - TIR'!$E$13-'Ejercicio 3 - TIR'!$C$13)*('Ejercicio 3 - TIR'!$E$13-'Ejercicio 3 - TIR'!$D$13)*(1-B6))) -> 72067.747 | D6: =RAND() -> 0.99969213 | E6: =IF(D6<=('Ejercicio 3 - TIR'!$D$14-'Ejercicio 3 - TIR'!$C$14)/('Ejercicio 3 - TIR'!$E$14-'Ejercicio 3 - TIR'!$C$14),'Ejercicio 3 - TIR'!$C$14+SQRT(('Ejercicio 3 - TIR'!$E$14-'Ejercicio 3 - TIR'!$C$14)*('Ejercicio 3 - TIR'!$D$14-'Ejercicio 3 - TIR'!$C$14)*D6),'Ejercicio 3 - TIR'!$E$14-SQRT(('Ejercicio 3 - TIR'!$E$14-'Ejercicio 3 - TIR'!$C$14)*('Ejercicio 3 - TIR'!$E$14-'Ejercicio 3 - TIR'!$D$14)*(1-D6))) -> 39785.104 | F6: =RAND() -> 0.57028463 | G6: =IF(F6<=('Ejercicio 3 - TIR'!$D$18-'Ejercicio 3 - TIR'!$C$18)/('Ejercicio 3 - TIR'!$E$18-'Ejercicio 3 - TIR'!$C$18),'Ejercicio 3 - TIR'!$C$18+SQRT(('Ejercicio 3 - TIR'!$E$18-'Ejercicio 3 - TIR'!$C$18)*('Ejercicio 3 - TIR'!$D$18-'Ejercicio 3 - TIR'!$C$18)*F6),'Ejercicio 3 - TIR'!$E$18-SQRT(('Ejercicio 3 - TIR'!$E$18-'Ejercicio 3 - TIR'!$C$18)*('Ejercicio 3 - TIR'!$E$18-'Ejercicio 3 - TIR'!$D$18)*(1-F6))) -> 39248.929 | H6: =RAND() -> 0.7194127 | I6: =IF(H6<=('Ejercicio 3 - TIR'!$D$18-'Ejercicio 3 - TIR'!$C$18)/('Ejercicio 3 - TIR'!$E$18-'Ejercicio 3 - TIR'!$C$18),'Ejercicio 3 - TIR'!$C$18+SQRT(('Ejercicio 3 - TIR'!$E$18-'Ejercicio 3 - TIR'!$C$18)*('Ejercicio 3 - TIR'!$D$18-'Ejercicio 3 - TIR'!$C$18)*H6),'Ejercicio 3 - TIR'!$E$18-SQRT(('Ejercicio 3 - TIR'!$E$18-'Ejercicio 3 - TIR'!$C$18)*('Ejercicio 3 - TIR'!$E$18-'Ejercicio 3 - TIR'!$D$18)*(1-H6))) -> 40412.621 | J6: =RAND() -> 0.030706232 | K6: =IF(J6<=('Ejercicio 3 - TIR'!$D$18-'Ejercicio 3 - TIR'!$C$18)/('Ejercicio 3 - TIR'!$E$18-'Ejercicio 3 - TIR'!$C$18),'Ejercicio 3 - TIR'!$C$18+SQRT(('Ejercicio 3 - TIR'!$E$18-'Ejercicio 3 - TIR'!$C$18)*('Ejercicio 3 - TIR'!$D$18-'Ejercicio 3 - TIR'!$C$18)*J6),'Ejercicio 3 - TIR'!$E$18-SQRT(('Ejercicio 3 - TIR'!$E$18-'Ejercicio 3 - TIR'!$C$18)*('Ejercicio 3 - TIR'!$E$18-'Ejercicio 3 - TIR'!$D$18)*(1-J6))) -> 32146.144 | L6: =RAND() -> 0.039732221 | M6: =IF(L6<=('Ejercicio 3 - TIR'!$D$18-'Ejercicio 3 - TIR'!$C$18)/('Ejercicio 3 - TIR'!$E$18-'Ejercicio 3 - TIR'!$C$18),'Ejercicio 3 - TIR'!$C$18+SQRT(('Ejercicio 3 - TIR'!$E$18-'Ejercicio 3 - TIR'!$C$18)*('Ejercicio 3 - TIR'!$D$18-'Ejercicio 3 - TIR'!$C$18)*L6),'Ejercicio 3 - TIR'!$E$18-SQRT(('Ejercicio 3 - TIR'!$E$18-'Ejercicio 3 - TIR'!$C$18)*('Ejercicio 3 - TIR'!$E$18-'Ejercicio 3 - TIR'!$D$18)*(1-L6))) -> 32441.277 | N6: =RAND() -> 0.24796723 | O6: =IF(N6<=('Ejercicio 3 - TIR'!$D$18-'Ejercicio 3 - TIR'!$C$18)/('Ejercicio 3 - TIR'!$E$18-'Ejercicio 3 - TIR'!$C$18),'Ejercicio 3 - TIR'!$C$18+SQRT(('Ejercicio 3 - TIR'!$E$18-'Ejercicio 3 - TIR'!$C$18)*('Ejercicio 3 - TIR'!$D$18-'Ejercicio 3 - TIR'!$C$18)*N6),'Ejercicio 3 - TIR'!$E$18-SQRT(('Ejercicio 3 - TIR'!$E$18-'Ejercicio 3 - TIR'!$C$18)*('Ejercicio 3 - TIR'!$E$18-'Ejercicio 3 - TIR'!$D$18)*(1-N6))) -> 36098.777 | P6: =RAND() -> 0.38634233 | Q6: =IF(P6<=('Ejercicio 3 - TIR'!$D$22-'Ejercicio 3 - TIR'!$C$22)/('Ejercicio 3 - TIR'!$E$22-'Ejercicio 3 - TIR'!$C$22),'Ejercicio 3 - TIR'!$C$22+SQRT(('Ejercicio 3 - TIR'!$E$22-'Ejercicio 3 - TIR'!$C$22)*('Ejercicio 3 - TIR'!$D$22-'Ejercicio 3 - TIR'!$C$22)*P6),'Ejercicio 3 - TIR'!$E$22-SQRT(('Ejercicio 3 - TIR'!$E$22-'Ejercicio 3 - TIR'!$C$22)*('Ejercicio 3 - TIR'!$E$22-'Ejercicio 3 - TIR'!$D$22)*(1-P6))) -> 0.14637074 | R6: =RAND() -> 0.44007963 | S6: =IF(R6<=('Ejercicio 3 - TIR'!$D$23-'Ejercicio 3 - TIR'!$C$23)/('Ejercicio 3 - TIR'!$E$23-'Ejercicio 3 - TIR'!$C$23),'Ejercicio 3 - TIR'!$C$23+SQRT(('Ejercicio 3 - TIR'!$E$23-'Ejercicio 3 - TIR'!$C$23)*('Ejercicio 3 - TIR'!$D$23-'Ejercicio 3 - TIR'!$C$23)*R6),'Ejercicio 3 - TIR'!$E$23-SQRT(('Ejercicio 3 - TIR'!$E$23-'Ejercicio 3 - TIR'!$C$23)*('Ejercicio 3 - TIR'!$E$23-'Ejercicio 3 - TIR'!$D$23)*(1-R6))) -> 0.14814504 | T6: =RAND() -> 0.1965392 | U6: =IF(T6<=('Ejercicio 3 - TIR'!$D$24-'Ejercicio 3 - TIR'!$C$24)/('Ejercicio 3 - TIR'!$E$24-'Ejercicio 3 - TIR'!$C$24),'Ejercicio 3 - TIR'!$C$24+SQRT(('Ejercicio 3 - TIR'!$E$24-'Ejercicio 3 - TIR'!$C$24)*('Ejercicio 3 - TIR'!$D$24-'Ejercicio 3 - TIR'!$C$24)*T6),'Ejercicio 3 - TIR'!$E$24-SQRT(('Ejercicio 3 - TIR'!$E$24-'Ejercicio 3 - TIR'!$C$24)*('Ejercicio 3 - TIR'!$E$24-'Ejercicio 3 - TIR'!$D$24)*(1-T6))) -> 0.17031581 | V6: =RAND() -> 0.32779464 | W6: =IF(V6<=('Ejercicio 3 - TIR'!$D$25-'Ejercicio 3 - TIR'!$C$25)/('Ejercicio 3 - TIR'!$E$25-'Ejercicio 3 - TIR'!$C$25),'Ejercicio 3 - TIR'!$C$25+SQRT(('Ejercicio 3 - TIR'!$E$25-'Ejercicio 3 - TIR'!$C$25)*('Ejercicio 3 - TIR'!$D$25-'Ejercicio 3 - TIR'!$C$25)*V6),'Ejercicio 3 - TIR'!$E$25-SQRT(('Ejercicio 3 - TIR'!$E$25-'Ejercicio 3 - TIR'!$C$25)*('Ejercicio 3 - TIR'!$E$25-'Ejercicio 3 - TIR'!$D$25)*(1-V6))) -> 0.20149517 | X6: =RAND() -> 0.2696569 | Y6: =IF(X6<=('Ejercicio 3 - TIR'!$D$26-'Ejercicio 3 - TIR'!$C$26)/('Ejercicio 3 - TIR'!$E$26-'Ejercicio 3 - TIR'!$C$26),'Ejercicio 3 - TIR'!$C$26+SQRT(('Ejercicio 3 - TIR'!$E$26-'Ejercicio 3 - TIR'!$C$26)*('Ejercicio 3 - TIR'!$D$26-'Ejercicio 3 - TIR'!$C$26)*X6),'Ejercicio 3 - TIR'!$E$26-SQRT(('Ejercicio 3 - TIR'!$E$26-'Ejercicio 3 - TIR'!$C$26)*('Ejercicio 3 - TIR'!$E$26-'Ejercicio 3 - TIR'!$D$26)*(1-X6))) -> 0.21698284 | Z6: =(1+Q6) -> 1.1463707 | AA6: =Z6*(1+S6) -> 1.3161999 | AB6: =AA6*(1+U6) -> 1.5403695 | AC6: =AB6*(1+W6) -> 1.8507466 | AD6: =AC6*(1+Y6) -> 2.2523268 | AE6: =E6*Q6 -> 5823.3753 | AF6: =AE6*(1+S6) -> 6686.0794 | AG6: =AF6*(1+U6) -> 7824.8245 | AH6: =AG6*(1+W6) -> 9401.4888 | AI6: =AH6*(1+Y6) -> 11441.451 | AJ6: =G6*Z6 -> 44993.824 | AK6: =I6*AA6 -> 53191.087 | AL6: =K6*AB6 -> 49516.941 | AM6: =M6*AC6 -> 60040.582 | AN6: =O6*AD6 -> 81306.244 | AO6: =C6/'Ejercicio 3 - TIR'!$D$7 -> 14413.549 | AP6: =AJ6-AO6 -> 30580.275 | AQ6: =AK6-AO6 -> 38777.538 | AR6: =AL6-AO6 -> 35103.392 | AS6: =AM6-AO6 -> 45627.032 | AT6: =AN6-AO6 -> 66892.694 | AU6: =AP6*'Ejercicio 3 - TIR'!$D$5 -> 15290.138 | AV6: =AQ6*'Ejercicio 3 - TIR'!$D$5 -> 19388.769 | AW6: =AR6*'Ejercicio 3 - TIR'!$D$5 -> 17551.696 | AX6: =AS6*'Ejercicio 3 - TIR'!$D$5 -> 22813.516 | AY6: =AT6*'Ejercicio 3 - TIR'!$D$5 -> 33446.347 | AZ6: =AJ6-AU6-AE6 -> 23880.312 | BA6: =AK6-AV6-AF6 -> 27116.239 | BB6: =AL6-AW6-AG6 -> 24140.421 | BC6: =AM6-AX6-AH6 -> 27825.577 | BD6: =AN6-AY6-AI6 -> 36418.446 | BE6: =AZ6/Z6 -> 20831.229 | BF6: =BA6/AA6 -> 20601.915 | BG6: =BB6/AB6 -> 15671.837 | BH6: =BC6/AC6 -> 15034.785 | BI6: =BD6/AD6 -> 16169.255 | BJ6: =E6*AD6 -> 89609.056 | BK6: =0.2*C6*AD6 -> 32464.024 | BL6: =BJ6+BK6 -> 122073.08 | BM6: =BK6*'Ejercicio 3 - TIR'!$D$5 -> 16232.012 | BN6: =BL6-BM6 -> 105841.07 | BO6: =BN6/AD6 -> 46991.878 | BP6: =-(C6+E6) -> -111852.85 | BQ6: =BE6 -> 20831.229 | BR6: =BF6 -> 20601.915 | BS6: =BG6 -> 15671.837 | BT6: =BH6 -> 15034.785 | BU6: =BI6+BO6 -> 63161.133 | BV6: =IFERROR(IRR(BP6:BU6,0.1),NA())*100 -> 5.5577863
